{"name":"Chair - Simple 5-view Visual Hull","voxels":[{"x":0,"y":0,"z":0,"color":"#c79a67"},{"x":0,"y":0,"z":1,"color":"#c79a67"},{"x":0,"y":0,"z":2,"color":"#c79a67"},{"x":0,"y":0,"z":19,"color":"#e2bf93"},{"x":0,"y":0,"z":20,"color":"#e2bf93"},{"x":0,"y":1,"z":0,"color":"#e2bf93"},{"x":0,"y":1,"z":1,"color":"#c79a67"},{"x":0,"y":1,"z":2,"color":"#c79a67"},{"x":0,"y":1,"z":19,"color":"#d3ab7d"},{"x":0,"y":1,"z":20,"color":"#d3ab7d"},{"x":0,"y":2,"z":0,"color":"#c79a67"},{"x":0,"y":2,"z":1,"color":"#c79a67"},{"x":0,"y":2,"z":2,"color":"#c79a67"},{"x":0,"y":2,"z":19,"color":"#d3ab7d"},{"x":0,"y":2,"z":20,"color":"#e2bf93"},{"x":0,"y":3,"z":1,"color":"#c79a67"},{"x":0,"y":3,"z":2,"color":"#b48653"},{"x":0,"y":3,"z":19,"color":"#d3ab7d"},{"x":0,"y":3,"z":20,"color":"#c79a67"},{"x":0,"y":4,"z":1,"color":"#c79a67"},{"x":0,"y":4,"z":2,"color":"#d3ab7d"},{"x":0,"y":4,"z":19,"color":"#e2bf93"},{"x":0,"y":4,"z":20,"color":"#c79a67"},{"x":0,"y":5,"z":1,"color":"#d3ab7d"},{"x":0,"y":5,"z":2,"color":"#c79a67"},{"x":0,"y":5,"z":19,"color":"#d3ab7d"},{"x":0,"y":5,"z":20,"color":"#c79a67"},{"x":0,"y":6,"z":1,"color":"#c79a67"},{"x":0,"y":6,"z":2,"color":"#c79a67"},{"x":0,"y":6,"z":19,"color":"#d3ab7d"},{"x":0,"y":6,"z":20,"color":"#c79a67"},{"x":0,"y":7,"z":1,"color":"#c79a67"},{"x":0,"y":7,"z":2,"color":"#c79a67"},{"x":0,"y":7,"z":18,"color":"#c79a67"},{"x":0,"y":7,"z":19,"color":"#d3ab7d"},{"x":0,"y":7,"z":20,"color":"#c79a67"},{"x":0,"y":17,"z":14,"color":"#966a3b"},{"x":0,"y":17,"z":15,"color":"#966a3b"},{"x":0,"y":17,"z":16,"color":"#966a3b"},{"x":0,"y":17,"z":17,"color":"#966a3b"},{"x":0,"y":17,"z":18,"color":"#966a3b"},{"x":0,"y":17,"z":19,"color":"#e2bf93"},{"x":0,"y":17,"z":20,"color":"#c79a67"},{"x":0,"y":18,"z":14,"color":"#d3ab7d"},{"x":0,"y":18,"z":15,"color":"#d3ab7d"},{"x":0,"y":18,"z":16,"color":"#d3ab7d"},{"x":0,"y":18,"z":17,"color":"#d3ab7d"},{"x":0,"y":18,"z":18,"color":"#e2bf93"},{"x":0,"y":18,"z":19,"color":"#d3ab7d"},{"x":0,"y":18,"z":20,"color":"#d3ab7d"},{"x":0,"y":19,"z":14,"color":"#d3ab7d"},{"x":0,"y":19,"z":15,"color":"#d3ab7d"},{"x":0,"y":19,"z":16,"color":"#d3ab7d"},{"x":0,"y":19,"z":17,"color":"#d3ab7d"},{"x":0,"y":19,"z":18,"color":"#e2bf93"},{"x":0,"y":19,"z":19,"color":"#e2bf93"},{"x":0,"y":19,"z":20,"color":"#e2bf93"},{"x":1,"y":0,"z":0,"color":"#d3ab7d"},{"x":1,"y":0,"z":1,"color":"#c79a67"},{"x":1,"y":0,"z":2,"color":"#c79a67"},{"x":1,"y":0,"z":19,"color":"#e2bf93"},{"x":1,"y":0,"z":20,"color":"#e2bf93"},{"x":1,"y":0,"z":21,"color":"#d3ab7d"},{"x":1,"y":1,"z":0,"color":"#d3ab7d"},{"x":1,"y":1,"z":1,"color":"#c79a67"},{"x":1,"y":1,"z":2,"color":"#d3ab7d"},{"x":1,"y":1,"z":19,"color":"#d3ab7d"},{"x":1,"y":1,"z":20,"color":"#d3ab7d"},{"x":1,"y":1,"z":21,"color":"#d3ab7d"},{"x":1,"y":2,"z":0,"color":"#d3ab7d"},{"x":1,"y":2,"z":1,"color":"#c79a67"},{"x":1,"y":2,"z":2,"color":"#d3ab7d"},{"x":1,"y":2,"z":3,"color":"#d3ab7d"},{"x":1,"y":2,"z":19,"color":"#d3ab7d"},{"x":1,"y":2,"z":20,"color":"#d3ab7d"},{"x":1,"y":2,"z":21,"color":"#d3ab7d"},{"x":1,"y":3,"z":1,"color":"#c79a67"},{"x":1,"y":3,"z":2,"color":"#c79a67"},{"x":1,"y":3,"z":3,"color":"#d3ab7d"},{"x":1,"y":3,"z":19,"color":"#d3ab7d"},{"x":1,"y":3,"z":20,"color":"#d3ab7d"},{"x":1,"y":3,"z":21,"color":"#d3ab7d"},{"x":1,"y":4,"z":1,"color":"#d3ab7d"},{"x":1,"y":4,"z":2,"color":"#d3ab7d"},{"x":1,"y":4,"z":3,"color":"#d3ab7d"},{"x":1,"y":4,"z":4,"color":"#d3ab7d"},{"x":1,"y":4,"z":19,"color":"#d3ab7d"},{"x":1,"y":4,"z":20,"color":"#d3ab7d"},{"x":1,"y":4,"z":21,"color":"#d3ab7d"},{"x":1,"y":5,"z":1,"color":"#d3ab7d"},{"x":1,"y":5,"z":2,"color":"#d3ab7d"},{"x":1,"y":5,"z":3,"color":"#b48653"},{"x":1,"y":5,"z":4,"color":"#d3ab7d"},{"x":1,"y":5,"z":19,"color":"#d3ab7d"},{"x":1,"y":5,"z":20,"color":"#d3ab7d"},{"x":1,"y":5,"z":21,"color":"#d3ab7d"},{"x":1,"y":6,"z":1,"color":"#d3ab7d"},{"x":1,"y":6,"z":2,"color":"#d3ab7d"},{"x":1,"y":6,"z":3,"color":"#b48653"},{"x":1,"y":6,"z":4,"color":"#d3ab7d"},{"x":1,"y":6,"z":19,"color":"#d3ab7d"},{"x":1,"y":6,"z":20,"color":"#d3ab7d"},{"x":1,"y":6,"z":21,"color":"#d3ab7d"},{"x":1,"y":7,"z":1,"color":"#d3ab7d"},{"x":1,"y":7,"z":2,"color":"#d3ab7d"},{"x":1,"y":7,"z":3,"color":"#d3ab7d"},{"x":1,"y":7,"z":4,"color":"#d3ab7d"},{"x":1,"y":7,"z":18,"color":"#c79a67"},{"x":1,"y":7,"z":19,"color":"#d3ab7d"},{"x":1,"y":7,"z":20,"color":"#d3ab7d"},{"x":1,"y":8,"z":2,"color":"#d3ab7d"},{"x":1,"y":8,"z":3,"color":"#c79a67"},{"x":1,"y":8,"z":4,"color":"#d3ab7d"},{"x":1,"y":8,"z":5,"color":"#d3ab7d"},{"x":1,"y":8,"z":18,"color":"#d3ab7d"},{"x":1,"y":8,"z":19,"color":"#d3ab7d"},{"x":1,"y":8,"z":20,"color":"#d3ab7d"},{"x":1,"y":9,"z":2,"color":"#d3ab7d"},{"x":1,"y":9,"z":3,"color":"#d3ab7d"},{"x":1,"y":9,"z":4,"color":"#b48653"},{"x":1,"y":9,"z":5,"color":"#d3ab7d"},{"x":1,"y":9,"z":18,"color":"#d3ab7d"},{"x":1,"y":9,"z":19,"color":"#d3ab7d"},{"x":1,"y":9,"z":20,"color":"#d3ab7d"},{"x":1,"y":10,"z":2,"color":"#d3ab7d"},{"x":1,"y":10,"z":3,"color":"#c79a67"},{"x":1,"y":10,"z":4,"color":"#b48653"},{"x":1,"y":10,"z":5,"color":"#c79a67"},{"x":1,"y":10,"z":18,"color":"#d3ab7d"},{"x":1,"y":10,"z":19,"color":"#d3ab7d"},{"x":1,"y":10,"z":20,"color":"#c79a67"},{"x":1,"y":11,"z":2,"color":"#c79a67"},{"x":1,"y":11,"z":3,"color":"#d3ab7d"},{"x":1,"y":11,"z":4,"color":"#c79a67"},{"x":1,"y":11,"z":5,"color":"#c79a67"},{"x":1,"y":11,"z":18,"color":"#d3ab7d"},{"x":1,"y":11,"z":19,"color":"#d3ab7d"},{"x":1,"y":11,"z":20,"color":"#c79a67"},{"x":1,"y":12,"z":2,"color":"#c79a67"},{"x":1,"y":12,"z":3,"color":"#c79a67"},{"x":1,"y":12,"z":4,"color":"#c79a67"},{"x":1,"y":12,"z":5,"color":"#c79a67"},{"x":1,"y":12,"z":6,"color":"#c79a67"},{"x":1,"y":12,"z":18,"color":"#d3ab7d"},{"x":1,"y":12,"z":19,"color":"#d3ab7d"},{"x":1,"y":12,"z":20,"color":"#c79a67"},{"x":1,"y":13,"z":3,"color":"#c79a67"},{"x":1,"y":13,"z":4,"color":"#c79a67"},{"x":1,"y":13,"z":5,"color":"#b48653"},{"x":1,"y":13,"z":6,"color":"#e2bf93"},{"x":1,"y":13,"z":18,"color":"#d3ab7d"},{"x":1,"y":13,"z":19,"color":"#e2bf93"},{"x":1,"y":13,"z":20,"color":"#e2bf93"},{"x":1,"y":14,"z":3,"color":"#e2bf93"},{"x":1,"y":14,"z":4,"color":"#c79a67"},{"x":1,"y":14,"z":5,"color":"#b48653"},{"x":1,"y":14,"z":6,"color":"#e2bf93"},{"x":1,"y":14,"z":17,"color":"#c79a67"},{"x":1,"y":14,"z":18,"color":"#d3ab7d"},{"x":1,"y":14,"z":19,"color":"#e2bf93"},{"x":1,"y":14,"z":20,"color":"#e2bf93"},{"x":1,"y":15,"z":3,"color":"#d3ab7d"},{"x":1,"y":15,"z":4,"color":"#c79a67"},{"x":1,"y":15,"z":5,"color":"#d3ab7d"},{"x":1,"y":15,"z":6,"color":"#d3ab7d"},{"x":1,"y":15,"z":7,"color":"#d3ab7d"},{"x":1,"y":15,"z":8,"color":"#d3ab7d"},{"x":1,"y":15,"z":9,"color":"#d3ab7d"},{"x":1,"y":15,"z":10,"color":"#d3ab7d"},{"x":1,"y":15,"z":17,"color":"#d3ab7d"},{"x":1,"y":15,"z":18,"color":"#d3ab7d"},{"x":1,"y":15,"z":19,"color":"#d3ab7d"},{"x":1,"y":15,"z":20,"color":"#d3ab7d"},{"x":1,"y":16,"z":3,"color":"#c79a67"},{"x":1,"y":16,"z":4,"color":"#c79a67"},{"x":1,"y":16,"z":5,"color":"#c79a67"},{"x":1,"y":16,"z":6,"color":"#b48653"},{"x":1,"y":16,"z":7,"color":"#b48653"},{"x":1,"y":16,"z":8,"color":"#966a3b"},{"x":1,"y":16,"z":9,"color":"#c79a67"},{"x":1,"y":16,"z":10,"color":"#d3ab7d"},{"x":1,"y":16,"z":11,"color":"#d3ab7d"},{"x":1,"y":16,"z":12,"color":"#d3ab7d"},{"x":1,"y":16,"z":13,"color":"#d3ab7d"},{"x":1,"y":16,"z":14,"color":"#d3ab7d"},{"x":1,"y":16,"z":15,"color":"#c79a67"},{"x":1,"y":16,"z":16,"color":"#c79a67"},{"x":1,"y":16,"z":17,"color":"#c79a67"},{"x":1,"y":16,"z":18,"color":"#c79a67"},{"x":1,"y":16,"z":19,"color":"#d3ab7d"},{"x":1,"y":16,"z":20,"color":"#c79a67"},{"x":1,"y":17,"z":3,"color":"#c79a67"},{"x":1,"y":17,"z":4,"color":"#c79a67"},{"x":1,"y":17,"z":5,"color":"#c79a67"},{"x":1,"y":17,"z":6,"color":"#b48653"},{"x":1,"y":17,"z":7,"color":"#b48653"},{"x":1,"y":17,"z":8,"color":"#b48653"},{"x":1,"y":17,"z":9,"color":"#b48653"},{"x":1,"y":17,"z":10,"color":"#c79a67"},{"x":1,"y":17,"z":11,"color":"#c79a67"},{"x":1,"y":17,"z":12,"color":"#c79a67"},{"x":1,"y":17,"z":13,"color":"#c79a67"},{"x":1,"y":17,"z":14,"color":"#c79a67"},{"x":1,"y":17,"z":15,"color":"#b48653"},{"x":1,"y":17,"z":16,"color":"#b48653"},{"x":1,"y":17,"z":17,"color":"#b48653"},{"x":1,"y":17,"z":18,"color":"#b48653"},{"x":1,"y":17,"z":19,"color":"#d3ab7d"},{"x":1,"y":17,"z":20,"color":"#c79a67"},{"x":1,"y":17,"z":21,"color":"#c79a67"},{"x":1,"y":18,"z":3,"color":"#b48653"},{"x":1,"y":18,"z":4,"color":"#c79a67"},{"x":1,"y":18,"z":5,"color":"#c79a67"},{"x":1,"y":18,"z":6,"color":"#b48653"},{"x":1,"y":18,"z":7,"color":"#b48653"},{"x":1,"y":18,"z":8,"color":"#c79a67"},{"x":1,"y":18,"z":9,"color":"#c79a67"},{"x":1,"y":18,"z":10,"color":"#c79a67"},{"x":1,"y":18,"z":11,"color":"#c79a67"},{"x":1,"y":18,"z":12,"color":"#c79a67"},{"x":1,"y":18,"z":13,"color":"#c79a67"},{"x":1,"y":18,"z":14,"color":"#c79a67"},{"x":1,"y":18,"z":15,"color":"#c79a67"},{"x":1,"y":18,"z":16,"color":"#b48653"},{"x":1,"y":18,"z":17,"color":"#b48653"},{"x":1,"y":18,"z":18,"color":"#b48653"},{"x":1,"y":18,"z":19,"color":"#b48653"},{"x":1,"y":18,"z":20,"color":"#b48653"},{"x":1,"y":18,"z":21,"color":"#e2bf93"},{"x":1,"y":19,"z":3,"color":"#c79a67"},{"x":1,"y":19,"z":4,"color":"#c79a67"},{"x":1,"y":19,"z":5,"color":"#d3ab7d"},{"x":1,"y":19,"z":6,"color":"#c79a67"},{"x":1,"y":19,"z":7,"color":"#d3ab7d"},{"x":1,"y":19,"z":8,"color":"#d3ab7d"},{"x":1,"y":19,"z":9,"color":"#d3ab7d"},{"x":1,"y":19,"z":10,"color":"#d3ab7d"},{"x":1,"y":19,"z":11,"color":"#d3ab7d"},{"x":1,"y":19,"z":12,"color":"#d3ab7d"},{"x":1,"y":19,"z":13,"color":"#d3ab7d"},{"x":1,"y":19,"z":14,"color":"#d3ab7d"},{"x":1,"y":19,"z":15,"color":"#d3ab7d"},{"x":1,"y":19,"z":16,"color":"#d3ab7d"},{"x":1,"y":19,"z":17,"color":"#d3ab7d"},{"x":1,"y":19,"z":18,"color":"#d3ab7d"},{"x":1,"y":19,"z":19,"color":"#d3ab7d"},{"x":1,"y":19,"z":20,"color":"#e2bf93"},{"x":1,"y":19,"z":21,"color":"#d3ab7d"},{"x":1,"y":20,"z":3,"color":"#e2bf93"},{"x":1,"y":20,"z":4,"color":"#c79a67"},{"x":1,"y":20,"z":5,"color":"#d3ab7d"},{"x":1,"y":20,"z":6,"color":"#e2bf93"},{"x":1,"y":21,"z":3,"color":"#e2bf93"},{"x":1,"y":21,"z":4,"color":"#d3ab7d"},{"x":1,"y":21,"z":5,"color":"#e2bf93"},{"x":1,"y":21,"z":6,"color":"#e2bf93"},{"x":1,"y":22,"z":3,"color":"#e2bf93"},{"x":1,"y":22,"z":4,"color":"#d3ab7d"},{"x":1,"y":22,"z":5,"color":"#d3ab7d"},{"x":1,"y":22,"z":6,"color":"#e2bf93"},{"x":1,"y":23,"z":3,"color":"#c79a67"},{"x":1,"y":23,"z":4,"color":"#c79a67"},{"x":1,"y":23,"z":5,"color":"#d3ab7d"},{"x":1,"y":23,"z":6,"color":"#e2bf93"},{"x":1,"y":24,"z":3,"color":"#e2bf93"},{"x":1,"y":24,"z":4,"color":"#d3ab7d"},{"x":1,"y":24,"z":5,"color":"#e2bf93"},{"x":1,"y":24,"z":6,"color":"#e2bf93"},{"x":1,"y":25,"z":3,"color":"#d3ab7d"},{"x":1,"y":25,"z":4,"color":"#d3ab7d"},{"x":1,"y":25,"z":5,"color":"#e2bf93"},{"x":1,"y":26,"z":2,"color":"#e2bf93"},{"x":1,"y":26,"z":3,"color":"#c79a67"},{"x":1,"y":26,"z":4,"color":"#d3ab7d"},{"x":1,"y":26,"z":5,"color":"#e2bf93"},{"x":1,"y":27,"z":2,"color":"#c79a67"},{"x":1,"y":27,"z":3,"color":"#c79a67"},{"x":1,"y":27,"z":4,"color":"#e2bf93"},{"x":1,"y":27,"z":5,"color":"#c79a67"},{"x":1,"y":28,"z":2,"color":"#c79a67"},{"x":1,"y":28,"z":3,"color":"#c79a67"},{"x":1,"y":28,"z":4,"color":"#d3ab7d"},{"x":1,"y":28,"z":5,"color":"#c79a67"},{"x":1,"y":29,"z":1,"color":"#c79a67"},{"x":1,"y":29,"z":2,"color":"#c79a67"},{"x":1,"y":29,"z":3,"color":"#c79a67"},{"x":1,"y":29,"z":4,"color":"#d3ab7d"},{"x":1,"y":29,"z":5,"color":"#c79a67"},{"x":1,"y":30,"z":1,"color":"#c79a67"},{"x":1,"y":30,"z":2,"color":"#c79a67"},{"x":1,"y":30,"z":3,"color":"#d3ab7d"},{"x":1,"y":30,"z":4,"color":"#c79a67"},{"x":1,"y":31,"z":1,"color":"#e2bf93"},{"x":1,"y":31,"z":2,"color":"#c79a67"},{"x":1,"y":31,"z":3,"color":"#d3ab7d"},{"x":1,"y":31,"z":4,"color":"#b48653"},{"x":1,"y":32,"z":1,"color":"#c79a67"},{"x":1,"y":32,"z":2,"color":"#d3ab7d"},{"x":1,"y":32,"z":3,"color":"#e2bf93"},{"x":1,"y":32,"z":4,"color":"#b48653"},{"x":1,"y":33,"z":0,"color":"#c79a67"},{"x":1,"y":33,"z":1,"color":"#c79a67"},{"x":1,"y":33,"z":2,"color":"#c79a67"},{"x":1,"y":33,"z":3,"color":"#d3ab7d"},{"x":1,"y":33,"z":4,"color":"#b48653"},{"x":1,"y":34,"z":0,"color":"#c79a67"},{"x":1,"y":34,"z":1,"color":"#c79a67"},{"x":1,"y":34,"z":2,"color":"#d3ab7d"},{"x":1,"y":34,"z":3,"color":"#e2bf93"},{"x":1,"y":34,"z":4,"color":"#b48653"},{"x":1,"y":35,"z":1,"color":"#c79a67"},{"x":1,"y":35,"z":2,"color":"#c79a67"},{"x":1,"y":35,"z":3,"color":"#b48653"},{"x":2,"y":0,"z":0,"color":"#c79a67"},{"x":2,"y":0,"z":1,"color":"#d3ab7d"},{"x":2,"y":0,"z":2,"color":"#b48653"},{"x":2,"y":0,"z":19,"color":"#e2bf93"},{"x":2,"y":0,"z":20,"color":"#e2bf93"},{"x":2,"y":0,"z":21,"color":"#e2bf93"},{"x":2,"y":1,"z":0,"color":"#e2bf93"},{"x":2,"y":1,"z":1,"color":"#c79a67"},{"x":2,"y":1,"z":2,"color":"#b48653"},{"x":2,"y":1,"z":19,"color":"#e2bf93"},{"x":2,"y":1,"z":20,"color":"#c79a67"},{"x":2,"y":1,"z":21,"color":"#e2bf93"},{"x":2,"y":2,"z":0,"color":"#c79a67"},{"x":2,"y":2,"z":1,"color":"#c79a67"},{"x":2,"y":2,"z":2,"color":"#b48653"},{"x":2,"y":2,"z":3,"color":"#d3ab7d"},{"x":2,"y":2,"z":19,"color":"#d3ab7d"},{"x":2,"y":2,"z":20,"color":"#e2bf93"},{"x":2,"y":2,"z":21,"color":"#e2bf93"},{"x":2,"y":3,"z":1,"color":"#c79a67"},{"x":2,"y":3,"z":2,"color":"#b48653"},{"x":2,"y":3,"z":3,"color":"#d3ab7d"},{"x":2,"y":3,"z":19,"color":"#e2bf93"},{"x":2,"y":3,"z":20,"color":"#b48653"},{"x":2,"y":3,"z":21,"color":"#e2bf93"},{"x":2,"y":4,"z":1,"color":"#c79a67"},{"x":2,"y":4,"z":2,"color":"#c79a67"},{"x":2,"y":4,"z":3,"color":"#c79a67"},{"x":2,"y":4,"z":4,"color":"#b48653"},{"x":2,"y":4,"z":19,"color":"#e2bf93"},{"x":2,"y":4,"z":20,"color":"#b48653"},{"x":2,"y":4,"z":21,"color":"#d3ab7d"},{"x":2,"y":5,"z":1,"color":"#c79a67"},{"x":2,"y":5,"z":2,"color":"#b48653"},{"x":2,"y":5,"z":3,"color":"#b48653"},{"x":2,"y":5,"z":4,"color":"#b48653"},{"x":2,"y":5,"z":19,"color":"#d3ab7d"},{"x":2,"y":5,"z":20,"color":"#b48653"},{"x":2,"y":5,"z":21,"color":"#b48653"},{"x":2,"y":6,"z":1,"color":"#b48653"},{"x":2,"y":6,"z":2,"color":"#b48653"},{"x":2,"y":6,"z":3,"color":"#b48653"},{"x":2,"y":6,"z":4,"color":"#b48653"},{"x":2,"y":6,"z":19,"color":"#d3ab7d"},{"x":2,"y":6,"z":20,"color":"#b48653"},{"x":2,"y":6,"z":21,"color":"#b48653"},{"x":2,"y":7,"z":1,"color":"#c79a67"},{"x":2,"y":7,"z":2,"color":"#c79a67"},{"x":2,"y":7,"z":3,"color":"#c79a67"},{"x":2,"y":7,"z":4,"color":"#b48653"},{"x":2,"y":7,"z":18,"color":"#c79a67"},{"x":2,"y":7,"z":19,"color":"#d3ab7d"},{"x":2,"y":7,"z":20,"color":"#b48653"},{"x":2,"y":8,"z":2,"color":"#b48653"},{"x":2,"y":8,"z":3,"color":"#c79a67"},{"x":2,"y":8,"z":4,"color":"#b48653"},{"x":2,"y":8,"z":5,"color":"#b48653"},{"x":2,"y":8,"z":18,"color":"#d3ab7d"},{"x":2,"y":8,"z":19,"color":"#d3ab7d"},{"x":2,"y":8,"z":20,"color":"#b48653"},{"x":2,"y":9,"z":2,"color":"#c79a67"},{"x":2,"y":9,"z":3,"color":"#d3ab7d"},{"x":2,"y":9,"z":4,"color":"#b48653"},{"x":2,"y":9,"z":5,"color":"#b48653"},{"x":2,"y":9,"z":18,"color":"#d3ab7d"},{"x":2,"y":9,"z":19,"color":"#d3ab7d"},{"x":2,"y":9,"z":20,"color":"#b48653"},{"x":2,"y":10,"z":2,"color":"#c79a67"},{"x":2,"y":10,"z":3,"color":"#c79a67"},{"x":2,"y":10,"z":4,"color":"#b48653"},{"x":2,"y":10,"z":5,"color":"#b48653"},{"x":2,"y":10,"z":18,"color":"#d3ab7d"},{"x":2,"y":10,"z":19,"color":"#d3ab7d"},{"x":2,"y":10,"z":20,"color":"#b48653"},{"x":2,"y":11,"z":2,"color":"#b48653"},{"x":2,"y":11,"z":3,"color":"#d3ab7d"},{"x":2,"y":11,"z":4,"color":"#c79a67"},{"x":2,"y":11,"z":5,"color":"#b48653"},{"x":2,"y":11,"z":18,"color":"#d3ab7d"},{"x":2,"y":11,"z":19,"color":"#e2bf93"},{"x":2,"y":11,"z":20,"color":"#b48653"},{"x":2,"y":12,"z":2,"color":"#b48653"},{"x":2,"y":12,"z":3,"color":"#d3ab7d"},{"x":2,"y":12,"z":4,"color":"#c79a67"},{"x":2,"y":12,"z":5,"color":"#b48653"},{"x":2,"y":12,"z":6,"color":"#b48653"},{"x":2,"y":12,"z":18,"color":"#d3ab7d"},{"x":2,"y":12,"z":19,"color":"#e2bf93"},{"x":2,"y":12,"z":20,"color":"#c79a67"},{"x":2,"y":13,"z":3,"color":"#d3ab7d"},{"x":2,"y":13,"z":4,"color":"#d3ab7d"},{"x":2,"y":13,"z":5,"color":"#b48653"},{"x":2,"y":13,"z":6,"color":"#d3ab7d"},{"x":2,"y":13,"z":18,"color":"#d3ab7d"},{"x":2,"y":13,"z":19,"color":"#d3ab7d"},{"x":2,"y":13,"z":20,"color":"#d3ab7d"},{"x":2,"y":14,"z":3,"color":"#d3ab7d"},{"x":2,"y":14,"z":4,"color":"#c79a67"},{"x":2,"y":14,"z":5,"color":"#b48653"},{"x":2,"y":14,"z":6,"color":"#c79a67"},{"x":2,"y":14,"z":17,"color":"#c79a67"},{"x":2,"y":14,"z":18,"color":"#d3ab7d"},{"x":2,"y":14,"z":19,"color":"#d3ab7d"},{"x":2,"y":14,"z":20,"color":"#c79a67"},{"x":2,"y":15,"z":3,"color":"#d3ab7d"},{"x":2,"y":15,"z":4,"color":"#c79a67"},{"x":2,"y":15,"z":5,"color":"#c79a67"},{"x":2,"y":15,"z":6,"color":"#c79a67"},{"x":2,"y":15,"z":7,"color":"#c79a67"},{"x":2,"y":15,"z":8,"color":"#d3ab7d"},{"x":2,"y":15,"z":9,"color":"#d3ab7d"},{"x":2,"y":15,"z":10,"color":"#c79a67"},{"x":2,"y":15,"z":17,"color":"#d3ab7d"},{"x":2,"y":15,"z":18,"color":"#d3ab7d"},{"x":2,"y":15,"z":19,"color":"#d3ab7d"},{"x":2,"y":15,"z":20,"color":"#c79a67"},{"x":2,"y":16,"z":3,"color":"#d3ab7d"},{"x":2,"y":16,"z":4,"color":"#c79a67"},{"x":2,"y":16,"z":5,"color":"#c79a67"},{"x":2,"y":16,"z":6,"color":"#b48653"},{"x":2,"y":16,"z":7,"color":"#c79a67"},{"x":2,"y":16,"z":8,"color":"#c79a67"},{"x":2,"y":16,"z":9,"color":"#d3ab7d"},{"x":2,"y":16,"z":10,"color":"#c79a67"},{"x":2,"y":16,"z":11,"color":"#d3ab7d"},{"x":2,"y":16,"z":12,"color":"#d3ab7d"},{"x":2,"y":16,"z":13,"color":"#d3ab7d"},{"x":2,"y":16,"z":14,"color":"#c79a67"},{"x":2,"y":16,"z":15,"color":"#d3ab7d"},{"x":2,"y":16,"z":16,"color":"#d3ab7d"},{"x":2,"y":16,"z":17,"color":"#d3ab7d"},{"x":2,"y":16,"z":18,"color":"#d3ab7d"},{"x":2,"y":16,"z":19,"color":"#e2bf93"},{"x":2,"y":16,"z":20,"color":"#c79a67"},{"x":2,"y":17,"z":3,"color":"#d3ab7d"},{"x":2,"y":17,"z":4,"color":"#c79a67"},{"x":2,"y":17,"z":5,"color":"#c79a67"},{"x":2,"y":17,"z":6,"color":"#b48653"},{"x":2,"y":17,"z":7,"color":"#b48653"},{"x":2,"y":17,"z":8,"color":"#b48653"},{"x":2,"y":17,"z":9,"color":"#966a3b"},{"x":2,"y":17,"z":10,"color":"#b48653"},{"x":2,"y":17,"z":11,"color":"#b48653"},{"x":2,"y":17,"z":12,"color":"#b48653"},{"x":2,"y":17,"z":13,"color":"#b48653"},{"x":2,"y":17,"z":14,"color":"#b48653"},{"x":2,"y":17,"z":15,"color":"#966a3b"},{"x":2,"y":17,"z":16,"color":"#b48653"},{"x":2,"y":17,"z":17,"color":"#966a3b"},{"x":2,"y":17,"z":18,"color":"#966a3b"},{"x":2,"y":17,"z":19,"color":"#e2bf93"},{"x":2,"y":17,"z":20,"color":"#b48653"},{"x":2,"y":17,"z":21,"color":"#d3ab7d"},{"x":2,"y":18,"z":3,"color":"#d3ab7d"},{"x":2,"y":18,"z":4,"color":"#c79a67"},{"x":2,"y":18,"z":5,"color":"#c79a67"},{"x":2,"y":18,"z":6,"color":"#b48653"},{"x":2,"y":18,"z":7,"color":"#c79a67"},{"x":2,"y":18,"z":8,"color":"#c79a67"},{"x":2,"y":18,"z":9,"color":"#c79a67"},{"x":2,"y":18,"z":10,"color":"#c79a67"},{"x":2,"y":18,"z":11,"color":"#c79a67"},{"x":2,"y":18,"z":12,"color":"#c79a67"},{"x":2,"y":18,"z":13,"color":"#c79a67"},{"x":2,"y":18,"z":14,"color":"#c79a67"},{"x":2,"y":18,"z":15,"color":"#c79a67"},{"x":2,"y":18,"z":16,"color":"#c79a67"},{"x":2,"y":18,"z":17,"color":"#c79a67"},{"x":2,"y":18,"z":18,"color":"#c79a67"},{"x":2,"y":18,"z":19,"color":"#c79a67"},{"x":2,"y":18,"z":20,"color":"#b48653"},{"x":2,"y":18,"z":21,"color":"#e2bf93"},{"x":2,"y":19,"z":3,"color":"#c79a67"},{"x":2,"y":19,"z":4,"color":"#c79a67"},{"x":2,"y":19,"z":5,"color":"#c79a67"},{"x":2,"y":19,"z":6,"color":"#c79a67"},{"x":2,"y":19,"z":7,"color":"#c79a67"},{"x":2,"y":19,"z":8,"color":"#d3ab7d"},{"x":2,"y":19,"z":9,"color":"#d3ab7d"},{"x":2,"y":19,"z":10,"color":"#c79a67"},{"x":2,"y":19,"z":11,"color":"#c79a67"},{"x":2,"y":19,"z":12,"color":"#d3ab7d"},{"x":2,"y":19,"z":13,"color":"#d3ab7d"},{"x":2,"y":19,"z":14,"color":"#c79a67"},{"x":2,"y":19,"z":15,"color":"#d3ab7d"},{"x":2,"y":19,"z":16,"color":"#d3ab7d"},{"x":2,"y":19,"z":17,"color":"#d3ab7d"},{"x":2,"y":19,"z":18,"color":"#d3ab7d"},{"x":2,"y":19,"z":19,"color":"#d3ab7d"},{"x":2,"y":19,"z":20,"color":"#c79a67"},{"x":2,"y":19,"z":21,"color":"#d3ab7d"},{"x":2,"y":20,"z":3,"color":"#d3ab7d"},{"x":2,"y":20,"z":4,"color":"#c79a67"},{"x":2,"y":20,"z":5,"color":"#c79a67"},{"x":2,"y":20,"z":6,"color":"#c79a67"},{"x":2,"y":21,"z":3,"color":"#d3ab7d"},{"x":2,"y":21,"z":4,"color":"#c79a67"},{"x":2,"y":21,"z":5,"color":"#d3ab7d"},{"x":2,"y":21,"z":6,"color":"#c79a67"},{"x":2,"y":22,"z":3,"color":"#d3ab7d"},{"x":2,"y":22,"z":4,"color":"#d3ab7d"},{"x":2,"y":22,"z":5,"color":"#d3ab7d"},{"x":2,"y":22,"z":6,"color":"#d3ab7d"},{"x":2,"y":23,"z":3,"color":"#d3ab7d"},{"x":2,"y":23,"z":4,"color":"#d3ab7d"},{"x":2,"y":23,"z":5,"color":"#d3ab7d"},{"x":2,"y":23,"z":6,"color":"#d3ab7d"},{"x":2,"y":24,"z":3,"color":"#d3ab7d"},{"x":2,"y":24,"z":4,"color":"#d3ab7d"},{"x":2,"y":24,"z":5,"color":"#c79a67"},{"x":2,"y":24,"z":6,"color":"#c79a67"},{"x":2,"y":25,"z":3,"color":"#d3ab7d"},{"x":2,"y":25,"z":4,"color":"#d3ab7d"},{"x":2,"y":25,"z":5,"color":"#d3ab7d"},{"x":2,"y":26,"z":2,"color":"#d3ab7d"},{"x":2,"y":26,"z":3,"color":"#d3ab7d"},{"x":2,"y":26,"z":4,"color":"#d3ab7d"},{"x":2,"y":26,"z":5,"color":"#d3ab7d"},{"x":2,"y":27,"z":2,"color":"#d3ab7d"},{"x":2,"y":27,"z":3,"color":"#d3ab7d"},{"x":2,"y":27,"z":4,"color":"#e2bf93"},{"x":2,"y":27,"z":5,"color":"#d3ab7d"},{"x":2,"y":28,"z":2,"color":"#c79a67"},{"x":2,"y":28,"z":3,"color":"#d3ab7d"},{"x":2,"y":28,"z":4,"color":"#e2bf93"},{"x":2,"y":28,"z":5,"color":"#e2bf93"},{"x":2,"y":29,"z":1,"color":"#e2bf93"},{"x":2,"y":29,"z":2,"color":"#c79a67"},{"x":2,"y":29,"z":3,"color":"#d3ab7d"},{"x":2,"y":29,"z":4,"color":"#e2bf93"},{"x":2,"y":29,"z":5,"color":"#e2bf93"},{"x":2,"y":30,"z":1,"color":"#d3ab7d"},{"x":2,"y":30,"z":2,"color":"#c79a67"},{"x":2,"y":30,"z":3,"color":"#d3ab7d"},{"x":2,"y":30,"z":4,"color":"#d3ab7d"},{"x":2,"y":31,"z":1,"color":"#e2bf93"},{"x":2,"y":31,"z":2,"color":"#e2bf93"},{"x":2,"y":31,"z":3,"color":"#d3ab7d"},{"x":2,"y":31,"z":4,"color":"#e2bf93"},{"x":2,"y":32,"z":1,"color":"#d3ab7d"},{"x":2,"y":32,"z":2,"color":"#d3ab7d"},{"x":2,"y":32,"z":3,"color":"#e2bf93"},{"x":2,"y":32,"z":4,"color":"#d3ab7d"},{"x":2,"y":33,"z":0,"color":"#e2bf93"},{"x":2,"y":33,"z":1,"color":"#d3ab7d"},{"x":2,"y":33,"z":2,"color":"#e2bf93"},{"x":2,"y":33,"z":3,"color":"#e2bf93"},{"x":2,"y":33,"z":4,"color":"#e2bf93"},{"x":2,"y":34,"z":0,"color":"#e2bf93"},{"x":2,"y":34,"z":1,"color":"#d3ab7d"},{"x":2,"y":34,"z":2,"color":"#d3ab7d"},{"x":2,"y":34,"z":3,"color":"#e2bf93"},{"x":2,"y":34,"z":4,"color":"#d3ab7d"},{"x":2,"y":35,"z":1,"color":"#e2bf93"},{"x":2,"y":35,"z":2,"color":"#e2bf93"},{"x":2,"y":35,"z":3,"color":"#e2bf93"},{"x":3,"y":3,"z":1,"color":"#c79a67"},{"x":3,"y":3,"z":2,"color":"#c79a67"},{"x":3,"y":3,"z":3,"color":"#b48653"},{"x":3,"y":3,"z":19,"color":"#d3ab7d"},{"x":3,"y":3,"z":20,"color":"#c79a67"},{"x":3,"y":3,"z":21,"color":"#c79a67"},{"x":3,"y":4,"z":1,"color":"#d3ab7d"},{"x":3,"y":4,"z":2,"color":"#c79a67"},{"x":3,"y":4,"z":3,"color":"#b48653"},{"x":3,"y":4,"z":4,"color":"#b48653"},{"x":3,"y":4,"z":19,"color":"#e2bf93"},{"x":3,"y":4,"z":20,"color":"#c79a67"},{"x":3,"y":4,"z":21,"color":"#c79a67"},{"x":3,"y":5,"z":1,"color":"#d3ab7d"},{"x":3,"y":5,"z":2,"color":"#c79a67"},{"x":3,"y":5,"z":3,"color":"#b48653"},{"x":3,"y":5,"z":4,"color":"#b48653"},{"x":3,"y":5,"z":19,"color":"#d3ab7d"},{"x":3,"y":5,"z":20,"color":"#c79a67"},{"x":3,"y":5,"z":21,"color":"#c79a67"},{"x":3,"y":6,"z":1,"color":"#e2bf93"},{"x":3,"y":6,"z":2,"color":"#c79a67"},{"x":3,"y":6,"z":3,"color":"#b48653"},{"x":3,"y":6,"z":4,"color":"#b48653"},{"x":3,"y":6,"z":19,"color":"#d3ab7d"},{"x":3,"y":6,"z":20,"color":"#c79a67"},{"x":3,"y":6,"z":21,"color":"#c79a67"},{"x":3,"y":7,"z":1,"color":"#e2bf93"},{"x":3,"y":7,"z":2,"color":"#c79a67"},{"x":3,"y":7,"z":3,"color":"#c79a67"},{"x":3,"y":7,"z":4,"color":"#b48653"},{"x":3,"y":7,"z":18,"color":"#c79a67"},{"x":3,"y":7,"z":19,"color":"#d3ab7d"},{"x":3,"y":7,"z":20,"color":"#c79a67"},{"x":3,"y":8,"z":2,"color":"#c79a67"},{"x":3,"y":8,"z":3,"color":"#c79a67"},{"x":3,"y":8,"z":4,"color":"#b48653"},{"x":3,"y":8,"z":5,"color":"#b48653"},{"x":3,"y":8,"z":18,"color":"#d3ab7d"},{"x":3,"y":8,"z":19,"color":"#d3ab7d"},{"x":3,"y":8,"z":20,"color":"#c79a67"},{"x":3,"y":9,"z":2,"color":"#c79a67"},{"x":3,"y":9,"z":3,"color":"#c79a67"},{"x":3,"y":9,"z":4,"color":"#b48653"},{"x":3,"y":9,"z":5,"color":"#b48653"},{"x":3,"y":9,"z":18,"color":"#d3ab7d"},{"x":3,"y":9,"z":19,"color":"#d3ab7d"},{"x":3,"y":9,"z":20,"color":"#c79a67"},{"x":3,"y":10,"z":2,"color":"#d3ab7d"},{"x":3,"y":10,"z":3,"color":"#c79a67"},{"x":3,"y":10,"z":4,"color":"#b48653"},{"x":3,"y":10,"z":5,"color":"#b48653"},{"x":3,"y":10,"z":18,"color":"#d3ab7d"},{"x":3,"y":10,"z":19,"color":"#d3ab7d"},{"x":3,"y":10,"z":20,"color":"#c79a67"},{"x":3,"y":11,"z":2,"color":"#c79a67"},{"x":3,"y":11,"z":3,"color":"#d3ab7d"},{"x":3,"y":11,"z":4,"color":"#c79a67"},{"x":3,"y":11,"z":5,"color":"#b48653"},{"x":3,"y":11,"z":18,"color":"#d3ab7d"},{"x":3,"y":11,"z":19,"color":"#d3ab7d"},{"x":3,"y":11,"z":20,"color":"#c79a67"},{"x":3,"y":12,"z":2,"color":"#c79a67"},{"x":3,"y":12,"z":3,"color":"#c79a67"},{"x":3,"y":12,"z":4,"color":"#c79a67"},{"x":3,"y":12,"z":5,"color":"#b48653"},{"x":3,"y":12,"z":6,"color":"#c79a67"},{"x":3,"y":12,"z":18,"color":"#d3ab7d"},{"x":3,"y":12,"z":19,"color":"#d3ab7d"},{"x":3,"y":12,"z":20,"color":"#c79a67"},{"x":3,"y":13,"z":3,"color":"#c79a67"},{"x":3,"y":13,"z":4,"color":"#c79a67"},{"x":3,"y":13,"z":5,"color":"#b48653"},{"x":3,"y":13,"z":6,"color":"#e2bf93"},{"x":3,"y":13,"z":18,"color":"#d3ab7d"},{"x":3,"y":13,"z":19,"color":"#e2bf93"},{"x":3,"y":13,"z":20,"color":"#e2bf93"},{"x":3,"y":14,"z":3,"color":"#e2bf93"},{"x":3,"y":14,"z":4,"color":"#c79a67"},{"x":3,"y":14,"z":5,"color":"#b48653"},{"x":3,"y":14,"z":6,"color":"#e2bf93"},{"x":3,"y":14,"z":17,"color":"#d3ab7d"},{"x":3,"y":14,"z":18,"color":"#e2bf93"},{"x":3,"y":14,"z":19,"color":"#e2bf93"},{"x":3,"y":14,"z":20,"color":"#e2bf93"},{"x":3,"y":15,"z":3,"color":"#b48653"},{"x":3,"y":15,"z":4,"color":"#b48653"},{"x":3,"y":15,"z":5,"color":"#c79a67"},{"x":3,"y":15,"z":6,"color":"#c79a67"},{"x":3,"y":15,"z":7,"color":"#c79a67"},{"x":3,"y":15,"z":8,"color":"#c79a67"},{"x":3,"y":15,"z":9,"color":"#c79a67"},{"x":3,"y":15,"z":10,"color":"#c79a67"},{"x":3,"y":15,"z":17,"color":"#d3ab7d"},{"x":3,"y":15,"z":18,"color":"#d3ab7d"},{"x":3,"y":15,"z":19,"color":"#c79a67"},{"x":3,"y":15,"z":20,"color":"#b48653"},{"x":3,"y":16,"z":3,"color":"#b48653"},{"x":3,"y":16,"z":4,"color":"#b48653"},{"x":3,"y":16,"z":5,"color":"#b48653"},{"x":3,"y":16,"z":6,"color":"#b48653"},{"x":3,"y":16,"z":7,"color":"#b48653"},{"x":3,"y":16,"z":8,"color":"#966a3b"},{"x":3,"y":16,"z":9,"color":"#c79a67"},{"x":3,"y":16,"z":10,"color":"#b48653"},{"x":3,"y":16,"z":11,"color":"#b48653"},{"x":3,"y":16,"z":12,"color":"#b48653"},{"x":3,"y":16,"z":13,"color":"#b48653"},{"x":3,"y":16,"z":14,"color":"#b48653"},{"x":3,"y":16,"z":15,"color":"#b48653"},{"x":3,"y":16,"z":16,"color":"#b48653"},{"x":3,"y":16,"z":17,"color":"#c79a67"},{"x":3,"y":16,"z":18,"color":"#c79a67"},{"x":3,"y":16,"z":19,"color":"#b48653"},{"x":3,"y":16,"z":20,"color":"#966a3b"},{"x":3,"y":17,"z":3,"color":"#b48653"},{"x":3,"y":17,"z":4,"color":"#b48653"},{"x":3,"y":17,"z":5,"color":"#b48653"},{"x":3,"y":17,"z":6,"color":"#b48653"},{"x":3,"y":17,"z":7,"color":"#b48653"},{"x":3,"y":17,"z":8,"color":"#b48653"},{"x":3,"y":17,"z":9,"color":"#966a3b"},{"x":3,"y":17,"z":10,"color":"#b48653"},{"x":3,"y":17,"z":11,"color":"#b48653"},{"x":3,"y":17,"z":12,"color":"#b48653"},{"x":3,"y":17,"z":13,"color":"#b48653"},{"x":3,"y":17,"z":14,"color":"#b48653"},{"x":3,"y":17,"z":15,"color":"#966a3b"},{"x":3,"y":17,"z":16,"color":"#b48653"},{"x":3,"y":17,"z":17,"color":"#966a3b"},{"x":3,"y":17,"z":18,"color":"#966a3b"},{"x":3,"y":17,"z":19,"color":"#c79a67"},{"x":3,"y":17,"z":20,"color":"#966a3b"},{"x":3,"y":17,"z":21,"color":"#966a3b"},{"x":3,"y":18,"z":3,"color":"#c79a67"},{"x":3,"y":18,"z":4,"color":"#c79a67"},{"x":3,"y":18,"z":5,"color":"#c79a67"},{"x":3,"y":18,"z":6,"color":"#c79a67"},{"x":3,"y":18,"z":7,"color":"#c79a67"},{"x":3,"y":18,"z":8,"color":"#c79a67"},{"x":3,"y":18,"z":9,"color":"#c79a67"},{"x":3,"y":18,"z":10,"color":"#c79a67"},{"x":3,"y":18,"z":11,"color":"#c79a67"},{"x":3,"y":18,"z":12,"color":"#c79a67"},{"x":3,"y":18,"z":13,"color":"#c79a67"},{"x":3,"y":18,"z":14,"color":"#c79a67"},{"x":3,"y":18,"z":15,"color":"#c79a67"},{"x":3,"y":18,"z":16,"color":"#c79a67"},{"x":3,"y":18,"z":17,"color":"#c79a67"},{"x":3,"y":18,"z":18,"color":"#c79a67"},{"x":3,"y":18,"z":19,"color":"#c79a67"},{"x":3,"y":18,"z":20,"color":"#c79a67"},{"x":3,"y":18,"z":21,"color":"#e2bf93"},{"x":3,"y":19,"z":3,"color":"#d3ab7d"},{"x":3,"y":19,"z":4,"color":"#d3ab7d"},{"x":3,"y":19,"z":5,"color":"#d3ab7d"},{"x":3,"y":19,"z":6,"color":"#c79a67"},{"x":3,"y":19,"z":7,"color":"#d3ab7d"},{"x":3,"y":19,"z":8,"color":"#d3ab7d"},{"x":3,"y":19,"z":9,"color":"#d3ab7d"},{"x":3,"y":19,"z":10,"color":"#d3ab7d"},{"x":3,"y":19,"z":11,"color":"#d3ab7d"},{"x":3,"y":19,"z":12,"color":"#d3ab7d"},{"x":3,"y":19,"z":13,"color":"#d3ab7d"},{"x":3,"y":19,"z":14,"color":"#d3ab7d"},{"x":3,"y":19,"z":15,"color":"#d3ab7d"},{"x":3,"y":19,"z":16,"color":"#d3ab7d"},{"x":3,"y":19,"z":17,"color":"#d3ab7d"},{"x":3,"y":19,"z":18,"color":"#d3ab7d"},{"x":3,"y":19,"z":19,"color":"#d3ab7d"},{"x":3,"y":19,"z":20,"color":"#d3ab7d"},{"x":3,"y":19,"z":21,"color":"#d3ab7d"},{"x":3,"y":20,"z":3,"color":"#b48653"},{"x":3,"y":20,"z":4,"color":"#c79a67"},{"x":3,"y":20,"z":5,"color":"#b48653"},{"x":3,"y":20,"z":6,"color":"#c79a67"},{"x":3,"y":21,"z":3,"color":"#b48653"},{"x":3,"y":21,"z":4,"color":"#c79a67"},{"x":3,"y":21,"z":5,"color":"#d3ab7d"},{"x":3,"y":21,"z":6,"color":"#c79a67"},{"x":3,"y":22,"z":3,"color":"#e2bf93"},{"x":3,"y":22,"z":4,"color":"#c79a67"},{"x":3,"y":22,"z":5,"color":"#b48653"},{"x":3,"y":22,"z":6,"color":"#c79a67"},{"x":3,"y":23,"z":3,"color":"#b48653"},{"x":3,"y":23,"z":4,"color":"#c79a67"},{"x":3,"y":23,"z":5,"color":"#d3ab7d"},{"x":3,"y":23,"z":6,"color":"#c79a67"},{"x":3,"y":24,"z":3,"color":"#c79a67"},{"x":3,"y":24,"z":4,"color":"#d3ab7d"},{"x":3,"y":24,"z":5,"color":"#b48653"},{"x":3,"y":24,"z":6,"color":"#c79a67"},{"x":3,"y":25,"z":3,"color":"#c79a67"},{"x":3,"y":25,"z":4,"color":"#d3ab7d"},{"x":3,"y":25,"z":5,"color":"#c79a67"},{"x":3,"y":26,"z":2,"color":"#c79a67"},{"x":3,"y":26,"z":3,"color":"#c79a67"},{"x":3,"y":26,"z":4,"color":"#d3ab7d"},{"x":3,"y":26,"z":5,"color":"#b48653"},{"x":3,"y":27,"z":2,"color":"#c79a67"},{"x":3,"y":27,"z":3,"color":"#c79a67"},{"x":3,"y":27,"z":4,"color":"#e2bf93"},{"x":3,"y":27,"z":5,"color":"#b48653"},{"x":3,"y":28,"z":2,"color":"#c79a67"},{"x":3,"y":28,"z":3,"color":"#c79a67"},{"x":3,"y":28,"z":4,"color":"#d3ab7d"},{"x":3,"y":28,"z":5,"color":"#b48653"},{"x":3,"y":29,"z":1,"color":"#d3ab7d"},{"x":3,"y":29,"z":2,"color":"#c79a67"},{"x":3,"y":29,"z":3,"color":"#c79a67"},{"x":3,"y":29,"z":4,"color":"#d3ab7d"},{"x":3,"y":29,"z":5,"color":"#d3ab7d"},{"x":3,"y":30,"z":1,"color":"#d3ab7d"},{"x":3,"y":30,"z":2,"color":"#c79a67"},{"x":3,"y":30,"z":3,"color":"#d3ab7d"},{"x":3,"y":30,"z":4,"color":"#d3ab7d"},{"x":3,"y":31,"z":1,"color":"#d3ab7d"},{"x":3,"y":31,"z":2,"color":"#d3ab7d"},{"x":3,"y":31,"z":3,"color":"#d3ab7d"},{"x":3,"y":31,"z":4,"color":"#d3ab7d"},{"x":3,"y":32,"z":1,"color":"#d3ab7d"},{"x":3,"y":32,"z":2,"color":"#d3ab7d"},{"x":3,"y":32,"z":3,"color":"#e2bf93"},{"x":3,"y":32,"z":4,"color":"#d3ab7d"},{"x":3,"y":33,"z":1,"color":"#d3ab7d"},{"x":3,"y":33,"z":2,"color":"#d3ab7d"},{"x":3,"y":33,"z":3,"color":"#d3ab7d"},{"x":3,"y":33,"z":4,"color":"#d3ab7d"},{"x":3,"y":34,"z":1,"color":"#d3ab7d"},{"x":3,"y":34,"z":2,"color":"#d3ab7d"},{"x":3,"y":34,"z":3,"color":"#d3ab7d"},{"x":3,"y":34,"z":4,"color":"#d3ab7d"},{"x":3,"y":35,"z":1,"color":"#e2bf93"},{"x":3,"y":35,"z":2,"color":"#c79a67"},{"x":3,"y":35,"z":3,"color":"#b48653"},{"x":4,"y":15,"z":3,"color":"#e2bf93"},{"x":4,"y":15,"z":4,"color":"#c79a67"},{"x":4,"y":15,"z":5,"color":"#c79a67"},{"x":4,"y":15,"z":6,"color":"#c79a67"},{"x":4,"y":15,"z":7,"color":"#d3ab7d"},{"x":4,"y":15,"z":8,"color":"#c79a67"},{"x":4,"y":15,"z":9,"color":"#d3ab7d"},{"x":4,"y":15,"z":10,"color":"#e2bf93"},{"x":4,"y":15,"z":17,"color":"#e2bf93"},{"x":4,"y":15,"z":18,"color":"#d3ab7d"},{"x":4,"y":15,"z":19,"color":"#e2bf93"},{"x":4,"y":15,"z":20,"color":"#966a3b"},{"x":4,"y":16,"z":3,"color":"#c79a67"},{"x":4,"y":16,"z":4,"color":"#c79a67"},{"x":4,"y":16,"z":5,"color":"#c79a67"},{"x":4,"y":16,"z":6,"color":"#b48653"},{"x":4,"y":16,"z":7,"color":"#c79a67"},{"x":4,"y":16,"z":8,"color":"#b48653"},{"x":4,"y":16,"z":9,"color":"#d3ab7d"},{"x":4,"y":16,"z":10,"color":"#d3ab7d"},{"x":4,"y":16,"z":11,"color":"#c79a67"},{"x":4,"y":16,"z":12,"color":"#c79a67"},{"x":4,"y":16,"z":13,"color":"#c79a67"},{"x":4,"y":16,"z":14,"color":"#c79a67"},{"x":4,"y":16,"z":15,"color":"#c79a67"},{"x":4,"y":16,"z":16,"color":"#c79a67"},{"x":4,"y":16,"z":17,"color":"#c79a67"},{"x":4,"y":16,"z":18,"color":"#d3ab7d"},{"x":4,"y":16,"z":19,"color":"#d3ab7d"},{"x":4,"y":16,"z":20,"color":"#b48653"},{"x":4,"y":17,"z":3,"color":"#b48653"},{"x":4,"y":17,"z":4,"color":"#c79a67"},{"x":4,"y":17,"z":5,"color":"#c79a67"},{"x":4,"y":17,"z":6,"color":"#b48653"},{"x":4,"y":17,"z":7,"color":"#b48653"},{"x":4,"y":17,"z":8,"color":"#b48653"},{"x":4,"y":17,"z":9,"color":"#966a3b"},{"x":4,"y":17,"z":10,"color":"#b48653"},{"x":4,"y":17,"z":11,"color":"#b48653"},{"x":4,"y":17,"z":12,"color":"#b48653"},{"x":4,"y":17,"z":13,"color":"#b48653"},{"x":4,"y":17,"z":14,"color":"#b48653"},{"x":4,"y":17,"z":15,"color":"#966a3b"},{"x":4,"y":17,"z":16,"color":"#b48653"},{"x":4,"y":17,"z":17,"color":"#966a3b"},{"x":4,"y":17,"z":18,"color":"#966a3b"},{"x":4,"y":17,"z":19,"color":"#d3ab7d"},{"x":4,"y":17,"z":20,"color":"#966a3b"},{"x":4,"y":17,"z":21,"color":"#966a3b"},{"x":4,"y":18,"z":3,"color":"#b48653"},{"x":4,"y":18,"z":4,"color":"#c79a67"},{"x":4,"y":18,"z":5,"color":"#c79a67"},{"x":4,"y":18,"z":6,"color":"#b48653"},{"x":4,"y":18,"z":7,"color":"#b48653"},{"x":4,"y":18,"z":8,"color":"#c79a67"},{"x":4,"y":18,"z":9,"color":"#c79a67"},{"x":4,"y":18,"z":10,"color":"#d3ab7d"},{"x":4,"y":18,"z":11,"color":"#c79a67"},{"x":4,"y":18,"z":12,"color":"#c79a67"},{"x":4,"y":18,"z":13,"color":"#c79a67"},{"x":4,"y":18,"z":14,"color":"#c79a67"},{"x":4,"y":18,"z":15,"color":"#c79a67"},{"x":4,"y":18,"z":16,"color":"#c79a67"},{"x":4,"y":18,"z":17,"color":"#c79a67"},{"x":4,"y":18,"z":18,"color":"#b48653"},{"x":4,"y":18,"z":19,"color":"#b48653"},{"x":4,"y":18,"z":20,"color":"#b48653"},{"x":4,"y":18,"z":21,"color":"#e2bf93"},{"x":4,"y":19,"z":3,"color":"#d3ab7d"},{"x":4,"y":19,"z":4,"color":"#d3ab7d"},{"x":4,"y":19,"z":5,"color":"#d3ab7d"},{"x":4,"y":19,"z":6,"color":"#c79a67"},{"x":4,"y":19,"z":7,"color":"#d3ab7d"},{"x":4,"y":19,"z":8,"color":"#d3ab7d"},{"x":4,"y":19,"z":9,"color":"#d3ab7d"},{"x":4,"y":19,"z":10,"color":"#d3ab7d"},{"x":4,"y":19,"z":11,"color":"#d3ab7d"},{"x":4,"y":19,"z":12,"color":"#d3ab7d"},{"x":4,"y":19,"z":13,"color":"#d3ab7d"},{"x":4,"y":19,"z":14,"color":"#d3ab7d"},{"x":4,"y":19,"z":15,"color":"#d3ab7d"},{"x":4,"y":19,"z":16,"color":"#d3ab7d"},{"x":4,"y":19,"z":17,"color":"#d3ab7d"},{"x":4,"y":19,"z":18,"color":"#d3ab7d"},{"x":4,"y":19,"z":19,"color":"#d3ab7d"},{"x":4,"y":19,"z":20,"color":"#d3ab7d"},{"x":4,"y":19,"z":21,"color":"#d3ab7d"},{"x":4,"y":27,"z":2,"color":"#c79a67"},{"x":4,"y":27,"z":3,"color":"#c79a67"},{"x":4,"y":27,"z":4,"color":"#e2bf93"},{"x":4,"y":27,"z":5,"color":"#c79a67"},{"x":4,"y":28,"z":2,"color":"#c79a67"},{"x":4,"y":28,"z":3,"color":"#d3ab7d"},{"x":4,"y":28,"z":4,"color":"#d3ab7d"},{"x":4,"y":28,"z":5,"color":"#d3ab7d"},{"x":4,"y":29,"z":1,"color":"#d3ab7d"},{"x":4,"y":29,"z":2,"color":"#c79a67"},{"x":4,"y":29,"z":3,"color":"#c79a67"},{"x":4,"y":29,"z":4,"color":"#d3ab7d"},{"x":4,"y":29,"z":5,"color":"#d3ab7d"},{"x":4,"y":30,"z":1,"color":"#d3ab7d"},{"x":4,"y":30,"z":2,"color":"#c79a67"},{"x":4,"y":30,"z":3,"color":"#d3ab7d"},{"x":4,"y":30,"z":4,"color":"#d3ab7d"},{"x":4,"y":31,"z":1,"color":"#d3ab7d"},{"x":4,"y":31,"z":2,"color":"#d3ab7d"},{"x":4,"y":31,"z":3,"color":"#d3ab7d"},{"x":4,"y":31,"z":4,"color":"#d3ab7d"},{"x":4,"y":32,"z":1,"color":"#c79a67"},{"x":4,"y":32,"z":2,"color":"#d3ab7d"},{"x":4,"y":32,"z":3,"color":"#d3ab7d"},{"x":4,"y":32,"z":4,"color":"#d3ab7d"},{"x":4,"y":33,"z":0,"color":"#e2bf93"},{"x":4,"y":33,"z":1,"color":"#c79a67"},{"x":4,"y":33,"z":2,"color":"#d3ab7d"},{"x":4,"y":33,"z":3,"color":"#d3ab7d"},{"x":4,"y":33,"z":4,"color":"#e2bf93"},{"x":4,"y":34,"z":0,"color":"#e2bf93"},{"x":4,"y":34,"z":1,"color":"#c79a67"},{"x":4,"y":34,"z":2,"color":"#d3ab7d"},{"x":4,"y":34,"z":3,"color":"#e2bf93"},{"x":4,"y":34,"z":4,"color":"#e2bf93"},{"x":4,"y":35,"z":1,"color":"#c79a67"},{"x":4,"y":35,"z":2,"color":"#c79a67"},{"x":4,"y":35,"z":3,"color":"#b48653"},{"x":5,"y":15,"z":3,"color":"#e2bf93"},{"x":5,"y":15,"z":4,"color":"#c79a67"},{"x":5,"y":15,"z":5,"color":"#c79a67"},{"x":5,"y":15,"z":6,"color":"#c79a67"},{"x":5,"y":15,"z":7,"color":"#c79a67"},{"x":5,"y":15,"z":8,"color":"#d3ab7d"},{"x":5,"y":15,"z":9,"color":"#c79a67"},{"x":5,"y":15,"z":10,"color":"#c79a67"},{"x":5,"y":15,"z":17,"color":"#d3ab7d"},{"x":5,"y":15,"z":18,"color":"#d3ab7d"},{"x":5,"y":15,"z":19,"color":"#d3ab7d"},{"x":5,"y":15,"z":20,"color":"#b48653"},{"x":5,"y":16,"z":3,"color":"#b48653"},{"x":5,"y":16,"z":4,"color":"#c79a67"},{"x":5,"y":16,"z":5,"color":"#c79a67"},{"x":5,"y":16,"z":6,"color":"#b48653"},{"x":5,"y":16,"z":7,"color":"#c79a67"},{"x":5,"y":16,"z":8,"color":"#b48653"},{"x":5,"y":16,"z":9,"color":"#c79a67"},{"x":5,"y":16,"z":10,"color":"#c79a67"},{"x":5,"y":16,"z":11,"color":"#c79a67"},{"x":5,"y":16,"z":12,"color":"#c79a67"},{"x":5,"y":16,"z":13,"color":"#d3ab7d"},{"x":5,"y":16,"z":14,"color":"#c79a67"},{"x":5,"y":16,"z":15,"color":"#c79a67"},{"x":5,"y":16,"z":16,"color":"#d3ab7d"},{"x":5,"y":16,"z":17,"color":"#c79a67"},{"x":5,"y":16,"z":18,"color":"#c79a67"},{"x":5,"y":16,"z":19,"color":"#c79a67"},{"x":5,"y":16,"z":20,"color":"#b48653"},{"x":5,"y":17,"z":3,"color":"#b48653"},{"x":5,"y":17,"z":4,"color":"#c79a67"},{"x":5,"y":17,"z":5,"color":"#c79a67"},{"x":5,"y":17,"z":6,"color":"#b48653"},{"x":5,"y":17,"z":7,"color":"#b48653"},{"x":5,"y":17,"z":8,"color":"#b48653"},{"x":5,"y":17,"z":9,"color":"#966a3b"},{"x":5,"y":17,"z":10,"color":"#b48653"},{"x":5,"y":17,"z":11,"color":"#b48653"},{"x":5,"y":17,"z":12,"color":"#b48653"},{"x":5,"y":17,"z":13,"color":"#b48653"},{"x":5,"y":17,"z":14,"color":"#b48653"},{"x":5,"y":17,"z":15,"color":"#966a3b"},{"x":5,"y":17,"z":16,"color":"#b48653"},{"x":5,"y":17,"z":17,"color":"#966a3b"},{"x":5,"y":17,"z":18,"color":"#966a3b"},{"x":5,"y":17,"z":19,"color":"#c79a67"},{"x":5,"y":17,"z":20,"color":"#b48653"},{"x":5,"y":17,"z":21,"color":"#966a3b"},{"x":5,"y":18,"z":3,"color":"#d3ab7d"},{"x":5,"y":18,"z":4,"color":"#c79a67"},{"x":5,"y":18,"z":5,"color":"#d3ab7d"},{"x":5,"y":18,"z":6,"color":"#c79a67"},{"x":5,"y":18,"z":7,"color":"#c79a67"},{"x":5,"y":18,"z":8,"color":"#c79a67"},{"x":5,"y":18,"z":9,"color":"#c79a67"},{"x":5,"y":18,"z":10,"color":"#d3ab7d"},{"x":5,"y":18,"z":11,"color":"#d3ab7d"},{"x":5,"y":18,"z":12,"color":"#c79a67"},{"x":5,"y":18,"z":13,"color":"#d3ab7d"},{"x":5,"y":18,"z":14,"color":"#c79a67"},{"x":5,"y":18,"z":15,"color":"#d3ab7d"},{"x":5,"y":18,"z":16,"color":"#d3ab7d"},{"x":5,"y":18,"z":17,"color":"#c79a67"},{"x":5,"y":18,"z":18,"color":"#d3ab7d"},{"x":5,"y":18,"z":19,"color":"#d3ab7d"},{"x":5,"y":18,"z":20,"color":"#b48653"},{"x":5,"y":18,"z":21,"color":"#e2bf93"},{"x":5,"y":19,"z":3,"color":"#d3ab7d"},{"x":5,"y":19,"z":4,"color":"#d3ab7d"},{"x":5,"y":19,"z":5,"color":"#d3ab7d"},{"x":5,"y":19,"z":6,"color":"#c79a67"},{"x":5,"y":19,"z":7,"color":"#d3ab7d"},{"x":5,"y":19,"z":8,"color":"#d3ab7d"},{"x":5,"y":19,"z":9,"color":"#d3ab7d"},{"x":5,"y":19,"z":10,"color":"#c79a67"},{"x":5,"y":19,"z":11,"color":"#d3ab7d"},{"x":5,"y":19,"z":12,"color":"#d3ab7d"},{"x":5,"y":19,"z":13,"color":"#d3ab7d"},{"x":5,"y":19,"z":14,"color":"#d3ab7d"},{"x":5,"y":19,"z":15,"color":"#d3ab7d"},{"x":5,"y":19,"z":16,"color":"#d3ab7d"},{"x":5,"y":19,"z":17,"color":"#d3ab7d"},{"x":5,"y":19,"z":18,"color":"#d3ab7d"},{"x":5,"y":19,"z":19,"color":"#d3ab7d"},{"x":5,"y":19,"z":20,"color":"#d3ab7d"},{"x":5,"y":19,"z":21,"color":"#d3ab7d"},{"x":5,"y":27,"z":2,"color":"#b48653"},{"x":5,"y":27,"z":3,"color":"#c79a67"},{"x":5,"y":27,"z":4,"color":"#e2bf93"},{"x":5,"y":27,"z":5,"color":"#b48653"},{"x":5,"y":28,"z":2,"color":"#c79a67"},{"x":5,"y":28,"z":3,"color":"#d3ab7d"},{"x":5,"y":28,"z":4,"color":"#d3ab7d"},{"x":5,"y":28,"z":5,"color":"#d3ab7d"},{"x":5,"y":29,"z":1,"color":"#d3ab7d"},{"x":5,"y":29,"z":2,"color":"#c79a67"},{"x":5,"y":29,"z":3,"color":"#c79a67"},{"x":5,"y":29,"z":4,"color":"#d3ab7d"},{"x":5,"y":29,"z":5,"color":"#d3ab7d"},{"x":5,"y":30,"z":1,"color":"#e2bf93"},{"x":5,"y":30,"z":2,"color":"#c79a67"},{"x":5,"y":30,"z":3,"color":"#d3ab7d"},{"x":5,"y":30,"z":4,"color":"#d3ab7d"},{"x":5,"y":31,"z":1,"color":"#d3ab7d"},{"x":5,"y":31,"z":2,"color":"#d3ab7d"},{"x":5,"y":31,"z":3,"color":"#d3ab7d"},{"x":5,"y":31,"z":4,"color":"#d3ab7d"},{"x":5,"y":32,"z":1,"color":"#c79a67"},{"x":5,"y":32,"z":2,"color":"#d3ab7d"},{"x":5,"y":32,"z":3,"color":"#d3ab7d"},{"x":5,"y":32,"z":4,"color":"#d3ab7d"},{"x":5,"y":33,"z":0,"color":"#d3ab7d"},{"x":5,"y":33,"z":1,"color":"#c79a67"},{"x":5,"y":33,"z":2,"color":"#c79a67"},{"x":5,"y":33,"z":3,"color":"#d3ab7d"},{"x":5,"y":33,"z":4,"color":"#c79a67"},{"x":5,"y":34,"z":0,"color":"#d3ab7d"},{"x":5,"y":34,"z":1,"color":"#c79a67"},{"x":5,"y":34,"z":2,"color":"#d3ab7d"},{"x":5,"y":34,"z":3,"color":"#e2bf93"},{"x":5,"y":34,"z":4,"color":"#d3ab7d"},{"x":6,"y":15,"z":3,"color":"#e2bf93"},{"x":6,"y":15,"z":4,"color":"#c79a67"},{"x":6,"y":15,"z":5,"color":"#c79a67"},{"x":6,"y":15,"z":6,"color":"#d3ab7d"},{"x":6,"y":15,"z":7,"color":"#c79a67"},{"x":6,"y":15,"z":8,"color":"#d3ab7d"},{"x":6,"y":15,"z":9,"color":"#d3ab7d"},{"x":6,"y":15,"z":10,"color":"#c79a67"},{"x":6,"y":15,"z":17,"color":"#d3ab7d"},{"x":6,"y":15,"z":18,"color":"#d3ab7d"},{"x":6,"y":15,"z":19,"color":"#d3ab7d"},{"x":6,"y":15,"z":20,"color":"#c79a67"},{"x":6,"y":16,"z":3,"color":"#e2bf93"},{"x":6,"y":16,"z":4,"color":"#c79a67"},{"x":6,"y":16,"z":5,"color":"#c79a67"},{"x":6,"y":16,"z":6,"color":"#c79a67"},{"x":6,"y":16,"z":7,"color":"#b48653"},{"x":6,"y":16,"z":8,"color":"#b48653"},{"x":6,"y":16,"z":9,"color":"#d3ab7d"},{"x":6,"y":16,"z":10,"color":"#c79a67"},{"x":6,"y":16,"z":11,"color":"#c79a67"},{"x":6,"y":16,"z":12,"color":"#c79a67"},{"x":6,"y":16,"z":13,"color":"#c79a67"},{"x":6,"y":16,"z":14,"color":"#c79a67"},{"x":6,"y":16,"z":15,"color":"#d3ab7d"},{"x":6,"y":16,"z":16,"color":"#c79a67"},{"x":6,"y":16,"z":17,"color":"#c79a67"},{"x":6,"y":16,"z":18,"color":"#c79a67"},{"x":6,"y":16,"z":19,"color":"#c79a67"},{"x":6,"y":16,"z":20,"color":"#c79a67"},{"x":6,"y":17,"z":3,"color":"#d3ab7d"},{"x":6,"y":17,"z":4,"color":"#c79a67"},{"x":6,"y":17,"z":5,"color":"#c79a67"},{"x":6,"y":17,"z":6,"color":"#b48653"},{"x":6,"y":17,"z":7,"color":"#b48653"},{"x":6,"y":17,"z":8,"color":"#b48653"},{"x":6,"y":17,"z":9,"color":"#966a3b"},{"x":6,"y":17,"z":10,"color":"#b48653"},{"x":6,"y":17,"z":11,"color":"#b48653"},{"x":6,"y":17,"z":12,"color":"#b48653"},{"x":6,"y":17,"z":13,"color":"#b48653"},{"x":6,"y":17,"z":14,"color":"#b48653"},{"x":6,"y":17,"z":15,"color":"#966a3b"},{"x":6,"y":17,"z":16,"color":"#b48653"},{"x":6,"y":17,"z":17,"color":"#966a3b"},{"x":6,"y":17,"z":18,"color":"#966a3b"},{"x":6,"y":17,"z":19,"color":"#d3ab7d"},{"x":6,"y":17,"z":20,"color":"#c79a67"},{"x":6,"y":17,"z":21,"color":"#b48653"},{"x":6,"y":18,"z":3,"color":"#e2bf93"},{"x":6,"y":18,"z":4,"color":"#c79a67"},{"x":6,"y":18,"z":5,"color":"#d3ab7d"},{"x":6,"y":18,"z":6,"color":"#d3ab7d"},{"x":6,"y":18,"z":7,"color":"#c79a67"},{"x":6,"y":18,"z":8,"color":"#d3ab7d"},{"x":6,"y":18,"z":9,"color":"#d3ab7d"},{"x":6,"y":18,"z":10,"color":"#d3ab7d"},{"x":6,"y":18,"z":11,"color":"#c79a67"},{"x":6,"y":18,"z":12,"color":"#c79a67"},{"x":6,"y":18,"z":13,"color":"#d3ab7d"},{"x":6,"y":18,"z":14,"color":"#c79a67"},{"x":6,"y":18,"z":15,"color":"#d3ab7d"},{"x":6,"y":18,"z":16,"color":"#c79a67"},{"x":6,"y":18,"z":17,"color":"#c79a67"},{"x":6,"y":18,"z":18,"color":"#c79a67"},{"x":6,"y":18,"z":19,"color":"#d3ab7d"},{"x":6,"y":18,"z":20,"color":"#c79a67"},{"x":6,"y":18,"z":21,"color":"#e2bf93"},{"x":6,"y":19,"z":3,"color":"#d3ab7d"},{"x":6,"y":19,"z":4,"color":"#d3ab7d"},{"x":6,"y":19,"z":5,"color":"#d3ab7d"},{"x":6,"y":19,"z":6,"color":"#c79a67"},{"x":6,"y":19,"z":7,"color":"#d3ab7d"},{"x":6,"y":19,"z":8,"color":"#d3ab7d"},{"x":6,"y":19,"z":9,"color":"#d3ab7d"},{"x":6,"y":19,"z":10,"color":"#c79a67"},{"x":6,"y":19,"z":11,"color":"#c79a67"},{"x":6,"y":19,"z":12,"color":"#d3ab7d"},{"x":6,"y":19,"z":13,"color":"#d3ab7d"},{"x":6,"y":19,"z":14,"color":"#d3ab7d"},{"x":6,"y":19,"z":15,"color":"#d3ab7d"},{"x":6,"y":19,"z":16,"color":"#d3ab7d"},{"x":6,"y":19,"z":17,"color":"#d3ab7d"},{"x":6,"y":19,"z":18,"color":"#d3ab7d"},{"x":6,"y":19,"z":19,"color":"#d3ab7d"},{"x":6,"y":19,"z":20,"color":"#d3ab7d"},{"x":6,"y":19,"z":21,"color":"#d3ab7d"},{"x":6,"y":27,"z":2,"color":"#b48653"},{"x":6,"y":27,"z":3,"color":"#d3ab7d"},{"x":6,"y":27,"z":4,"color":"#e2bf93"},{"x":6,"y":27,"z":5,"color":"#c79a67"},{"x":6,"y":28,"z":2,"color":"#c79a67"},{"x":6,"y":28,"z":3,"color":"#c79a67"},{"x":6,"y":28,"z":4,"color":"#c79a67"},{"x":6,"y":28,"z":5,"color":"#c79a67"},{"x":6,"y":29,"z":1,"color":"#d3ab7d"},{"x":6,"y":29,"z":2,"color":"#c79a67"},{"x":6,"y":29,"z":3,"color":"#d3ab7d"},{"x":6,"y":29,"z":4,"color":"#d3ab7d"},{"x":6,"y":29,"z":5,"color":"#d3ab7d"},{"x":6,"y":30,"z":1,"color":"#e2bf93"},{"x":6,"y":30,"z":2,"color":"#c79a67"},{"x":6,"y":30,"z":3,"color":"#e2bf93"},{"x":6,"y":30,"z":4,"color":"#d3ab7d"},{"x":6,"y":31,"z":1,"color":"#c79a67"},{"x":6,"y":31,"z":2,"color":"#c79a67"},{"x":6,"y":31,"z":3,"color":"#d3ab7d"},{"x":6,"y":31,"z":4,"color":"#c79a67"},{"x":6,"y":32,"z":1,"color":"#c79a67"},{"x":6,"y":32,"z":2,"color":"#d3ab7d"},{"x":6,"y":32,"z":3,"color":"#e2bf93"},{"x":6,"y":32,"z":4,"color":"#d3ab7d"},{"x":6,"y":33,"z":0,"color":"#d3ab7d"},{"x":6,"y":33,"z":1,"color":"#c79a67"},{"x":6,"y":33,"z":2,"color":"#d3ab7d"},{"x":6,"y":33,"z":3,"color":"#d3ab7d"},{"x":6,"y":33,"z":4,"color":"#d3ab7d"},{"x":6,"y":34,"z":0,"color":"#d3ab7d"},{"x":6,"y":34,"z":1,"color":"#c79a67"},{"x":6,"y":34,"z":2,"color":"#d3ab7d"},{"x":6,"y":34,"z":3,"color":"#e2bf93"},{"x":6,"y":34,"z":4,"color":"#d3ab7d"},{"x":7,"y":15,"z":3,"color":"#e2bf93"},{"x":7,"y":15,"z":4,"color":"#c79a67"},{"x":7,"y":15,"z":5,"color":"#c79a67"},{"x":7,"y":15,"z":6,"color":"#c79a67"},{"x":7,"y":15,"z":7,"color":"#c79a67"},{"x":7,"y":15,"z":8,"color":"#c79a67"},{"x":7,"y":15,"z":9,"color":"#c79a67"},{"x":7,"y":15,"z":10,"color":"#d3ab7d"},{"x":7,"y":15,"z":17,"color":"#d3ab7d"},{"x":7,"y":15,"z":18,"color":"#d3ab7d"},{"x":7,"y":15,"z":19,"color":"#d3ab7d"},{"x":7,"y":15,"z":20,"color":"#d3ab7d"},{"x":7,"y":16,"z":3,"color":"#b48653"},{"x":7,"y":16,"z":4,"color":"#b48653"},{"x":7,"y":16,"z":5,"color":"#c79a67"},{"x":7,"y":16,"z":6,"color":"#b48653"},{"x":7,"y":16,"z":7,"color":"#b48653"},{"x":7,"y":16,"z":8,"color":"#b48653"},{"x":7,"y":16,"z":9,"color":"#c79a67"},{"x":7,"y":16,"z":10,"color":"#c79a67"},{"x":7,"y":16,"z":11,"color":"#c79a67"},{"x":7,"y":16,"z":12,"color":"#c79a67"},{"x":7,"y":16,"z":13,"color":"#c79a67"},{"x":7,"y":16,"z":14,"color":"#c79a67"},{"x":7,"y":16,"z":15,"color":"#c79a67"},{"x":7,"y":16,"z":16,"color":"#c79a67"},{"x":7,"y":16,"z":17,"color":"#c79a67"},{"x":7,"y":16,"z":18,"color":"#d3ab7d"},{"x":7,"y":16,"z":19,"color":"#c79a67"},{"x":7,"y":16,"z":20,"color":"#c79a67"},{"x":7,"y":17,"z":3,"color":"#b48653"},{"x":7,"y":17,"z":4,"color":"#c79a67"},{"x":7,"y":17,"z":5,"color":"#c79a67"},{"x":7,"y":17,"z":6,"color":"#b48653"},{"x":7,"y":17,"z":7,"color":"#b48653"},{"x":7,"y":17,"z":8,"color":"#b48653"},{"x":7,"y":17,"z":9,"color":"#966a3b"},{"x":7,"y":17,"z":10,"color":"#b48653"},{"x":7,"y":17,"z":11,"color":"#b48653"},{"x":7,"y":17,"z":12,"color":"#b48653"},{"x":7,"y":17,"z":13,"color":"#b48653"},{"x":7,"y":17,"z":14,"color":"#b48653"},{"x":7,"y":17,"z":15,"color":"#966a3b"},{"x":7,"y":17,"z":16,"color":"#b48653"},{"x":7,"y":17,"z":17,"color":"#966a3b"},{"x":7,"y":17,"z":18,"color":"#966a3b"},{"x":7,"y":17,"z":19,"color":"#c79a67"},{"x":7,"y":17,"z":20,"color":"#c79a67"},{"x":7,"y":17,"z":21,"color":"#b48653"},{"x":7,"y":18,"z":3,"color":"#d3ab7d"},{"x":7,"y":18,"z":4,"color":"#c79a67"},{"x":7,"y":18,"z":5,"color":"#d3ab7d"},{"x":7,"y":18,"z":6,"color":"#c79a67"},{"x":7,"y":18,"z":7,"color":"#c79a67"},{"x":7,"y":18,"z":8,"color":"#c79a67"},{"x":7,"y":18,"z":9,"color":"#c79a67"},{"x":7,"y":18,"z":10,"color":"#d3ab7d"},{"x":7,"y":18,"z":11,"color":"#c79a67"},{"x":7,"y":18,"z":12,"color":"#c79a67"},{"x":7,"y":18,"z":13,"color":"#c79a67"},{"x":7,"y":18,"z":14,"color":"#d3ab7d"},{"x":7,"y":18,"z":15,"color":"#d3ab7d"},{"x":7,"y":18,"z":16,"color":"#d3ab7d"},{"x":7,"y":18,"z":17,"color":"#d3ab7d"},{"x":7,"y":18,"z":18,"color":"#d3ab7d"},{"x":7,"y":18,"z":19,"color":"#d3ab7d"},{"x":7,"y":18,"z":20,"color":"#d3ab7d"},{"x":7,"y":18,"z":21,"color":"#e2bf93"},{"x":7,"y":19,"z":3,"color":"#d3ab7d"},{"x":7,"y":19,"z":4,"color":"#c79a67"},{"x":7,"y":19,"z":5,"color":"#c79a67"},{"x":7,"y":19,"z":6,"color":"#c79a67"},{"x":7,"y":19,"z":7,"color":"#d3ab7d"},{"x":7,"y":19,"z":8,"color":"#c79a67"},{"x":7,"y":19,"z":9,"color":"#c79a67"},{"x":7,"y":19,"z":10,"color":"#c79a67"},{"x":7,"y":19,"z":11,"color":"#c79a67"},{"x":7,"y":19,"z":12,"color":"#c79a67"},{"x":7,"y":19,"z":13,"color":"#d3ab7d"},{"x":7,"y":19,"z":14,"color":"#d3ab7d"},{"x":7,"y":19,"z":15,"color":"#d3ab7d"},{"x":7,"y":19,"z":16,"color":"#d3ab7d"},{"x":7,"y":19,"z":17,"color":"#d3ab7d"},{"x":7,"y":19,"z":18,"color":"#d3ab7d"},{"x":7,"y":19,"z":19,"color":"#d3ab7d"},{"x":7,"y":19,"z":20,"color":"#d3ab7d"},{"x":7,"y":19,"z":21,"color":"#d3ab7d"},{"x":7,"y":27,"z":2,"color":"#b48653"},{"x":7,"y":27,"z":3,"color":"#d3ab7d"},{"x":7,"y":27,"z":4,"color":"#e2bf93"},{"x":7,"y":27,"z":5,"color":"#c79a67"},{"x":7,"y":28,"z":2,"color":"#c79a67"},{"x":7,"y":28,"z":3,"color":"#c79a67"},{"x":7,"y":28,"z":4,"color":"#c79a67"},{"x":7,"y":28,"z":5,"color":"#c79a67"},{"x":7,"y":29,"z":1,"color":"#c79a67"},{"x":7,"y":29,"z":2,"color":"#c79a67"},{"x":7,"y":29,"z":3,"color":"#c79a67"},{"x":7,"y":29,"z":4,"color":"#d3ab7d"},{"x":7,"y":29,"z":5,"color":"#c79a67"},{"x":7,"y":30,"z":1,"color":"#d3ab7d"},{"x":7,"y":30,"z":2,"color":"#c79a67"},{"x":7,"y":30,"z":3,"color":"#d3ab7d"},{"x":7,"y":30,"z":4,"color":"#d3ab7d"},{"x":7,"y":31,"z":1,"color":"#d3ab7d"},{"x":7,"y":31,"z":2,"color":"#c79a67"},{"x":7,"y":31,"z":3,"color":"#d3ab7d"},{"x":7,"y":31,"z":4,"color":"#c79a67"},{"x":7,"y":32,"z":1,"color":"#c79a67"},{"x":7,"y":32,"z":2,"color":"#d3ab7d"},{"x":7,"y":32,"z":3,"color":"#d3ab7d"},{"x":7,"y":32,"z":4,"color":"#c79a67"},{"x":7,"y":33,"z":0,"color":"#c79a67"},{"x":7,"y":33,"z":1,"color":"#b48653"},{"x":7,"y":33,"z":2,"color":"#c79a67"},{"x":7,"y":33,"z":3,"color":"#c79a67"},{"x":7,"y":33,"z":4,"color":"#c79a67"},{"x":7,"y":34,"z":0,"color":"#d3ab7d"},{"x":7,"y":34,"z":1,"color":"#c79a67"},{"x":7,"y":34,"z":2,"color":"#d3ab7d"},{"x":7,"y":34,"z":3,"color":"#d3ab7d"},{"x":7,"y":34,"z":4,"color":"#d3ab7d"},{"x":8,"y":15,"z":3,"color":"#e2bf93"},{"x":8,"y":15,"z":4,"color":"#c79a67"},{"x":8,"y":15,"z":5,"color":"#c79a67"},{"x":8,"y":15,"z":6,"color":"#c79a67"},{"x":8,"y":15,"z":7,"color":"#c79a67"},{"x":8,"y":15,"z":8,"color":"#c79a67"},{"x":8,"y":15,"z":9,"color":"#c79a67"},{"x":8,"y":15,"z":10,"color":"#c79a67"},{"x":8,"y":15,"z":17,"color":"#d3ab7d"},{"x":8,"y":15,"z":18,"color":"#d3ab7d"},{"x":8,"y":15,"z":19,"color":"#d3ab7d"},{"x":8,"y":15,"z":20,"color":"#d3ab7d"},{"x":8,"y":16,"z":3,"color":"#b48653"},{"x":8,"y":16,"z":4,"color":"#b48653"},{"x":8,"y":16,"z":5,"color":"#b48653"},{"x":8,"y":16,"z":6,"color":"#b48653"},{"x":8,"y":16,"z":7,"color":"#b48653"},{"x":8,"y":16,"z":8,"color":"#b48653"},{"x":8,"y":16,"z":9,"color":"#c79a67"},{"x":8,"y":16,"z":10,"color":"#c79a67"},{"x":8,"y":16,"z":11,"color":"#c79a67"},{"x":8,"y":16,"z":12,"color":"#c79a67"},{"x":8,"y":16,"z":13,"color":"#c79a67"},{"x":8,"y":16,"z":14,"color":"#c79a67"},{"x":8,"y":16,"z":15,"color":"#c79a67"},{"x":8,"y":16,"z":16,"color":"#c79a67"},{"x":8,"y":16,"z":17,"color":"#c79a67"},{"x":8,"y":16,"z":18,"color":"#c79a67"},{"x":8,"y":16,"z":19,"color":"#c79a67"},{"x":8,"y":16,"z":20,"color":"#c79a67"},{"x":8,"y":17,"z":3,"color":"#966a3b"},{"x":8,"y":17,"z":4,"color":"#b48653"},{"x":8,"y":17,"z":5,"color":"#b48653"},{"x":8,"y":17,"z":6,"color":"#b48653"},{"x":8,"y":17,"z":7,"color":"#b48653"},{"x":8,"y":17,"z":8,"color":"#b48653"},{"x":8,"y":17,"z":9,"color":"#966a3b"},{"x":8,"y":17,"z":10,"color":"#b48653"},{"x":8,"y":17,"z":11,"color":"#b48653"},{"x":8,"y":17,"z":12,"color":"#b48653"},{"x":8,"y":17,"z":13,"color":"#b48653"},{"x":8,"y":17,"z":14,"color":"#b48653"},{"x":8,"y":17,"z":15,"color":"#966a3b"},{"x":8,"y":17,"z":16,"color":"#b48653"},{"x":8,"y":17,"z":17,"color":"#966a3b"},{"x":8,"y":17,"z":18,"color":"#966a3b"},{"x":8,"y":17,"z":19,"color":"#c79a67"},{"x":8,"y":17,"z":20,"color":"#b48653"},{"x":8,"y":17,"z":21,"color":"#966a3b"},{"x":8,"y":18,"z":3,"color":"#d3ab7d"},{"x":8,"y":18,"z":4,"color":"#c79a67"},{"x":8,"y":18,"z":5,"color":"#d3ab7d"},{"x":8,"y":18,"z":6,"color":"#c79a67"},{"x":8,"y":18,"z":7,"color":"#c79a67"},{"x":8,"y":18,"z":8,"color":"#c79a67"},{"x":8,"y":18,"z":9,"color":"#c79a67"},{"x":8,"y":18,"z":10,"color":"#d3ab7d"},{"x":8,"y":18,"z":11,"color":"#c79a67"},{"x":8,"y":18,"z":12,"color":"#c79a67"},{"x":8,"y":18,"z":13,"color":"#c79a67"},{"x":8,"y":18,"z":14,"color":"#c79a67"},{"x":8,"y":18,"z":15,"color":"#c79a67"},{"x":8,"y":18,"z":16,"color":"#d3ab7d"},{"x":8,"y":18,"z":17,"color":"#d3ab7d"},{"x":8,"y":18,"z":18,"color":"#d3ab7d"},{"x":8,"y":18,"z":19,"color":"#d3ab7d"},{"x":8,"y":18,"z":20,"color":"#d3ab7d"},{"x":8,"y":18,"z":21,"color":"#e2bf93"},{"x":8,"y":19,"z":3,"color":"#d3ab7d"},{"x":8,"y":19,"z":4,"color":"#d3ab7d"},{"x":8,"y":19,"z":5,"color":"#d3ab7d"},{"x":8,"y":19,"z":6,"color":"#c79a67"},{"x":8,"y":19,"z":7,"color":"#d3ab7d"},{"x":8,"y":19,"z":8,"color":"#d3ab7d"},{"x":8,"y":19,"z":9,"color":"#d3ab7d"},{"x":8,"y":19,"z":10,"color":"#c79a67"},{"x":8,"y":19,"z":11,"color":"#d3ab7d"},{"x":8,"y":19,"z":12,"color":"#d3ab7d"},{"x":8,"y":19,"z":13,"color":"#d3ab7d"},{"x":8,"y":19,"z":14,"color":"#d3ab7d"},{"x":8,"y":19,"z":15,"color":"#d3ab7d"},{"x":8,"y":19,"z":16,"color":"#d3ab7d"},{"x":8,"y":19,"z":17,"color":"#d3ab7d"},{"x":8,"y":19,"z":18,"color":"#d3ab7d"},{"x":8,"y":19,"z":19,"color":"#d3ab7d"},{"x":8,"y":19,"z":20,"color":"#d3ab7d"},{"x":8,"y":19,"z":21,"color":"#d3ab7d"},{"x":8,"y":27,"z":2,"color":"#b48653"},{"x":8,"y":27,"z":3,"color":"#d3ab7d"},{"x":8,"y":27,"z":4,"color":"#e2bf93"},{"x":8,"y":27,"z":5,"color":"#b48653"},{"x":8,"y":28,"z":2,"color":"#c79a67"},{"x":8,"y":28,"z":3,"color":"#c79a67"},{"x":8,"y":28,"z":4,"color":"#d3ab7d"},{"x":8,"y":28,"z":5,"color":"#c79a67"},{"x":8,"y":29,"z":1,"color":"#c79a67"},{"x":8,"y":29,"z":2,"color":"#c79a67"},{"x":8,"y":29,"z":3,"color":"#c79a67"},{"x":8,"y":29,"z":4,"color":"#d3ab7d"},{"x":8,"y":29,"z":5,"color":"#c79a67"},{"x":8,"y":30,"z":1,"color":"#d3ab7d"},{"x":8,"y":30,"z":2,"color":"#c79a67"},{"x":8,"y":30,"z":3,"color":"#d3ab7d"},{"x":8,"y":30,"z":4,"color":"#d3ab7d"},{"x":8,"y":31,"z":1,"color":"#d3ab7d"},{"x":8,"y":31,"z":2,"color":"#c79a67"},{"x":8,"y":31,"z":3,"color":"#d3ab7d"},{"x":8,"y":31,"z":4,"color":"#c79a67"},{"x":8,"y":32,"z":1,"color":"#c79a67"},{"x":8,"y":32,"z":2,"color":"#d3ab7d"},{"x":8,"y":32,"z":3,"color":"#d3ab7d"},{"x":8,"y":32,"z":4,"color":"#d3ab7d"},{"x":8,"y":33,"z":0,"color":"#c79a67"},{"x":8,"y":33,"z":1,"color":"#c79a67"},{"x":8,"y":33,"z":2,"color":"#c79a67"},{"x":8,"y":33,"z":3,"color":"#d3ab7d"},{"x":8,"y":33,"z":4,"color":"#c79a67"},{"x":8,"y":34,"z":0,"color":"#d3ab7d"},{"x":8,"y":34,"z":1,"color":"#c79a67"},{"x":8,"y":34,"z":2,"color":"#d3ab7d"},{"x":8,"y":34,"z":3,"color":"#d3ab7d"},{"x":8,"y":34,"z":4,"color":"#c79a67"},{"x":9,"y":15,"z":3,"color":"#e2bf93"},{"x":9,"y":15,"z":4,"color":"#c79a67"},{"x":9,"y":15,"z":5,"color":"#c79a67"},{"x":9,"y":15,"z":6,"color":"#b48653"},{"x":9,"y":15,"z":7,"color":"#b48653"},{"x":9,"y":15,"z":8,"color":"#b48653"},{"x":9,"y":15,"z":9,"color":"#b48653"},{"x":9,"y":15,"z":10,"color":"#b48653"},{"x":9,"y":15,"z":17,"color":"#d3ab7d"},{"x":9,"y":15,"z":18,"color":"#d3ab7d"},{"x":9,"y":15,"z":19,"color":"#c79a67"},{"x":9,"y":15,"z":20,"color":"#d3ab7d"},{"x":9,"y":16,"z":3,"color":"#b48653"},{"x":9,"y":16,"z":4,"color":"#b48653"},{"x":9,"y":16,"z":5,"color":"#b48653"},{"x":9,"y":16,"z":6,"color":"#b48653"},{"x":9,"y":16,"z":7,"color":"#b48653"},{"x":9,"y":16,"z":8,"color":"#966a3b"},{"x":9,"y":16,"z":9,"color":"#b48653"},{"x":9,"y":16,"z":10,"color":"#b48653"},{"x":9,"y":16,"z":11,"color":"#b48653"},{"x":9,"y":16,"z":12,"color":"#b48653"},{"x":9,"y":16,"z":13,"color":"#c79a67"},{"x":9,"y":16,"z":14,"color":"#c79a67"},{"x":9,"y":16,"z":15,"color":"#c79a67"},{"x":9,"y":16,"z":16,"color":"#b48653"},{"x":9,"y":16,"z":17,"color":"#c79a67"},{"x":9,"y":16,"z":18,"color":"#c79a67"},{"x":9,"y":16,"z":19,"color":"#c79a67"},{"x":9,"y":16,"z":20,"color":"#c79a67"},{"x":9,"y":17,"z":3,"color":"#966a3b"},{"x":9,"y":17,"z":4,"color":"#b48653"},{"x":9,"y":17,"z":5,"color":"#b48653"},{"x":9,"y":17,"z":6,"color":"#b48653"},{"x":9,"y":17,"z":7,"color":"#b48653"},{"x":9,"y":17,"z":8,"color":"#b48653"},{"x":9,"y":17,"z":9,"color":"#966a3b"},{"x":9,"y":17,"z":10,"color":"#b48653"},{"x":9,"y":17,"z":11,"color":"#b48653"},{"x":9,"y":17,"z":12,"color":"#b48653"},{"x":9,"y":17,"z":13,"color":"#b48653"},{"x":9,"y":17,"z":14,"color":"#b48653"},{"x":9,"y":17,"z":15,"color":"#966a3b"},{"x":9,"y":17,"z":16,"color":"#b48653"},{"x":9,"y":17,"z":17,"color":"#966a3b"},{"x":9,"y":17,"z":18,"color":"#966a3b"},{"x":9,"y":17,"z":19,"color":"#c79a67"},{"x":9,"y":17,"z":20,"color":"#b48653"},{"x":9,"y":17,"z":21,"color":"#966a3b"},{"x":9,"y":18,"z":3,"color":"#d3ab7d"},{"x":9,"y":18,"z":4,"color":"#c79a67"},{"x":9,"y":18,"z":5,"color":"#d3ab7d"},{"x":9,"y":18,"z":6,"color":"#b48653"},{"x":9,"y":18,"z":7,"color":"#b48653"},{"x":9,"y":18,"z":8,"color":"#c79a67"},{"x":9,"y":18,"z":9,"color":"#c79a67"},{"x":9,"y":18,"z":10,"color":"#d3ab7d"},{"x":9,"y":18,"z":11,"color":"#c79a67"},{"x":9,"y":18,"z":12,"color":"#c79a67"},{"x":9,"y":18,"z":13,"color":"#c79a67"},{"x":9,"y":18,"z":14,"color":"#c79a67"},{"x":9,"y":18,"z":15,"color":"#c79a67"},{"x":9,"y":18,"z":16,"color":"#c79a67"},{"x":9,"y":18,"z":17,"color":"#c79a67"},{"x":9,"y":18,"z":18,"color":"#c79a67"},{"x":9,"y":18,"z":19,"color":"#c79a67"},{"x":9,"y":18,"z":20,"color":"#d3ab7d"},{"x":9,"y":18,"z":21,"color":"#e2bf93"},{"x":9,"y":19,"z":3,"color":"#c79a67"},{"x":9,"y":19,"z":4,"color":"#c79a67"},{"x":9,"y":19,"z":5,"color":"#c79a67"},{"x":9,"y":19,"z":6,"color":"#c79a67"},{"x":9,"y":19,"z":7,"color":"#d3ab7d"},{"x":9,"y":19,"z":8,"color":"#c79a67"},{"x":9,"y":19,"z":9,"color":"#c79a67"},{"x":9,"y":19,"z":10,"color":"#c79a67"},{"x":9,"y":19,"z":11,"color":"#c79a67"},{"x":9,"y":19,"z":12,"color":"#c79a67"},{"x":9,"y":19,"z":13,"color":"#d3ab7d"},{"x":9,"y":19,"z":14,"color":"#d3ab7d"},{"x":9,"y":19,"z":15,"color":"#d3ab7d"},{"x":9,"y":19,"z":16,"color":"#d3ab7d"},{"x":9,"y":19,"z":17,"color":"#d3ab7d"},{"x":9,"y":19,"z":18,"color":"#d3ab7d"},{"x":9,"y":19,"z":19,"color":"#d3ab7d"},{"x":9,"y":19,"z":20,"color":"#d3ab7d"},{"x":9,"y":19,"z":21,"color":"#c79a67"},{"x":9,"y":27,"z":2,"color":"#b48653"},{"x":9,"y":27,"z":3,"color":"#d3ab7d"},{"x":9,"y":27,"z":4,"color":"#e2bf93"},{"x":9,"y":27,"z":5,"color":"#b48653"},{"x":9,"y":28,"z":2,"color":"#c79a67"},{"x":9,"y":28,"z":3,"color":"#c79a67"},{"x":9,"y":28,"z":4,"color":"#c79a67"},{"x":9,"y":28,"z":5,"color":"#c79a67"},{"x":9,"y":29,"z":1,"color":"#b48653"},{"x":9,"y":29,"z":2,"color":"#b48653"},{"x":9,"y":29,"z":3,"color":"#c79a67"},{"x":9,"y":29,"z":4,"color":"#d3ab7d"},{"x":9,"y":29,"z":5,"color":"#b48653"},{"x":9,"y":30,"z":1,"color":"#c79a67"},{"x":9,"y":30,"z":2,"color":"#c79a67"},{"x":9,"y":30,"z":3,"color":"#d3ab7d"},{"x":9,"y":30,"z":4,"color":"#d3ab7d"},{"x":9,"y":31,"z":1,"color":"#d3ab7d"},{"x":9,"y":31,"z":2,"color":"#c79a67"},{"x":9,"y":31,"z":3,"color":"#d3ab7d"},{"x":9,"y":31,"z":4,"color":"#c79a67"},{"x":9,"y":32,"z":1,"color":"#c79a67"},{"x":9,"y":32,"z":2,"color":"#d3ab7d"},{"x":9,"y":32,"z":3,"color":"#d3ab7d"},{"x":9,"y":32,"z":4,"color":"#c79a67"},{"x":9,"y":33,"z":0,"color":"#c79a67"},{"x":9,"y":33,"z":1,"color":"#b48653"},{"x":9,"y":33,"z":2,"color":"#c79a67"},{"x":9,"y":33,"z":3,"color":"#c79a67"},{"x":9,"y":33,"z":4,"color":"#c79a67"},{"x":9,"y":34,"z":0,"color":"#c79a67"},{"x":9,"y":34,"z":1,"color":"#c79a67"},{"x":9,"y":34,"z":2,"color":"#c79a67"},{"x":9,"y":34,"z":3,"color":"#d3ab7d"},{"x":9,"y":34,"z":4,"color":"#c79a67"},{"x":10,"y":15,"z":3,"color":"#e2bf93"},{"x":10,"y":15,"z":4,"color":"#c79a67"},{"x":10,"y":15,"z":5,"color":"#c79a67"},{"x":10,"y":15,"z":6,"color":"#c79a67"},{"x":10,"y":15,"z":7,"color":"#b48653"},{"x":10,"y":15,"z":8,"color":"#c79a67"},{"x":10,"y":15,"z":9,"color":"#b48653"},{"x":10,"y":15,"z":10,"color":"#c79a67"},{"x":10,"y":15,"z":17,"color":"#d3ab7d"},{"x":10,"y":15,"z":18,"color":"#d3ab7d"},{"x":10,"y":15,"z":19,"color":"#c79a67"},{"x":10,"y":15,"z":20,"color":"#c79a67"},{"x":10,"y":16,"z":3,"color":"#b48653"},{"x":10,"y":16,"z":4,"color":"#b48653"},{"x":10,"y":16,"z":5,"color":"#c79a67"},{"x":10,"y":16,"z":6,"color":"#b48653"},{"x":10,"y":16,"z":7,"color":"#b48653"},{"x":10,"y":16,"z":8,"color":"#966a3b"},{"x":10,"y":16,"z":9,"color":"#b48653"},{"x":10,"y":16,"z":10,"color":"#c79a67"},{"x":10,"y":16,"z":11,"color":"#c79a67"},{"x":10,"y":16,"z":12,"color":"#c79a67"},{"x":10,"y":16,"z":13,"color":"#c79a67"},{"x":10,"y":16,"z":14,"color":"#b48653"},{"x":10,"y":16,"z":15,"color":"#c79a67"},{"x":10,"y":16,"z":16,"color":"#b48653"},{"x":10,"y":16,"z":17,"color":"#c79a67"},{"x":10,"y":16,"z":18,"color":"#c79a67"},{"x":10,"y":16,"z":19,"color":"#c79a67"},{"x":10,"y":16,"z":20,"color":"#c79a67"},{"x":10,"y":17,"z":3,"color":"#966a3b"},{"x":10,"y":17,"z":4,"color":"#b48653"},{"x":10,"y":17,"z":5,"color":"#b48653"},{"x":10,"y":17,"z":6,"color":"#b48653"},{"x":10,"y":17,"z":7,"color":"#b48653"},{"x":10,"y":17,"z":8,"color":"#b48653"},{"x":10,"y":17,"z":9,"color":"#966a3b"},{"x":10,"y":17,"z":10,"color":"#b48653"},{"x":10,"y":17,"z":11,"color":"#b48653"},{"x":10,"y":17,"z":12,"color":"#b48653"},{"x":10,"y":17,"z":13,"color":"#b48653"},{"x":10,"y":17,"z":14,"color":"#b48653"},{"x":10,"y":17,"z":15,"color":"#966a3b"},{"x":10,"y":17,"z":16,"color":"#966a3b"},{"x":10,"y":17,"z":17,"color":"#966a3b"},{"x":10,"y":17,"z":18,"color":"#966a3b"},{"x":10,"y":17,"z":19,"color":"#b48653"},{"x":10,"y":17,"z":20,"color":"#b48653"},{"x":10,"y":17,"z":21,"color":"#966a3b"},{"x":10,"y":18,"z":3,"color":"#d3ab7d"},{"x":10,"y":18,"z":4,"color":"#c79a67"},{"x":10,"y":18,"z":5,"color":"#d3ab7d"},{"x":10,"y":18,"z":6,"color":"#c79a67"},{"x":10,"y":18,"z":7,"color":"#b48653"},{"x":10,"y":18,"z":8,"color":"#c79a67"},{"x":10,"y":18,"z":9,"color":"#c79a67"},{"x":10,"y":18,"z":10,"color":"#d3ab7d"},{"x":10,"y":18,"z":11,"color":"#c79a67"},{"x":10,"y":18,"z":12,"color":"#c79a67"},{"x":10,"y":18,"z":13,"color":"#c79a67"},{"x":10,"y":18,"z":14,"color":"#c79a67"},{"x":10,"y":18,"z":15,"color":"#c79a67"},{"x":10,"y":18,"z":16,"color":"#c79a67"},{"x":10,"y":18,"z":17,"color":"#c79a67"},{"x":10,"y":18,"z":18,"color":"#c79a67"},{"x":10,"y":18,"z":19,"color":"#c79a67"},{"x":10,"y":18,"z":20,"color":"#c79a67"},{"x":10,"y":18,"z":21,"color":"#e2bf93"},{"x":10,"y":19,"z":3,"color":"#c79a67"},{"x":10,"y":19,"z":4,"color":"#c79a67"},{"x":10,"y":19,"z":5,"color":"#c79a67"},{"x":10,"y":19,"z":6,"color":"#c79a67"},{"x":10,"y":19,"z":7,"color":"#d3ab7d"},{"x":10,"y":19,"z":8,"color":"#c79a67"},{"x":10,"y":19,"z":9,"color":"#c79a67"},{"x":10,"y":19,"z":10,"color":"#c79a67"},{"x":10,"y":19,"z":11,"color":"#c79a67"},{"x":10,"y":19,"z":12,"color":"#c79a67"},{"x":10,"y":19,"z":13,"color":"#d3ab7d"},{"x":10,"y":19,"z":14,"color":"#d3ab7d"},{"x":10,"y":19,"z":15,"color":"#d3ab7d"},{"x":10,"y":19,"z":16,"color":"#d3ab7d"},{"x":10,"y":19,"z":17,"color":"#d3ab7d"},{"x":10,"y":19,"z":18,"color":"#d3ab7d"},{"x":10,"y":19,"z":19,"color":"#d3ab7d"},{"x":10,"y":19,"z":20,"color":"#d3ab7d"},{"x":10,"y":19,"z":21,"color":"#c79a67"},{"x":10,"y":27,"z":2,"color":"#b48653"},{"x":10,"y":27,"z":3,"color":"#d3ab7d"},{"x":10,"y":27,"z":4,"color":"#e2bf93"},{"x":10,"y":27,"z":5,"color":"#b48653"},{"x":10,"y":28,"z":2,"color":"#c79a67"},{"x":10,"y":28,"z":3,"color":"#c79a67"},{"x":10,"y":28,"z":4,"color":"#c79a67"},{"x":10,"y":28,"z":5,"color":"#c79a67"},{"x":10,"y":29,"z":1,"color":"#b48653"},{"x":10,"y":29,"z":2,"color":"#b48653"},{"x":10,"y":29,"z":3,"color":"#c79a67"},{"x":10,"y":29,"z":4,"color":"#d3ab7d"},{"x":10,"y":29,"z":5,"color":"#b48653"},{"x":10,"y":30,"z":1,"color":"#c79a67"},{"x":10,"y":30,"z":2,"color":"#c79a67"},{"x":10,"y":30,"z":3,"color":"#d3ab7d"},{"x":10,"y":30,"z":4,"color":"#d3ab7d"},{"x":10,"y":31,"z":1,"color":"#c79a67"},{"x":10,"y":31,"z":2,"color":"#c79a67"},{"x":10,"y":31,"z":3,"color":"#c79a67"},{"x":10,"y":31,"z":4,"color":"#b48653"},{"x":10,"y":32,"z":1,"color":"#c79a67"},{"x":10,"y":32,"z":2,"color":"#d3ab7d"},{"x":10,"y":32,"z":3,"color":"#d3ab7d"},{"x":10,"y":32,"z":4,"color":"#c79a67"},{"x":10,"y":33,"z":0,"color":"#c79a67"},{"x":10,"y":33,"z":1,"color":"#b48653"},{"x":10,"y":33,"z":2,"color":"#c79a67"},{"x":10,"y":33,"z":3,"color":"#c79a67"},{"x":10,"y":33,"z":4,"color":"#c79a67"},{"x":10,"y":34,"z":0,"color":"#c79a67"},{"x":10,"y":34,"z":1,"color":"#c79a67"},{"x":10,"y":34,"z":2,"color":"#c79a67"},{"x":10,"y":34,"z":3,"color":"#d3ab7d"},{"x":10,"y":34,"z":4,"color":"#c79a67"},{"x":11,"y":15,"z":3,"color":"#e2bf93"},{"x":11,"y":15,"z":4,"color":"#c79a67"},{"x":11,"y":15,"z":5,"color":"#c79a67"},{"x":11,"y":15,"z":6,"color":"#b48653"},{"x":11,"y":15,"z":7,"color":"#c79a67"},{"x":11,"y":15,"z":8,"color":"#b48653"},{"x":11,"y":15,"z":9,"color":"#c79a67"},{"x":11,"y":15,"z":10,"color":"#c79a67"},{"x":11,"y":15,"z":17,"color":"#d3ab7d"},{"x":11,"y":15,"z":18,"color":"#d3ab7d"},{"x":11,"y":15,"z":19,"color":"#c79a67"},{"x":11,"y":15,"z":20,"color":"#b48653"},{"x":11,"y":16,"z":3,"color":"#b48653"},{"x":11,"y":16,"z":4,"color":"#b48653"},{"x":11,"y":16,"z":5,"color":"#c79a67"},{"x":11,"y":16,"z":6,"color":"#b48653"},{"x":11,"y":16,"z":7,"color":"#b48653"},{"x":11,"y":16,"z":8,"color":"#966a3b"},{"x":11,"y":16,"z":9,"color":"#c79a67"},{"x":11,"y":16,"z":10,"color":"#c79a67"},{"x":11,"y":16,"z":11,"color":"#c79a67"},{"x":11,"y":16,"z":12,"color":"#b48653"},{"x":11,"y":16,"z":13,"color":"#c79a67"},{"x":11,"y":16,"z":14,"color":"#c79a67"},{"x":11,"y":16,"z":15,"color":"#c79a67"},{"x":11,"y":16,"z":16,"color":"#c79a67"},{"x":11,"y":16,"z":17,"color":"#c79a67"},{"x":11,"y":16,"z":18,"color":"#c79a67"},{"x":11,"y":16,"z":19,"color":"#c79a67"},{"x":11,"y":16,"z":20,"color":"#b48653"},{"x":11,"y":17,"z":3,"color":"#966a3b"},{"x":11,"y":17,"z":4,"color":"#b48653"},{"x":11,"y":17,"z":5,"color":"#b48653"},{"x":11,"y":17,"z":6,"color":"#b48653"},{"x":11,"y":17,"z":7,"color":"#b48653"},{"x":11,"y":17,"z":8,"color":"#b48653"},{"x":11,"y":17,"z":9,"color":"#966a3b"},{"x":11,"y":17,"z":10,"color":"#b48653"},{"x":11,"y":17,"z":11,"color":"#b48653"},{"x":11,"y":17,"z":12,"color":"#b48653"},{"x":11,"y":17,"z":13,"color":"#b48653"},{"x":11,"y":17,"z":14,"color":"#b48653"},{"x":11,"y":17,"z":15,"color":"#966a3b"},{"x":11,"y":17,"z":16,"color":"#966a3b"},{"x":11,"y":17,"z":17,"color":"#966a3b"},{"x":11,"y":17,"z":18,"color":"#966a3b"},{"x":11,"y":17,"z":19,"color":"#b48653"},{"x":11,"y":17,"z":20,"color":"#b48653"},{"x":11,"y":17,"z":21,"color":"#966a3b"},{"x":11,"y":18,"z":3,"color":"#d3ab7d"},{"x":11,"y":18,"z":4,"color":"#c79a67"},{"x":11,"y":18,"z":5,"color":"#d3ab7d"},{"x":11,"y":18,"z":6,"color":"#b48653"},{"x":11,"y":18,"z":7,"color":"#c79a67"},{"x":11,"y":18,"z":8,"color":"#c79a67"},{"x":11,"y":18,"z":9,"color":"#c79a67"},{"x":11,"y":18,"z":10,"color":"#d3ab7d"},{"x":11,"y":18,"z":11,"color":"#c79a67"},{"x":11,"y":18,"z":12,"color":"#c79a67"},{"x":11,"y":18,"z":13,"color":"#c79a67"},{"x":11,"y":18,"z":14,"color":"#c79a67"},{"x":11,"y":18,"z":15,"color":"#c79a67"},{"x":11,"y":18,"z":16,"color":"#c79a67"},{"x":11,"y":18,"z":17,"color":"#c79a67"},{"x":11,"y":18,"z":18,"color":"#c79a67"},{"x":11,"y":18,"z":19,"color":"#c79a67"},{"x":11,"y":18,"z":20,"color":"#c79a67"},{"x":11,"y":18,"z":21,"color":"#e2bf93"},{"x":11,"y":19,"z":3,"color":"#d3ab7d"},{"x":11,"y":19,"z":4,"color":"#c79a67"},{"x":11,"y":19,"z":5,"color":"#c79a67"},{"x":11,"y":19,"z":6,"color":"#c79a67"},{"x":11,"y":19,"z":7,"color":"#d3ab7d"},{"x":11,"y":19,"z":8,"color":"#c79a67"},{"x":11,"y":19,"z":9,"color":"#c79a67"},{"x":11,"y":19,"z":10,"color":"#c79a67"},{"x":11,"y":19,"z":11,"color":"#c79a67"},{"x":11,"y":19,"z":12,"color":"#c79a67"},{"x":11,"y":19,"z":13,"color":"#d3ab7d"},{"x":11,"y":19,"z":14,"color":"#d3ab7d"},{"x":11,"y":19,"z":15,"color":"#d3ab7d"},{"x":11,"y":19,"z":16,"color":"#d3ab7d"},{"x":11,"y":19,"z":17,"color":"#d3ab7d"},{"x":11,"y":19,"z":18,"color":"#d3ab7d"},{"x":11,"y":19,"z":19,"color":"#d3ab7d"},{"x":11,"y":19,"z":20,"color":"#d3ab7d"},{"x":11,"y":19,"z":21,"color":"#d3ab7d"},{"x":11,"y":27,"z":2,"color":"#b48653"},{"x":11,"y":27,"z":3,"color":"#d3ab7d"},{"x":11,"y":27,"z":4,"color":"#e2bf93"},{"x":11,"y":27,"z":5,"color":"#966a3b"},{"x":11,"y":28,"z":2,"color":"#b48653"},{"x":11,"y":28,"z":3,"color":"#c79a67"},{"x":11,"y":28,"z":4,"color":"#c79a67"},{"x":11,"y":28,"z":5,"color":"#b48653"},{"x":11,"y":29,"z":1,"color":"#b48653"},{"x":11,"y":29,"z":2,"color":"#b48653"},{"x":11,"y":29,"z":3,"color":"#c79a67"},{"x":11,"y":29,"z":4,"color":"#c79a67"},{"x":11,"y":29,"z":5,"color":"#b48653"},{"x":11,"y":30,"z":1,"color":"#b48653"},{"x":11,"y":30,"z":2,"color":"#b48653"},{"x":11,"y":30,"z":3,"color":"#c79a67"},{"x":11,"y":30,"z":4,"color":"#c79a67"},{"x":11,"y":31,"z":1,"color":"#b48653"},{"x":11,"y":31,"z":2,"color":"#b48653"},{"x":11,"y":31,"z":3,"color":"#c79a67"},{"x":11,"y":31,"z":4,"color":"#b48653"},{"x":11,"y":32,"z":1,"color":"#b48653"},{"x":11,"y":32,"z":2,"color":"#c79a67"},{"x":11,"y":32,"z":3,"color":"#d3ab7d"},{"x":11,"y":32,"z":4,"color":"#b48653"},{"x":11,"y":33,"z":0,"color":"#b48653"},{"x":11,"y":33,"z":1,"color":"#b48653"},{"x":11,"y":33,"z":2,"color":"#b48653"},{"x":11,"y":33,"z":3,"color":"#c79a67"},{"x":11,"y":33,"z":4,"color":"#b48653"},{"x":11,"y":34,"z":0,"color":"#c79a67"},{"x":11,"y":34,"z":1,"color":"#c79a67"},{"x":11,"y":34,"z":2,"color":"#c79a67"},{"x":11,"y":34,"z":3,"color":"#d3ab7d"},{"x":11,"y":34,"z":4,"color":"#b48653"},{"x":12,"y":15,"z":3,"color":"#e2bf93"},{"x":12,"y":15,"z":4,"color":"#c79a67"},{"x":12,"y":15,"z":5,"color":"#c79a67"},{"x":12,"y":15,"z":6,"color":"#b48653"},{"x":12,"y":15,"z":7,"color":"#b48653"},{"x":12,"y":15,"z":8,"color":"#b48653"},{"x":12,"y":15,"z":9,"color":"#b48653"},{"x":12,"y":15,"z":10,"color":"#c79a67"},{"x":12,"y":15,"z":17,"color":"#d3ab7d"},{"x":12,"y":15,"z":18,"color":"#d3ab7d"},{"x":12,"y":15,"z":19,"color":"#d3ab7d"},{"x":12,"y":15,"z":20,"color":"#b48653"},{"x":12,"y":16,"z":3,"color":"#b48653"},{"x":12,"y":16,"z":4,"color":"#b48653"},{"x":12,"y":16,"z":5,"color":"#b48653"},{"x":12,"y":16,"z":6,"color":"#b48653"},{"x":12,"y":16,"z":7,"color":"#b48653"},{"x":12,"y":16,"z":8,"color":"#966a3b"},{"x":12,"y":16,"z":9,"color":"#b48653"},{"x":12,"y":16,"z":10,"color":"#b48653"},{"x":12,"y":16,"z":11,"color":"#b48653"},{"x":12,"y":16,"z":12,"color":"#b48653"},{"x":12,"y":16,"z":13,"color":"#b48653"},{"x":12,"y":16,"z":14,"color":"#c79a67"},{"x":12,"y":16,"z":15,"color":"#c79a67"},{"x":12,"y":16,"z":16,"color":"#c79a67"},{"x":12,"y":16,"z":17,"color":"#c79a67"},{"x":12,"y":16,"z":18,"color":"#c79a67"},{"x":12,"y":16,"z":19,"color":"#c79a67"},{"x":12,"y":16,"z":20,"color":"#b48653"},{"x":12,"y":17,"z":3,"color":"#966a3b"},{"x":12,"y":17,"z":4,"color":"#b48653"},{"x":12,"y":17,"z":5,"color":"#b48653"},{"x":12,"y":17,"z":6,"color":"#b48653"},{"x":12,"y":17,"z":7,"color":"#b48653"},{"x":12,"y":17,"z":8,"color":"#b48653"},{"x":12,"y":17,"z":9,"color":"#966a3b"},{"x":12,"y":17,"z":10,"color":"#b48653"},{"x":12,"y":17,"z":11,"color":"#b48653"},{"x":12,"y":17,"z":12,"color":"#b48653"},{"x":12,"y":17,"z":13,"color":"#b48653"},{"x":12,"y":17,"z":14,"color":"#b48653"},{"x":12,"y":17,"z":15,"color":"#966a3b"},{"x":12,"y":17,"z":16,"color":"#b48653"},{"x":12,"y":17,"z":17,"color":"#966a3b"},{"x":12,"y":17,"z":18,"color":"#966a3b"},{"x":12,"y":17,"z":19,"color":"#c79a67"},{"x":12,"y":17,"z":20,"color":"#b48653"},{"x":12,"y":17,"z":21,"color":"#966a3b"},{"x":12,"y":18,"z":3,"color":"#d3ab7d"},{"x":12,"y":18,"z":4,"color":"#c79a67"},{"x":12,"y":18,"z":5,"color":"#d3ab7d"},{"x":12,"y":18,"z":6,"color":"#b48653"},{"x":12,"y":18,"z":7,"color":"#b48653"},{"x":12,"y":18,"z":8,"color":"#c79a67"},{"x":12,"y":18,"z":9,"color":"#c79a67"},{"x":12,"y":18,"z":10,"color":"#d3ab7d"},{"x":12,"y":18,"z":11,"color":"#c79a67"},{"x":12,"y":18,"z":12,"color":"#c79a67"},{"x":12,"y":18,"z":13,"color":"#c79a67"},{"x":12,"y":18,"z":14,"color":"#c79a67"},{"x":12,"y":18,"z":15,"color":"#c79a67"},{"x":12,"y":18,"z":16,"color":"#c79a67"},{"x":12,"y":18,"z":17,"color":"#c79a67"},{"x":12,"y":18,"z":18,"color":"#c79a67"},{"x":12,"y":18,"z":19,"color":"#d3ab7d"},{"x":12,"y":18,"z":20,"color":"#b48653"},{"x":12,"y":18,"z":21,"color":"#e2bf93"},{"x":12,"y":19,"z":3,"color":"#c79a67"},{"x":12,"y":19,"z":4,"color":"#c79a67"},{"x":12,"y":19,"z":5,"color":"#c79a67"},{"x":12,"y":19,"z":6,"color":"#c79a67"},{"x":12,"y":19,"z":7,"color":"#d3ab7d"},{"x":12,"y":19,"z":8,"color":"#c79a67"},{"x":12,"y":19,"z":9,"color":"#c79a67"},{"x":12,"y":19,"z":10,"color":"#c79a67"},{"x":12,"y":19,"z":11,"color":"#c79a67"},{"x":12,"y":19,"z":12,"color":"#c79a67"},{"x":12,"y":19,"z":13,"color":"#d3ab7d"},{"x":12,"y":19,"z":14,"color":"#d3ab7d"},{"x":12,"y":19,"z":15,"color":"#d3ab7d"},{"x":12,"y":19,"z":16,"color":"#d3ab7d"},{"x":12,"y":19,"z":17,"color":"#d3ab7d"},{"x":12,"y":19,"z":18,"color":"#d3ab7d"},{"x":12,"y":19,"z":19,"color":"#d3ab7d"},{"x":12,"y":19,"z":20,"color":"#d3ab7d"},{"x":12,"y":19,"z":21,"color":"#c79a67"},{"x":12,"y":27,"z":2,"color":"#b48653"},{"x":12,"y":27,"z":3,"color":"#d3ab7d"},{"x":12,"y":27,"z":4,"color":"#e2bf93"},{"x":12,"y":27,"z":5,"color":"#b48653"},{"x":12,"y":28,"z":2,"color":"#b48653"},{"x":12,"y":28,"z":3,"color":"#c79a67"},{"x":12,"y":28,"z":4,"color":"#c79a67"},{"x":12,"y":28,"z":5,"color":"#b48653"},{"x":12,"y":29,"z":1,"color":"#b48653"},{"x":12,"y":29,"z":2,"color":"#b48653"},{"x":12,"y":29,"z":3,"color":"#c79a67"},{"x":12,"y":29,"z":4,"color":"#c79a67"},{"x":12,"y":29,"z":5,"color":"#b48653"},{"x":12,"y":30,"z":1,"color":"#b48653"},{"x":12,"y":30,"z":2,"color":"#b48653"},{"x":12,"y":30,"z":3,"color":"#c79a67"},{"x":12,"y":30,"z":4,"color":"#b48653"},{"x":12,"y":31,"z":1,"color":"#b48653"},{"x":12,"y":31,"z":2,"color":"#b48653"},{"x":12,"y":31,"z":3,"color":"#c79a67"},{"x":12,"y":31,"z":4,"color":"#b48653"},{"x":12,"y":32,"z":1,"color":"#b48653"},{"x":12,"y":32,"z":2,"color":"#b48653"},{"x":12,"y":32,"z":3,"color":"#c79a67"},{"x":12,"y":32,"z":4,"color":"#b48653"},{"x":12,"y":33,"z":0,"color":"#b48653"},{"x":12,"y":33,"z":1,"color":"#b48653"},{"x":12,"y":33,"z":2,"color":"#c79a67"},{"x":12,"y":33,"z":3,"color":"#c79a67"},{"x":12,"y":33,"z":4,"color":"#b48653"},{"x":12,"y":34,"z":0,"color":"#b48653"},{"x":12,"y":34,"z":1,"color":"#b48653"},{"x":12,"y":34,"z":2,"color":"#b48653"},{"x":12,"y":34,"z":3,"color":"#c79a67"},{"x":12,"y":34,"z":4,"color":"#b48653"},{"x":13,"y":15,"z":3,"color":"#e2bf93"},{"x":13,"y":15,"z":4,"color":"#c79a67"},{"x":13,"y":15,"z":5,"color":"#c79a67"},{"x":13,"y":15,"z":6,"color":"#b48653"},{"x":13,"y":15,"z":7,"color":"#b48653"},{"x":13,"y":15,"z":8,"color":"#b48653"},{"x":13,"y":15,"z":9,"color":"#c79a67"},{"x":13,"y":15,"z":10,"color":"#c79a67"},{"x":13,"y":15,"z":17,"color":"#d3ab7d"},{"x":13,"y":15,"z":18,"color":"#d3ab7d"},{"x":13,"y":15,"z":19,"color":"#c79a67"},{"x":13,"y":15,"z":20,"color":"#b48653"},{"x":13,"y":16,"z":3,"color":"#e2bf93"},{"x":13,"y":16,"z":4,"color":"#b48653"},{"x":13,"y":16,"z":5,"color":"#c79a67"},{"x":13,"y":16,"z":6,"color":"#b48653"},{"x":13,"y":16,"z":7,"color":"#b48653"},{"x":13,"y":16,"z":8,"color":"#966a3b"},{"x":13,"y":16,"z":9,"color":"#c79a67"},{"x":13,"y":16,"z":10,"color":"#c79a67"},{"x":13,"y":16,"z":11,"color":"#c79a67"},{"x":13,"y":16,"z":12,"color":"#c79a67"},{"x":13,"y":16,"z":13,"color":"#c79a67"},{"x":13,"y":16,"z":14,"color":"#c79a67"},{"x":13,"y":16,"z":15,"color":"#c79a67"},{"x":13,"y":16,"z":16,"color":"#c79a67"},{"x":13,"y":16,"z":17,"color":"#c79a67"},{"x":13,"y":16,"z":18,"color":"#c79a67"},{"x":13,"y":16,"z":19,"color":"#c79a67"},{"x":13,"y":16,"z":20,"color":"#c79a67"},{"x":13,"y":17,"z":3,"color":"#c79a67"},{"x":13,"y":17,"z":4,"color":"#c79a67"},{"x":13,"y":17,"z":5,"color":"#c79a67"},{"x":13,"y":17,"z":6,"color":"#b48653"},{"x":13,"y":17,"z":7,"color":"#b48653"},{"x":13,"y":17,"z":8,"color":"#b48653"},{"x":13,"y":17,"z":9,"color":"#966a3b"},{"x":13,"y":17,"z":10,"color":"#b48653"},{"x":13,"y":17,"z":11,"color":"#b48653"},{"x":13,"y":17,"z":12,"color":"#b48653"},{"x":13,"y":17,"z":13,"color":"#b48653"},{"x":13,"y":17,"z":14,"color":"#b48653"},{"x":13,"y":17,"z":15,"color":"#966a3b"},{"x":13,"y":17,"z":16,"color":"#b48653"},{"x":13,"y":17,"z":17,"color":"#966a3b"},{"x":13,"y":17,"z":18,"color":"#966a3b"},{"x":13,"y":17,"z":19,"color":"#c79a67"},{"x":13,"y":17,"z":20,"color":"#b48653"},{"x":13,"y":17,"z":21,"color":"#b48653"},{"x":13,"y":18,"z":3,"color":"#d3ab7d"},{"x":13,"y":18,"z":4,"color":"#c79a67"},{"x":13,"y":18,"z":5,"color":"#d3ab7d"},{"x":13,"y":18,"z":6,"color":"#b48653"},{"x":13,"y":18,"z":7,"color":"#b48653"},{"x":13,"y":18,"z":8,"color":"#c79a67"},{"x":13,"y":18,"z":9,"color":"#c79a67"},{"x":13,"y":18,"z":10,"color":"#d3ab7d"},{"x":13,"y":18,"z":11,"color":"#c79a67"},{"x":13,"y":18,"z":12,"color":"#c79a67"},{"x":13,"y":18,"z":13,"color":"#c79a67"},{"x":13,"y":18,"z":14,"color":"#c79a67"},{"x":13,"y":18,"z":15,"color":"#c79a67"},{"x":13,"y":18,"z":16,"color":"#c79a67"},{"x":13,"y":18,"z":17,"color":"#d3ab7d"},{"x":13,"y":18,"z":18,"color":"#c79a67"},{"x":13,"y":18,"z":19,"color":"#c79a67"},{"x":13,"y":18,"z":20,"color":"#b48653"},{"x":13,"y":18,"z":21,"color":"#e2bf93"},{"x":13,"y":19,"z":3,"color":"#d3ab7d"},{"x":13,"y":19,"z":4,"color":"#c79a67"},{"x":13,"y":19,"z":5,"color":"#c79a67"},{"x":13,"y":19,"z":6,"color":"#c79a67"},{"x":13,"y":19,"z":7,"color":"#d3ab7d"},{"x":13,"y":19,"z":8,"color":"#c79a67"},{"x":13,"y":19,"z":9,"color":"#c79a67"},{"x":13,"y":19,"z":10,"color":"#c79a67"},{"x":13,"y":19,"z":11,"color":"#c79a67"},{"x":13,"y":19,"z":12,"color":"#c79a67"},{"x":13,"y":19,"z":13,"color":"#d3ab7d"},{"x":13,"y":19,"z":14,"color":"#d3ab7d"},{"x":13,"y":19,"z":15,"color":"#d3ab7d"},{"x":13,"y":19,"z":16,"color":"#d3ab7d"},{"x":13,"y":19,"z":17,"color":"#d3ab7d"},{"x":13,"y":19,"z":18,"color":"#d3ab7d"},{"x":13,"y":19,"z":19,"color":"#d3ab7d"},{"x":13,"y":19,"z":20,"color":"#d3ab7d"},{"x":13,"y":19,"z":21,"color":"#d3ab7d"},{"x":13,"y":27,"z":2,"color":"#b48653"},{"x":13,"y":27,"z":3,"color":"#d3ab7d"},{"x":13,"y":27,"z":4,"color":"#e2bf93"},{"x":13,"y":27,"z":5,"color":"#b48653"},{"x":13,"y":28,"z":2,"color":"#b48653"},{"x":13,"y":28,"z":3,"color":"#c79a67"},{"x":13,"y":28,"z":4,"color":"#c79a67"},{"x":13,"y":28,"z":5,"color":"#b48653"},{"x":13,"y":29,"z":1,"color":"#b48653"},{"x":13,"y":29,"z":2,"color":"#b48653"},{"x":13,"y":29,"z":3,"color":"#c79a67"},{"x":13,"y":29,"z":4,"color":"#c79a67"},{"x":13,"y":29,"z":5,"color":"#b48653"},{"x":13,"y":30,"z":1,"color":"#b48653"},{"x":13,"y":30,"z":2,"color":"#b48653"},{"x":13,"y":30,"z":3,"color":"#d3ab7d"},{"x":13,"y":30,"z":4,"color":"#b48653"},{"x":13,"y":31,"z":1,"color":"#b48653"},{"x":13,"y":31,"z":2,"color":"#b48653"},{"x":13,"y":31,"z":3,"color":"#d3ab7d"},{"x":13,"y":31,"z":4,"color":"#b48653"},{"x":13,"y":32,"z":1,"color":"#b48653"},{"x":13,"y":32,"z":2,"color":"#b48653"},{"x":13,"y":32,"z":3,"color":"#e2bf93"},{"x":13,"y":32,"z":4,"color":"#b48653"},{"x":13,"y":33,"z":0,"color":"#b48653"},{"x":13,"y":33,"z":1,"color":"#b48653"},{"x":13,"y":33,"z":2,"color":"#b48653"},{"x":13,"y":33,"z":3,"color":"#d3ab7d"},{"x":13,"y":33,"z":4,"color":"#b48653"},{"x":13,"y":34,"z":0,"color":"#b48653"},{"x":13,"y":34,"z":1,"color":"#b48653"},{"x":13,"y":34,"z":2,"color":"#c79a67"},{"x":13,"y":34,"z":3,"color":"#e2bf93"},{"x":13,"y":34,"z":4,"color":"#b48653"},{"x":14,"y":15,"z":3,"color":"#d3ab7d"},{"x":14,"y":15,"z":4,"color":"#c79a67"},{"x":14,"y":15,"z":5,"color":"#c79a67"},{"x":14,"y":15,"z":6,"color":"#b48653"},{"x":14,"y":15,"z":7,"color":"#b48653"},{"x":14,"y":15,"z":8,"color":"#c79a67"},{"x":14,"y":15,"z":9,"color":"#c79a67"},{"x":14,"y":15,"z":10,"color":"#c79a67"},{"x":14,"y":15,"z":17,"color":"#d3ab7d"},{"x":14,"y":15,"z":18,"color":"#d3ab7d"},{"x":14,"y":15,"z":19,"color":"#c79a67"},{"x":14,"y":15,"z":20,"color":"#b48653"},{"x":14,"y":16,"z":3,"color":"#b48653"},{"x":14,"y":16,"z":4,"color":"#b48653"},{"x":14,"y":16,"z":5,"color":"#c79a67"},{"x":14,"y":16,"z":6,"color":"#b48653"},{"x":14,"y":16,"z":7,"color":"#b48653"},{"x":14,"y":16,"z":8,"color":"#b48653"},{"x":14,"y":16,"z":9,"color":"#c79a67"},{"x":14,"y":16,"z":10,"color":"#c79a67"},{"x":14,"y":16,"z":11,"color":"#c79a67"},{"x":14,"y":16,"z":12,"color":"#c79a67"},{"x":14,"y":16,"z":13,"color":"#c79a67"},{"x":14,"y":16,"z":14,"color":"#c79a67"},{"x":14,"y":16,"z":15,"color":"#c79a67"},{"x":14,"y":16,"z":16,"color":"#c79a67"},{"x":14,"y":16,"z":17,"color":"#c79a67"},{"x":14,"y":16,"z":18,"color":"#d3ab7d"},{"x":14,"y":16,"z":19,"color":"#c79a67"},{"x":14,"y":16,"z":20,"color":"#b48653"},{"x":14,"y":17,"z":3,"color":"#966a3b"},{"x":14,"y":17,"z":4,"color":"#c79a67"},{"x":14,"y":17,"z":5,"color":"#c79a67"},{"x":14,"y":17,"z":6,"color":"#b48653"},{"x":14,"y":17,"z":7,"color":"#b48653"},{"x":14,"y":17,"z":8,"color":"#b48653"},{"x":14,"y":17,"z":9,"color":"#966a3b"},{"x":14,"y":17,"z":10,"color":"#b48653"},{"x":14,"y":17,"z":11,"color":"#b48653"},{"x":14,"y":17,"z":12,"color":"#b48653"},{"x":14,"y":17,"z":13,"color":"#b48653"},{"x":14,"y":17,"z":14,"color":"#b48653"},{"x":14,"y":17,"z":15,"color":"#966a3b"},{"x":14,"y":17,"z":16,"color":"#b48653"},{"x":14,"y":17,"z":17,"color":"#966a3b"},{"x":14,"y":17,"z":18,"color":"#966a3b"},{"x":14,"y":17,"z":19,"color":"#c79a67"},{"x":14,"y":17,"z":20,"color":"#b48653"},{"x":14,"y":17,"z":21,"color":"#b48653"},{"x":14,"y":18,"z":3,"color":"#d3ab7d"},{"x":14,"y":18,"z":4,"color":"#c79a67"},{"x":14,"y":18,"z":5,"color":"#d3ab7d"},{"x":14,"y":18,"z":6,"color":"#b48653"},{"x":14,"y":18,"z":7,"color":"#b48653"},{"x":14,"y":18,"z":8,"color":"#c79a67"},{"x":14,"y":18,"z":9,"color":"#c79a67"},{"x":14,"y":18,"z":10,"color":"#d3ab7d"},{"x":14,"y":18,"z":11,"color":"#c79a67"},{"x":14,"y":18,"z":12,"color":"#c79a67"},{"x":14,"y":18,"z":13,"color":"#c79a67"},{"x":14,"y":18,"z":14,"color":"#c79a67"},{"x":14,"y":18,"z":15,"color":"#c79a67"},{"x":14,"y":18,"z":16,"color":"#c79a67"},{"x":14,"y":18,"z":17,"color":"#d3ab7d"},{"x":14,"y":18,"z":18,"color":"#d3ab7d"},{"x":14,"y":18,"z":19,"color":"#c79a67"},{"x":14,"y":18,"z":20,"color":"#b48653"},{"x":14,"y":18,"z":21,"color":"#e2bf93"},{"x":14,"y":19,"z":3,"color":"#c79a67"},{"x":14,"y":19,"z":4,"color":"#c79a67"},{"x":14,"y":19,"z":5,"color":"#c79a67"},{"x":14,"y":19,"z":6,"color":"#c79a67"},{"x":14,"y":19,"z":7,"color":"#d3ab7d"},{"x":14,"y":19,"z":8,"color":"#c79a67"},{"x":14,"y":19,"z":9,"color":"#c79a67"},{"x":14,"y":19,"z":10,"color":"#c79a67"},{"x":14,"y":19,"z":11,"color":"#c79a67"},{"x":14,"y":19,"z":12,"color":"#c79a67"},{"x":14,"y":19,"z":13,"color":"#d3ab7d"},{"x":14,"y":19,"z":14,"color":"#d3ab7d"},{"x":14,"y":19,"z":15,"color":"#d3ab7d"},{"x":14,"y":19,"z":16,"color":"#d3ab7d"},{"x":14,"y":19,"z":17,"color":"#d3ab7d"},{"x":14,"y":19,"z":18,"color":"#d3ab7d"},{"x":14,"y":19,"z":19,"color":"#d3ab7d"},{"x":14,"y":19,"z":20,"color":"#d3ab7d"},{"x":14,"y":19,"z":21,"color":"#d3ab7d"},{"x":14,"y":27,"z":2,"color":"#b48653"},{"x":14,"y":27,"z":3,"color":"#c79a67"},{"x":14,"y":27,"z":4,"color":"#e2bf93"},{"x":14,"y":27,"z":5,"color":"#966a3b"},{"x":14,"y":28,"z":2,"color":"#b48653"},{"x":14,"y":28,"z":3,"color":"#b48653"},{"x":14,"y":28,"z":4,"color":"#b48653"},{"x":14,"y":28,"z":5,"color":"#b48653"},{"x":14,"y":29,"z":1,"color":"#b48653"},{"x":14,"y":29,"z":2,"color":"#b48653"},{"x":14,"y":29,"z":3,"color":"#b48653"},{"x":14,"y":29,"z":4,"color":"#b48653"},{"x":14,"y":29,"z":5,"color":"#b48653"},{"x":14,"y":30,"z":1,"color":"#b48653"},{"x":14,"y":30,"z":2,"color":"#b48653"},{"x":14,"y":30,"z":3,"color":"#b48653"},{"x":14,"y":30,"z":4,"color":"#b48653"},{"x":14,"y":31,"z":1,"color":"#b48653"},{"x":14,"y":31,"z":2,"color":"#b48653"},{"x":14,"y":31,"z":3,"color":"#b48653"},{"x":14,"y":31,"z":4,"color":"#b48653"},{"x":14,"y":32,"z":1,"color":"#c79a67"},{"x":14,"y":32,"z":2,"color":"#c79a67"},{"x":14,"y":32,"z":3,"color":"#c79a67"},{"x":14,"y":32,"z":4,"color":"#c79a67"},{"x":14,"y":33,"z":0,"color":"#b48653"},{"x":14,"y":33,"z":1,"color":"#b48653"},{"x":14,"y":33,"z":2,"color":"#b48653"},{"x":14,"y":33,"z":3,"color":"#b48653"},{"x":14,"y":33,"z":4,"color":"#b48653"},{"x":14,"y":34,"z":0,"color":"#b48653"},{"x":14,"y":34,"z":1,"color":"#b48653"},{"x":14,"y":34,"z":2,"color":"#c79a67"},{"x":14,"y":34,"z":3,"color":"#c79a67"},{"x":14,"y":34,"z":4,"color":"#b48653"},{"x":15,"y":15,"z":3,"color":"#e2bf93"},{"x":15,"y":15,"z":4,"color":"#c79a67"},{"x":15,"y":15,"z":5,"color":"#c79a67"},{"x":15,"y":15,"z":6,"color":"#c79a67"},{"x":15,"y":15,"z":7,"color":"#c79a67"},{"x":15,"y":15,"z":8,"color":"#c79a67"},{"x":15,"y":15,"z":9,"color":"#d3ab7d"},{"x":15,"y":15,"z":10,"color":"#d3ab7d"},{"x":15,"y":15,"z":17,"color":"#d3ab7d"},{"x":15,"y":15,"z":18,"color":"#d3ab7d"},{"x":15,"y":15,"z":19,"color":"#d3ab7d"},{"x":15,"y":15,"z":20,"color":"#966a3b"},{"x":15,"y":16,"z":3,"color":"#b48653"},{"x":15,"y":16,"z":4,"color":"#b48653"},{"x":15,"y":16,"z":5,"color":"#c79a67"},{"x":15,"y":16,"z":6,"color":"#b48653"},{"x":15,"y":16,"z":7,"color":"#b48653"},{"x":15,"y":16,"z":8,"color":"#b48653"},{"x":15,"y":16,"z":9,"color":"#d3ab7d"},{"x":15,"y":16,"z":10,"color":"#c79a67"},{"x":15,"y":16,"z":11,"color":"#c79a67"},{"x":15,"y":16,"z":12,"color":"#c79a67"},{"x":15,"y":16,"z":13,"color":"#c79a67"},{"x":15,"y":16,"z":14,"color":"#c79a67"},{"x":15,"y":16,"z":15,"color":"#c79a67"},{"x":15,"y":16,"z":16,"color":"#c79a67"},{"x":15,"y":16,"z":17,"color":"#c79a67"},{"x":15,"y":16,"z":18,"color":"#c79a67"},{"x":15,"y":16,"z":19,"color":"#c79a67"},{"x":15,"y":16,"z":20,"color":"#b48653"},{"x":15,"y":17,"z":3,"color":"#966a3b"},{"x":15,"y":17,"z":4,"color":"#c79a67"},{"x":15,"y":17,"z":5,"color":"#c79a67"},{"x":15,"y":17,"z":6,"color":"#b48653"},{"x":15,"y":17,"z":7,"color":"#b48653"},{"x":15,"y":17,"z":8,"color":"#b48653"},{"x":15,"y":17,"z":9,"color":"#966a3b"},{"x":15,"y":17,"z":10,"color":"#b48653"},{"x":15,"y":17,"z":11,"color":"#b48653"},{"x":15,"y":17,"z":12,"color":"#b48653"},{"x":15,"y":17,"z":13,"color":"#b48653"},{"x":15,"y":17,"z":14,"color":"#b48653"},{"x":15,"y":17,"z":15,"color":"#966a3b"},{"x":15,"y":17,"z":16,"color":"#b48653"},{"x":15,"y":17,"z":17,"color":"#966a3b"},{"x":15,"y":17,"z":18,"color":"#966a3b"},{"x":15,"y":17,"z":19,"color":"#c79a67"},{"x":15,"y":17,"z":20,"color":"#966a3b"},{"x":15,"y":17,"z":21,"color":"#b48653"},{"x":15,"y":18,"z":3,"color":"#c79a67"},{"x":15,"y":18,"z":4,"color":"#c79a67"},{"x":15,"y":18,"z":5,"color":"#c79a67"},{"x":15,"y":18,"z":6,"color":"#c79a67"},{"x":15,"y":18,"z":7,"color":"#c79a67"},{"x":15,"y":18,"z":8,"color":"#c79a67"},{"x":15,"y":18,"z":9,"color":"#c79a67"},{"x":15,"y":18,"z":10,"color":"#c79a67"},{"x":15,"y":18,"z":11,"color":"#c79a67"},{"x":15,"y":18,"z":12,"color":"#c79a67"},{"x":15,"y":18,"z":13,"color":"#c79a67"},{"x":15,"y":18,"z":14,"color":"#c79a67"},{"x":15,"y":18,"z":15,"color":"#c79a67"},{"x":15,"y":18,"z":16,"color":"#c79a67"},{"x":15,"y":18,"z":17,"color":"#c79a67"},{"x":15,"y":18,"z":18,"color":"#c79a67"},{"x":15,"y":18,"z":19,"color":"#c79a67"},{"x":15,"y":18,"z":20,"color":"#b48653"},{"x":15,"y":18,"z":21,"color":"#e2bf93"},{"x":15,"y":19,"z":3,"color":"#d3ab7d"},{"x":15,"y":19,"z":4,"color":"#d3ab7d"},{"x":15,"y":19,"z":5,"color":"#d3ab7d"},{"x":15,"y":19,"z":6,"color":"#c79a67"},{"x":15,"y":19,"z":7,"color":"#d3ab7d"},{"x":15,"y":19,"z":8,"color":"#d3ab7d"},{"x":15,"y":19,"z":9,"color":"#d3ab7d"},{"x":15,"y":19,"z":10,"color":"#d3ab7d"},{"x":15,"y":19,"z":11,"color":"#c79a67"},{"x":15,"y":19,"z":12,"color":"#d3ab7d"},{"x":15,"y":19,"z":13,"color":"#d3ab7d"},{"x":15,"y":19,"z":14,"color":"#d3ab7d"},{"x":15,"y":19,"z":15,"color":"#d3ab7d"},{"x":15,"y":19,"z":16,"color":"#d3ab7d"},{"x":15,"y":19,"z":17,"color":"#d3ab7d"},{"x":15,"y":19,"z":18,"color":"#d3ab7d"},{"x":15,"y":19,"z":19,"color":"#d3ab7d"},{"x":15,"y":19,"z":20,"color":"#d3ab7d"},{"x":15,"y":19,"z":21,"color":"#d3ab7d"},{"x":15,"y":27,"z":2,"color":"#b48653"},{"x":15,"y":27,"z":3,"color":"#c79a67"},{"x":15,"y":27,"z":4,"color":"#e2bf93"},{"x":15,"y":27,"z":5,"color":"#b48653"},{"x":15,"y":28,"z":2,"color":"#b48653"},{"x":15,"y":28,"z":3,"color":"#b48653"},{"x":15,"y":28,"z":4,"color":"#c79a67"},{"x":15,"y":28,"z":5,"color":"#b48653"},{"x":15,"y":29,"z":1,"color":"#966a3b"},{"x":15,"y":29,"z":2,"color":"#b48653"},{"x":15,"y":29,"z":3,"color":"#b48653"},{"x":15,"y":29,"z":4,"color":"#b48653"},{"x":15,"y":29,"z":5,"color":"#966a3b"},{"x":15,"y":30,"z":1,"color":"#b48653"},{"x":15,"y":30,"z":2,"color":"#b48653"},{"x":15,"y":30,"z":3,"color":"#b48653"},{"x":15,"y":30,"z":4,"color":"#b48653"},{"x":15,"y":31,"z":1,"color":"#b48653"},{"x":15,"y":31,"z":2,"color":"#b48653"},{"x":15,"y":31,"z":3,"color":"#b48653"},{"x":15,"y":31,"z":4,"color":"#966a3b"},{"x":15,"y":32,"z":1,"color":"#b48653"},{"x":15,"y":32,"z":2,"color":"#b48653"},{"x":15,"y":32,"z":3,"color":"#b48653"},{"x":15,"y":32,"z":4,"color":"#b48653"},{"x":15,"y":33,"z":0,"color":"#b48653"},{"x":15,"y":33,"z":1,"color":"#b48653"},{"x":15,"y":33,"z":2,"color":"#b48653"},{"x":15,"y":33,"z":3,"color":"#b48653"},{"x":15,"y":33,"z":4,"color":"#b48653"},{"x":15,"y":34,"z":0,"color":"#b48653"},{"x":15,"y":34,"z":1,"color":"#c79a67"},{"x":15,"y":34,"z":2,"color":"#c79a67"},{"x":15,"y":34,"z":3,"color":"#c79a67"},{"x":15,"y":34,"z":4,"color":"#b48653"},{"x":15,"y":35,"z":1,"color":"#c79a67"},{"x":15,"y":35,"z":2,"color":"#b48653"},{"x":15,"y":35,"z":3,"color":"#966a3b"},{"x":16,"y":15,"z":3,"color":"#e2bf93"},{"x":16,"y":15,"z":4,"color":"#c79a67"},{"x":16,"y":15,"z":5,"color":"#c79a67"},{"x":16,"y":15,"z":6,"color":"#c79a67"},{"x":16,"y":15,"z":7,"color":"#d3ab7d"},{"x":16,"y":15,"z":8,"color":"#d3ab7d"},{"x":16,"y":15,"z":9,"color":"#d3ab7d"},{"x":16,"y":15,"z":10,"color":"#c79a67"},{"x":16,"y":15,"z":17,"color":"#d3ab7d"},{"x":16,"y":15,"z":18,"color":"#d3ab7d"},{"x":16,"y":15,"z":19,"color":"#e2bf93"},{"x":16,"y":15,"z":20,"color":"#e2bf93"},{"x":16,"y":16,"z":3,"color":"#966a3b"},{"x":16,"y":16,"z":4,"color":"#b48653"},{"x":16,"y":16,"z":5,"color":"#b48653"},{"x":16,"y":16,"z":6,"color":"#b48653"},{"x":16,"y":16,"z":7,"color":"#b48653"},{"x":16,"y":16,"z":8,"color":"#966a3b"},{"x":16,"y":16,"z":9,"color":"#c79a67"},{"x":16,"y":16,"z":10,"color":"#b48653"},{"x":16,"y":16,"z":11,"color":"#b48653"},{"x":16,"y":16,"z":12,"color":"#b48653"},{"x":16,"y":16,"z":13,"color":"#b48653"},{"x":16,"y":16,"z":14,"color":"#b48653"},{"x":16,"y":16,"z":15,"color":"#b48653"},{"x":16,"y":16,"z":16,"color":"#b48653"},{"x":16,"y":16,"z":17,"color":"#c79a67"},{"x":16,"y":16,"z":18,"color":"#c79a67"},{"x":16,"y":16,"z":19,"color":"#b48653"},{"x":16,"y":16,"z":20,"color":"#b48653"},{"x":16,"y":17,"z":3,"color":"#966a3b"},{"x":16,"y":17,"z":4,"color":"#b48653"},{"x":16,"y":17,"z":5,"color":"#b48653"},{"x":16,"y":17,"z":6,"color":"#b48653"},{"x":16,"y":17,"z":7,"color":"#b48653"},{"x":16,"y":17,"z":8,"color":"#b48653"},{"x":16,"y":17,"z":9,"color":"#966a3b"},{"x":16,"y":17,"z":10,"color":"#b48653"},{"x":16,"y":17,"z":11,"color":"#b48653"},{"x":16,"y":17,"z":12,"color":"#b48653"},{"x":16,"y":17,"z":13,"color":"#b48653"},{"x":16,"y":17,"z":14,"color":"#b48653"},{"x":16,"y":17,"z":15,"color":"#966a3b"},{"x":16,"y":17,"z":16,"color":"#b48653"},{"x":16,"y":17,"z":17,"color":"#966a3b"},{"x":16,"y":17,"z":18,"color":"#966a3b"},{"x":16,"y":17,"z":19,"color":"#c79a67"},{"x":16,"y":17,"z":20,"color":"#b48653"},{"x":16,"y":17,"z":21,"color":"#966a3b"},{"x":16,"y":18,"z":3,"color":"#c79a67"},{"x":16,"y":18,"z":4,"color":"#c79a67"},{"x":16,"y":18,"z":5,"color":"#c79a67"},{"x":16,"y":18,"z":6,"color":"#c79a67"},{"x":16,"y":18,"z":7,"color":"#c79a67"},{"x":16,"y":18,"z":8,"color":"#c79a67"},{"x":16,"y":18,"z":9,"color":"#c79a67"},{"x":16,"y":18,"z":10,"color":"#c79a67"},{"x":16,"y":18,"z":11,"color":"#c79a67"},{"x":16,"y":18,"z":12,"color":"#c79a67"},{"x":16,"y":18,"z":13,"color":"#c79a67"},{"x":16,"y":18,"z":14,"color":"#c79a67"},{"x":16,"y":18,"z":15,"color":"#c79a67"},{"x":16,"y":18,"z":16,"color":"#c79a67"},{"x":16,"y":18,"z":17,"color":"#c79a67"},{"x":16,"y":18,"z":18,"color":"#c79a67"},{"x":16,"y":18,"z":19,"color":"#c79a67"},{"x":16,"y":18,"z":20,"color":"#c79a67"},{"x":16,"y":18,"z":21,"color":"#e2bf93"},{"x":16,"y":19,"z":3,"color":"#d3ab7d"},{"x":16,"y":19,"z":4,"color":"#d3ab7d"},{"x":16,"y":19,"z":5,"color":"#d3ab7d"},{"x":16,"y":19,"z":6,"color":"#c79a67"},{"x":16,"y":19,"z":7,"color":"#d3ab7d"},{"x":16,"y":19,"z":8,"color":"#d3ab7d"},{"x":16,"y":19,"z":9,"color":"#d3ab7d"},{"x":16,"y":19,"z":10,"color":"#c79a67"},{"x":16,"y":19,"z":11,"color":"#d3ab7d"},{"x":16,"y":19,"z":12,"color":"#d3ab7d"},{"x":16,"y":19,"z":13,"color":"#d3ab7d"},{"x":16,"y":19,"z":14,"color":"#d3ab7d"},{"x":16,"y":19,"z":15,"color":"#d3ab7d"},{"x":16,"y":19,"z":16,"color":"#d3ab7d"},{"x":16,"y":19,"z":17,"color":"#d3ab7d"},{"x":16,"y":19,"z":18,"color":"#d3ab7d"},{"x":16,"y":19,"z":19,"color":"#d3ab7d"},{"x":16,"y":19,"z":20,"color":"#d3ab7d"},{"x":16,"y":19,"z":21,"color":"#d3ab7d"},{"x":16,"y":27,"z":2,"color":"#b48653"},{"x":16,"y":27,"z":3,"color":"#c79a67"},{"x":16,"y":27,"z":4,"color":"#e2bf93"},{"x":16,"y":27,"z":5,"color":"#966a3b"},{"x":16,"y":28,"z":2,"color":"#b48653"},{"x":16,"y":28,"z":3,"color":"#c79a67"},{"x":16,"y":28,"z":4,"color":"#c79a67"},{"x":16,"y":28,"z":5,"color":"#966a3b"},{"x":16,"y":29,"z":1,"color":"#b48653"},{"x":16,"y":29,"z":2,"color":"#b48653"},{"x":16,"y":29,"z":3,"color":"#b48653"},{"x":16,"y":29,"z":4,"color":"#b48653"},{"x":16,"y":29,"z":5,"color":"#966a3b"},{"x":16,"y":30,"z":1,"color":"#b48653"},{"x":16,"y":30,"z":2,"color":"#b48653"},{"x":16,"y":30,"z":3,"color":"#b48653"},{"x":16,"y":30,"z":4,"color":"#b48653"},{"x":16,"y":31,"z":1,"color":"#c79a67"},{"x":16,"y":31,"z":2,"color":"#c79a67"},{"x":16,"y":31,"z":3,"color":"#c79a67"},{"x":16,"y":31,"z":4,"color":"#966a3b"},{"x":16,"y":32,"z":1,"color":"#c79a67"},{"x":16,"y":32,"z":2,"color":"#b48653"},{"x":16,"y":32,"z":3,"color":"#b48653"},{"x":16,"y":32,"z":4,"color":"#966a3b"},{"x":16,"y":33,"z":0,"color":"#b48653"},{"x":16,"y":33,"z":1,"color":"#b48653"},{"x":16,"y":33,"z":2,"color":"#b48653"},{"x":16,"y":33,"z":3,"color":"#b48653"},{"x":16,"y":33,"z":4,"color":"#b48653"},{"x":16,"y":34,"z":0,"color":"#b48653"},{"x":16,"y":34,"z":1,"color":"#c79a67"},{"x":16,"y":34,"z":2,"color":"#b48653"},{"x":16,"y":34,"z":3,"color":"#b48653"},{"x":16,"y":34,"z":4,"color":"#b48653"},{"x":16,"y":35,"z":1,"color":"#d3ab7d"},{"x":16,"y":35,"z":2,"color":"#b48653"},{"x":16,"y":35,"z":3,"color":"#966a3b"},{"x":17,"y":3,"z":1,"color":"#c79a67"},{"x":17,"y":3,"z":2,"color":"#b48653"},{"x":17,"y":3,"z":3,"color":"#b48653"},{"x":17,"y":3,"z":19,"color":"#d3ab7d"},{"x":17,"y":3,"z":20,"color":"#b48653"},{"x":17,"y":3,"z":21,"color":"#e2bf93"},{"x":17,"y":4,"z":1,"color":"#c79a67"},{"x":17,"y":4,"z":2,"color":"#c79a67"},{"x":17,"y":4,"z":3,"color":"#b48653"},{"x":17,"y":4,"z":4,"color":"#c79a67"},{"x":17,"y":4,"z":19,"color":"#e2bf93"},{"x":17,"y":4,"z":20,"color":"#b48653"},{"x":17,"y":4,"z":21,"color":"#e2bf93"},{"x":17,"y":5,"z":1,"color":"#c79a67"},{"x":17,"y":5,"z":2,"color":"#b48653"},{"x":17,"y":5,"z":3,"color":"#b48653"},{"x":17,"y":5,"z":4,"color":"#b48653"},{"x":17,"y":5,"z":19,"color":"#d3ab7d"},{"x":17,"y":5,"z":20,"color":"#b48653"},{"x":17,"y":5,"z":21,"color":"#b48653"},{"x":17,"y":6,"z":1,"color":"#c79a67"},{"x":17,"y":6,"z":2,"color":"#c79a67"},{"x":17,"y":6,"z":3,"color":"#b48653"},{"x":17,"y":6,"z":4,"color":"#c79a67"},{"x":17,"y":6,"z":19,"color":"#d3ab7d"},{"x":17,"y":6,"z":20,"color":"#b48653"},{"x":17,"y":6,"z":21,"color":"#c79a67"},{"x":17,"y":7,"z":1,"color":"#b48653"},{"x":17,"y":7,"z":2,"color":"#b48653"},{"x":17,"y":7,"z":3,"color":"#b48653"},{"x":17,"y":7,"z":4,"color":"#b48653"},{"x":17,"y":7,"z":18,"color":"#b48653"},{"x":17,"y":7,"z":19,"color":"#d3ab7d"},{"x":17,"y":7,"z":20,"color":"#b48653"},{"x":17,"y":8,"z":2,"color":"#b48653"},{"x":17,"y":8,"z":3,"color":"#b48653"},{"x":17,"y":8,"z":4,"color":"#b48653"},{"x":17,"y":8,"z":5,"color":"#b48653"},{"x":17,"y":8,"z":18,"color":"#c79a67"},{"x":17,"y":8,"z":19,"color":"#d3ab7d"},{"x":17,"y":8,"z":20,"color":"#b48653"},{"x":17,"y":9,"z":2,"color":"#b48653"},{"x":17,"y":9,"z":3,"color":"#b48653"},{"x":17,"y":9,"z":4,"color":"#b48653"},{"x":17,"y":9,"z":5,"color":"#b48653"},{"x":17,"y":9,"z":18,"color":"#c79a67"},{"x":17,"y":9,"z":19,"color":"#d3ab7d"},{"x":17,"y":9,"z":20,"color":"#b48653"},{"x":17,"y":10,"z":2,"color":"#c79a67"},{"x":17,"y":10,"z":3,"color":"#c79a67"},{"x":17,"y":10,"z":4,"color":"#b48653"},{"x":17,"y":10,"z":5,"color":"#b48653"},{"x":17,"y":10,"z":18,"color":"#c79a67"},{"x":17,"y":10,"z":19,"color":"#d3ab7d"},{"x":17,"y":10,"z":20,"color":"#b48653"},{"x":17,"y":11,"z":2,"color":"#c79a67"},{"x":17,"y":11,"z":3,"color":"#d3ab7d"},{"x":17,"y":11,"z":4,"color":"#c79a67"},{"x":17,"y":11,"z":5,"color":"#c79a67"},{"x":17,"y":11,"z":18,"color":"#d3ab7d"},{"x":17,"y":11,"z":19,"color":"#d3ab7d"},{"x":17,"y":11,"z":20,"color":"#c79a67"},{"x":17,"y":12,"z":2,"color":"#d3ab7d"},{"x":17,"y":12,"z":3,"color":"#d3ab7d"},{"x":17,"y":12,"z":4,"color":"#d3ab7d"},{"x":17,"y":12,"z":5,"color":"#d3ab7d"},{"x":17,"y":12,"z":6,"color":"#d3ab7d"},{"x":17,"y":12,"z":18,"color":"#d3ab7d"},{"x":17,"y":12,"z":19,"color":"#d3ab7d"},{"x":17,"y":12,"z":20,"color":"#d3ab7d"},{"x":17,"y":13,"z":3,"color":"#d3ab7d"},{"x":17,"y":13,"z":4,"color":"#d3ab7d"},{"x":17,"y":13,"z":5,"color":"#b48653"},{"x":17,"y":13,"z":6,"color":"#e2bf93"},{"x":17,"y":13,"z":18,"color":"#d3ab7d"},{"x":17,"y":13,"z":19,"color":"#e2bf93"},{"x":17,"y":13,"z":20,"color":"#e2bf93"},{"x":17,"y":14,"z":3,"color":"#d3ab7d"},{"x":17,"y":14,"z":4,"color":"#c79a67"},{"x":17,"y":14,"z":5,"color":"#b48653"},{"x":17,"y":14,"z":6,"color":"#d3ab7d"},{"x":17,"y":14,"z":17,"color":"#d3ab7d"},{"x":17,"y":14,"z":18,"color":"#d3ab7d"},{"x":17,"y":14,"z":19,"color":"#d3ab7d"},{"x":17,"y":14,"z":20,"color":"#d3ab7d"},{"x":17,"y":15,"z":3,"color":"#d3ab7d"},{"x":17,"y":15,"z":4,"color":"#d3ab7d"},{"x":17,"y":15,"z":5,"color":"#d3ab7d"},{"x":17,"y":15,"z":6,"color":"#d3ab7d"},{"x":17,"y":15,"z":7,"color":"#d3ab7d"},{"x":17,"y":15,"z":8,"color":"#d3ab7d"},{"x":17,"y":15,"z":9,"color":"#d3ab7d"},{"x":17,"y":15,"z":10,"color":"#d3ab7d"},{"x":17,"y":15,"z":17,"color":"#d3ab7d"},{"x":17,"y":15,"z":18,"color":"#d3ab7d"},{"x":17,"y":15,"z":19,"color":"#d3ab7d"},{"x":17,"y":15,"z":20,"color":"#d3ab7d"},{"x":17,"y":16,"z":3,"color":"#d3ab7d"},{"x":17,"y":16,"z":4,"color":"#c79a67"},{"x":17,"y":16,"z":5,"color":"#c79a67"},{"x":17,"y":16,"z":6,"color":"#c79a67"},{"x":17,"y":16,"z":7,"color":"#c79a67"},{"x":17,"y":16,"z":8,"color":"#d3ab7d"},{"x":17,"y":16,"z":9,"color":"#e2bf93"},{"x":17,"y":16,"z":10,"color":"#d3ab7d"},{"x":17,"y":16,"z":11,"color":"#d3ab7d"},{"x":17,"y":16,"z":12,"color":"#d3ab7d"},{"x":17,"y":16,"z":13,"color":"#d3ab7d"},{"x":17,"y":16,"z":14,"color":"#d3ab7d"},{"x":17,"y":16,"z":15,"color":"#d3ab7d"},{"x":17,"y":16,"z":16,"color":"#e2bf93"},{"x":17,"y":16,"z":17,"color":"#d3ab7d"},{"x":17,"y":16,"z":18,"color":"#d3ab7d"},{"x":17,"y":16,"z":19,"color":"#d3ab7d"},{"x":17,"y":16,"z":20,"color":"#d3ab7d"},{"x":17,"y":17,"z":3,"color":"#b48653"},{"x":17,"y":17,"z":4,"color":"#c79a67"},{"x":17,"y":17,"z":5,"color":"#c79a67"},