{"name":"Chair - Medium 5-view Visual Hull","voxels":[{"x":0,"y":0,"z":1,"color":"#c79a67"},{"x":0,"y":0,"z":2,"color":"#c79a67"},{"x":0,"y":0,"z":23,"color":"#e2bf93"},{"x":0,"y":0,"z":24,"color":"#e2bf93"},{"x":0,"y":1,"z":1,"color":"#c79a67"},{"x":0,"y":1,"z":2,"color":"#c79a67"},{"x":0,"y":1,"z":23,"color":"#d3ab7d"},{"x":0,"y":1,"z":24,"color":"#e2bf93"},{"x":0,"y":2,"z":1,"color":"#c79a67"},{"x":0,"y":2,"z":2,"color":"#b48653"},{"x":0,"y":2,"z":23,"color":"#d3ab7d"},{"x":0,"y":2,"z":24,"color":"#c79a67"},{"x":0,"y":3,"z":1,"color":"#c79a67"},{"x":0,"y":3,"z":2,"color":"#c79a67"},{"x":0,"y":3,"z":23,"color":"#d3ab7d"},{"x":0,"y":3,"z":24,"color":"#c79a67"},{"x":0,"y":4,"z":1,"color":"#c79a67"},{"x":0,"y":4,"z":2,"color":"#c79a67"},{"x":0,"y":4,"z":22,"color":"#c79a67"},{"x":0,"y":4,"z":23,"color":"#d3ab7d"},{"x":0,"y":4,"z":24,"color":"#c79a67"},{"x":0,"y":5,"z":1,"color":"#b48653"},{"x":0,"y":5,"z":2,"color":"#c79a67"},{"x":0,"y":5,"z":22,"color":"#c79a67"},{"x":0,"y":5,"z":23,"color":"#d3ab7d"},{"x":0,"y":5,"z":24,"color":"#c79a67"},{"x":0,"y":6,"z":1,"color":"#e2bf93"},{"x":0,"y":6,"z":2,"color":"#c79a67"},{"x":0,"y":6,"z":22,"color":"#e2bf93"},{"x":0,"y":6,"z":23,"color":"#d3ab7d"},{"x":0,"y":6,"z":24,"color":"#c79a67"},{"x":0,"y":7,"z":1,"color":"#c79a67"},{"x":0,"y":7,"z":2,"color":"#b48653"},{"x":0,"y":7,"z":22,"color":"#d3ab7d"},{"x":0,"y":7,"z":23,"color":"#d3ab7d"},{"x":0,"y":7,"z":24,"color":"#c79a67"},{"x":0,"y":21,"z":17,"color":"#966a3b"},{"x":0,"y":21,"z":18,"color":"#966a3b"},{"x":0,"y":21,"z":19,"color":"#966a3b"},{"x":0,"y":21,"z":20,"color":"#966a3b"},{"x":0,"y":21,"z":21,"color":"#966a3b"},{"x":0,"y":21,"z":22,"color":"#966a3b"},{"x":0,"y":21,"z":23,"color":"#d3ab7d"},{"x":0,"y":21,"z":24,"color":"#c79a67"},{"x":0,"y":22,"z":17,"color":"#d3ab7d"},{"x":0,"y":22,"z":18,"color":"#d3ab7d"},{"x":0,"y":22,"z":19,"color":"#d3ab7d"},{"x":0,"y":22,"z":20,"color":"#d3ab7d"},{"x":0,"y":22,"z":21,"color":"#d3ab7d"},{"x":0,"y":22,"z":22,"color":"#d3ab7d"},{"x":0,"y":22,"z":23,"color":"#d3ab7d"},{"x":0,"y":22,"z":24,"color":"#d3ab7d"},{"x":0,"y":23,"z":17,"color":"#d3ab7d"},{"x":0,"y":23,"z":18,"color":"#d3ab7d"},{"x":0,"y":23,"z":19,"color":"#d3ab7d"},{"x":0,"y":23,"z":20,"color":"#d3ab7d"},{"x":0,"y":23,"z":21,"color":"#d3ab7d"},{"x":0,"y":23,"z":22,"color":"#e2bf93"},{"x":0,"y":23,"z":23,"color":"#e2bf93"},{"x":0,"y":23,"z":24,"color":"#e2bf93"},{"x":1,"y":0,"z":0,"color":"#d3ab7d"},{"x":1,"y":0,"z":1,"color":"#d3ab7d"},{"x":1,"y":0,"z":2,"color":"#c79a67"},{"x":1,"y":0,"z":23,"color":"#e2bf93"},{"x":1,"y":0,"z":24,"color":"#e2bf93"},{"x":1,"y":0,"z":25,"color":"#d3ab7d"},{"x":1,"y":1,"z":0,"color":"#d3ab7d"},{"x":1,"y":1,"z":1,"color":"#c79a67"},{"x":1,"y":1,"z":2,"color":"#c79a67"},{"x":1,"y":1,"z":23,"color":"#d3ab7d"},{"x":1,"y":1,"z":24,"color":"#d3ab7d"},{"x":1,"y":1,"z":25,"color":"#d3ab7d"},{"x":1,"y":2,"z":0,"color":"#d3ab7d"},{"x":1,"y":2,"z":1,"color":"#d3ab7d"},{"x":1,"y":2,"z":2,"color":"#c79a67"},{"x":1,"y":2,"z":3,"color":"#d3ab7d"},{"x":1,"y":2,"z":23,"color":"#d3ab7d"},{"x":1,"y":2,"z":24,"color":"#d3ab7d"},{"x":1,"y":2,"z":25,"color":"#d3ab7d"},{"x":1,"y":3,"z":1,"color":"#d3ab7d"},{"x":1,"y":3,"z":2,"color":"#d3ab7d"},{"x":1,"y":3,"z":3,"color":"#d3ab7d"},{"x":1,"y":3,"z":4,"color":"#d3ab7d"},{"x":1,"y":3,"z":23,"color":"#d3ab7d"},{"x":1,"y":3,"z":24,"color":"#d3ab7d"},{"x":1,"y":3,"z":25,"color":"#d3ab7d"},{"x":1,"y":4,"z":1,"color":"#d3ab7d"},{"x":1,"y":4,"z":2,"color":"#d3ab7d"},{"x":1,"y":4,"z":3,"color":"#c79a67"},{"x":1,"y":4,"z":4,"color":"#d3ab7d"},{"x":1,"y":4,"z":22,"color":"#d3ab7d"},{"x":1,"y":4,"z":23,"color":"#d3ab7d"},{"x":1,"y":4,"z":24,"color":"#d3ab7d"},{"x":1,"y":4,"z":25,"color":"#d3ab7d"},{"x":1,"y":5,"z":1,"color":"#d3ab7d"},{"x":1,"y":5,"z":2,"color":"#d3ab7d"},{"x":1,"y":5,"z":3,"color":"#c79a67"},{"x":1,"y":5,"z":4,"color":"#d3ab7d"},{"x":1,"y":5,"z":22,"color":"#d3ab7d"},{"x":1,"y":5,"z":23,"color":"#d3ab7d"},{"x":1,"y":5,"z":24,"color":"#d3ab7d"},{"x":1,"y":5,"z":25,"color":"#d3ab7d"},{"x":1,"y":6,"z":1,"color":"#d3ab7d"},{"x":1,"y":6,"z":2,"color":"#c79a67"},{"x":1,"y":6,"z":3,"color":"#c79a67"},{"x":1,"y":6,"z":4,"color":"#d3ab7d"},{"x":1,"y":6,"z":22,"color":"#d3ab7d"},{"x":1,"y":6,"z":23,"color":"#d3ab7d"},{"x":1,"y":6,"z":24,"color":"#d3ab7d"},{"x":1,"y":7,"z":1,"color":"#d3ab7d"},{"x":1,"y":7,"z":2,"color":"#c79a67"},{"x":1,"y":7,"z":3,"color":"#d3ab7d"},{"x":1,"y":7,"z":4,"color":"#d3ab7d"},{"x":1,"y":7,"z":5,"color":"#d3ab7d"},{"x":1,"y":7,"z":22,"color":"#d3ab7d"},{"x":1,"y":7,"z":23,"color":"#d3ab7d"},{"x":1,"y":7,"z":24,"color":"#d3ab7d"},{"x":1,"y":8,"z":2,"color":"#c79a67"},{"x":1,"y":8,"z":3,"color":"#d3ab7d"},{"x":1,"y":8,"z":4,"color":"#b48653"},{"x":1,"y":8,"z":5,"color":"#d3ab7d"},{"x":1,"y":8,"z":22,"color":"#d3ab7d"},{"x":1,"y":8,"z":23,"color":"#d3ab7d"},{"x":1,"y":8,"z":24,"color":"#d3ab7d"},{"x":1,"y":9,"z":2,"color":"#c79a67"},{"x":1,"y":9,"z":3,"color":"#c79a67"},{"x":1,"y":9,"z":4,"color":"#b48653"},{"x":1,"y":9,"z":5,"color":"#d3ab7d"},{"x":1,"y":9,"z":22,"color":"#d3ab7d"},{"x":1,"y":9,"z":23,"color":"#c79a67"},{"x":1,"y":9,"z":24,"color":"#d3ab7d"},{"x":1,"y":10,"z":2,"color":"#c79a67"},{"x":1,"y":10,"z":3,"color":"#c79a67"},{"x":1,"y":10,"z":4,"color":"#c79a67"},{"x":1,"y":10,"z":5,"color":"#c79a67"},{"x":1,"y":10,"z":22,"color":"#d3ab7d"},{"x":1,"y":10,"z":23,"color":"#b48653"},{"x":1,"y":10,"z":24,"color":"#c79a67"},{"x":1,"y":11,"z":2,"color":"#c79a67"},{"x":1,"y":11,"z":3,"color":"#c79a67"},{"x":1,"y":11,"z":4,"color":"#c79a67"},{"x":1,"y":11,"z":5,"color":"#e2bf93"},{"x":1,"y":11,"z":6,"color":"#c79a67"},{"x":1,"y":11,"z":21,"color":"#c79a67"},{"x":1,"y":11,"z":22,"color":"#d3ab7d"},{"x":1,"y":11,"z":23,"color":"#c79a67"},{"x":1,"y":11,"z":24,"color":"#c79a67"},{"x":1,"y":12,"z":2,"color":"#d3ab7d"},{"x":1,"y":12,"z":3,"color":"#c79a67"},{"x":1,"y":12,"z":4,"color":"#c79a67"},{"x":1,"y":12,"z":5,"color":"#b48653"},{"x":1,"y":12,"z":6,"color":"#e2bf93"},{"x":1,"y":12,"z":21,"color":"#c79a67"},{"x":1,"y":12,"z":22,"color":"#d3ab7d"},{"x":1,"y":12,"z":23,"color":"#e2bf93"},{"x":1,"y":12,"z":24,"color":"#e2bf93"},{"x":1,"y":13,"z":3,"color":"#d3ab7d"},{"x":1,"y":13,"z":4,"color":"#c79a67"},{"x":1,"y":13,"z":5,"color":"#b48653"},{"x":1,"y":13,"z":6,"color":"#e2bf93"},{"x":1,"y":13,"z":21,"color":"#c79a67"},{"x":1,"y":13,"z":22,"color":"#d3ab7d"},{"x":1,"y":13,"z":23,"color":"#c79a67"},{"x":1,"y":13,"z":24,"color":"#e2bf93"},{"x":1,"y":14,"z":3,"color":"#d3ab7d"},{"x":1,"y":14,"z":4,"color":"#c79a67"},{"x":1,"y":14,"z":5,"color":"#c79a67"},{"x":1,"y":14,"z":6,"color":"#d3ab7d"},{"x":1,"y":14,"z":21,"color":"#d3ab7d"},{"x":1,"y":14,"z":22,"color":"#d3ab7d"},{"x":1,"y":14,"z":23,"color":"#c79a67"},{"x":1,"y":14,"z":24,"color":"#d3ab7d"},{"x":1,"y":15,"z":3,"color":"#c79a67"},{"x":1,"y":15,"z":4,"color":"#c79a67"},{"x":1,"y":15,"z":5,"color":"#c79a67"},{"x":1,"y":15,"z":6,"color":"#e2bf93"},{"x":1,"y":15,"z":21,"color":"#c79a67"},{"x":1,"y":15,"z":22,"color":"#c79a67"},{"x":1,"y":15,"z":23,"color":"#b48653"},{"x":1,"y":15,"z":24,"color":"#c79a67"},{"x":1,"y":16,"z":3,"color":"#c79a67"},{"x":1,"y":16,"z":4,"color":"#c79a67"},{"x":1,"y":16,"z":5,"color":"#c79a67"},{"x":1,"y":16,"z":6,"color":"#b48653"},{"x":1,"y":16,"z":21,"color":"#c79a67"},{"x":1,"y":16,"z":22,"color":"#d3ab7d"},{"x":1,"y":16,"z":23,"color":"#b48653"},{"x":1,"y":16,"z":24,"color":"#c79a67"},{"x":1,"y":17,"z":3,"color":"#c79a67"},{"x":1,"y":17,"z":4,"color":"#c79a67"},{"x":1,"y":17,"z":5,"color":"#d3ab7d"},{"x":1,"y":17,"z":6,"color":"#b48653"},{"x":1,"y":17,"z":21,"color":"#d3ab7d"},{"x":1,"y":17,"z":22,"color":"#d3ab7d"},{"x":1,"y":17,"z":23,"color":"#c79a67"},{"x":1,"y":18,"z":4,"color":"#d3ab7d"},{"x":1,"y":18,"z":5,"color":"#c79a67"},{"x":1,"y":18,"z":6,"color":"#c79a67"},{"x":1,"y":18,"z":20,"color":"#e2bf93"},{"x":1,"y":18,"z":21,"color":"#d3ab7d"},{"x":1,"y":18,"z":22,"color":"#d3ab7d"},{"x":1,"y":18,"z":23,"color":"#d3ab7d"},{"x":1,"y":19,"z":4,"color":"#d3ab7d"},{"x":1,"y":19,"z":5,"color":"#d3ab7d"},{"x":1,"y":19,"z":6,"color":"#d3ab7d"},{"x":1,"y":19,"z":9,"color":"#e2bf93"},{"x":1,"y":19,"z":10,"color":"#e2bf93"},{"x":1,"y":19,"z":11,"color":"#e2bf93"},{"x":1,"y":19,"z":12,"color":"#e2bf93"},{"x":1,"y":19,"z":13,"color":"#e2bf93"},{"x":1,"y":19,"z":20,"color":"#c79a67"},{"x":1,"y":19,"z":21,"color":"#d3ab7d"},{"x":1,"y":19,"z":22,"color":"#d3ab7d"},{"x":1,"y":19,"z":23,"color":"#e2bf93"},{"x":1,"y":20,"z":4,"color":"#d3ab7d"},{"x":1,"y":20,"z":5,"color":"#d3ab7d"},{"x":1,"y":20,"z":6,"color":"#d3ab7d"},{"x":1,"y":20,"z":9,"color":"#d3ab7d"},{"x":1,"y":20,"z":10,"color":"#d3ab7d"},{"x":1,"y":20,"z":11,"color":"#b48653"},{"x":1,"y":20,"z":12,"color":"#e2bf93"},{"x":1,"y":20,"z":13,"color":"#e2bf93"},{"x":1,"y":20,"z":14,"color":"#e2bf93"},{"x":1,"y":20,"z":15,"color":"#e2bf93"},{"x":1,"y":20,"z":16,"color":"#e2bf93"},{"x":1,"y":20,"z":17,"color":"#e2bf93"},{"x":1,"y":20,"z":18,"color":"#e2bf93"},{"x":1,"y":20,"z":19,"color":"#e2bf93"},{"x":1,"y":20,"z":20,"color":"#d3ab7d"},{"x":1,"y":20,"z":21,"color":"#c79a67"},{"x":1,"y":20,"z":22,"color":"#d3ab7d"},{"x":1,"y":20,"z":23,"color":"#e2bf93"},{"x":1,"y":20,"z":24,"color":"#e2bf93"},{"x":1,"y":20,"z":25,"color":"#e2bf93"},{"x":1,"y":21,"z":4,"color":"#b48653"},{"x":1,"y":21,"z":5,"color":"#b48653"},{"x":1,"y":21,"z":6,"color":"#b48653"},{"x":1,"y":21,"z":9,"color":"#b48653"},{"x":1,"y":21,"z":10,"color":"#b48653"},{"x":1,"y":21,"z":11,"color":"#b48653"},{"x":1,"y":21,"z":12,"color":"#b48653"},{"x":1,"y":21,"z":13,"color":"#c79a67"},{"x":1,"y":21,"z":14,"color":"#c79a67"},{"x":1,"y":21,"z":15,"color":"#b48653"},{"x":1,"y":21,"z":16,"color":"#b48653"},{"x":1,"y":21,"z":17,"color":"#b48653"},{"x":1,"y":21,"z":18,"color":"#966a3b"},{"x":1,"y":21,"z":19,"color":"#966a3b"},{"x":1,"y":21,"z":20,"color":"#966a3b"},{"x":1,"y":21,"z":21,"color":"#966a3b"},{"x":1,"y":21,"z":22,"color":"#966a3b"},{"x":1,"y":21,"z":23,"color":"#b48653"},{"x":1,"y":21,"z":24,"color":"#966a3b"},{"x":1,"y":21,"z":25,"color":"#966a3b"},{"x":1,"y":22,"z":4,"color":"#b48653"},{"x":1,"y":22,"z":5,"color":"#c79a67"},{"x":1,"y":22,"z":6,"color":"#b48653"},{"x":1,"y":22,"z":9,"color":"#b48653"},{"x":1,"y":22,"z":10,"color":"#b48653"},{"x":1,"y":22,"z":11,"color":"#b48653"},{"x":1,"y":22,"z":12,"color":"#b48653"},{"x":1,"y":22,"z":13,"color":"#c79a67"},{"x":1,"y":22,"z":14,"color":"#c79a67"},{"x":1,"y":22,"z":15,"color":"#c79a67"},{"x":1,"y":22,"z":16,"color":"#b48653"},{"x":1,"y":22,"z":17,"color":"#b48653"},{"x":1,"y":22,"z":18,"color":"#b48653"},{"x":1,"y":22,"z":19,"color":"#b48653"},{"x":1,"y":22,"z":20,"color":"#b48653"},{"x":1,"y":22,"z":21,"color":"#b48653"},{"x":1,"y":22,"z":22,"color":"#b48653"},{"x":1,"y":22,"z":23,"color":"#b48653"},{"x":1,"y":22,"z":24,"color":"#b48653"},{"x":1,"y":22,"z":25,"color":"#b48653"},{"x":1,"y":23,"z":4,"color":"#d3ab7d"},{"x":1,"y":23,"z":5,"color":"#d3ab7d"},{"x":1,"y":23,"z":6,"color":"#d3ab7d"},{"x":1,"y":23,"z":9,"color":"#d3ab7d"},{"x":1,"y":23,"z":10,"color":"#d3ab7d"},{"x":1,"y":23,"z":11,"color":"#d3ab7d"},{"x":1,"y":23,"z":12,"color":"#d3ab7d"},{"x":1,"y":23,"z":13,"color":"#d3ab7d"},{"x":1,"y":23,"z":14,"color":"#d3ab7d"},{"x":1,"y":23,"z":15,"color":"#d3ab7d"},{"x":1,"y":23,"z":16,"color":"#d3ab7d"},{"x":1,"y":23,"z":17,"color":"#d3ab7d"},{"x":1,"y":23,"z":18,"color":"#d3ab7d"},{"x":1,"y":23,"z":19,"color":"#d3ab7d"},{"x":1,"y":23,"z":20,"color":"#d3ab7d"},{"x":1,"y":23,"z":21,"color":"#d3ab7d"},{"x":1,"y":23,"z":22,"color":"#d3ab7d"},{"x":1,"y":23,"z":23,"color":"#d3ab7d"},{"x":1,"y":23,"z":24,"color":"#d3ab7d"},{"x":1,"y":23,"z":25,"color":"#d3ab7d"},{"x":1,"y":24,"z":4,"color":"#b48653"},{"x":1,"y":24,"z":5,"color":"#c79a67"},{"x":1,"y":24,"z":6,"color":"#c79a67"},{"x":1,"y":24,"z":16,"color":"#d3ab7d"},{"x":1,"y":24,"z":17,"color":"#e2bf93"},{"x":1,"y":24,"z":18,"color":"#e2bf93"},{"x":1,"y":24,"z":19,"color":"#e2bf93"},{"x":1,"y":24,"z":20,"color":"#e2bf93"},{"x":1,"y":24,"z":21,"color":"#e2bf93"},{"x":1,"y":24,"z":22,"color":"#d3ab7d"},{"x":1,"y":24,"z":23,"color":"#e2bf93"},{"x":1,"y":24,"z":24,"color":"#e2bf93"},{"x":1,"y":24,"z":25,"color":"#c79a67"},{"x":1,"y":25,"z":4,"color":"#b48653"},{"x":1,"y":25,"z":5,"color":"#d3ab7d"},{"x":1,"y":25,"z":6,"color":"#c79a67"},{"x":1,"y":26,"z":4,"color":"#d3ab7d"},{"x":1,"y":26,"z":5,"color":"#d3ab7d"},{"x":1,"y":26,"z":6,"color":"#d3ab7d"},{"x":1,"y":27,"z":4,"color":"#c79a67"},{"x":1,"y":27,"z":5,"color":"#d3ab7d"},{"x":1,"y":27,"z":6,"color":"#c79a67"},{"x":1,"y":28,"z":3,"color":"#c79a67"},{"x":1,"y":28,"z":4,"color":"#c79a67"},{"x":1,"y":28,"z":5,"color":"#d3ab7d"},{"x":1,"y":28,"z":6,"color":"#d3ab7d"},{"x":1,"y":29,"z":3,"color":"#c79a67"},{"x":1,"y":29,"z":4,"color":"#c79a67"},{"x":1,"y":29,"z":5,"color":"#d3ab7d"},{"x":1,"y":29,"z":6,"color":"#c79a67"},{"x":1,"y":30,"z":3,"color":"#c79a67"},{"x":1,"y":30,"z":4,"color":"#c79a67"},{"x":1,"y":30,"z":5,"color":"#d3ab7d"},{"x":1,"y":30,"z":6,"color":"#d3ab7d"},{"x":1,"y":31,"z":3,"color":"#e2bf93"},{"x":1,"y":31,"z":4,"color":"#c79a67"},{"x":1,"y":31,"z":5,"color":"#d3ab7d"},{"x":1,"y":31,"z":6,"color":"#e2bf93"},{"x":1,"y":32,"z":3,"color":"#c79a67"},{"x":1,"y":32,"z":4,"color":"#c79a67"},{"x":1,"y":32,"z":5,"color":"#e2bf93"},{"x":1,"y":32,"z":6,"color":"#c79a67"},{"x":1,"y":33,"z":3,"color":"#c79a67"},{"x":1,"y":33,"z":4,"color":"#c79a67"},{"x":1,"y":33,"z":5,"color":"#d3ab7d"},{"x":1,"y":33,"z":6,"color":"#c79a67"},{"x":1,"y":34,"z":2,"color":"#c79a67"},{"x":1,"y":34,"z":3,"color":"#d3ab7d"},{"x":1,"y":34,"z":4,"color":"#d3ab7d"},{"x":1,"y":34,"z":5,"color":"#d3ab7d"},{"x":1,"y":34,"z":6,"color":"#c79a67"},{"x":1,"y":35,"z":2,"color":"#c79a67"},{"x":1,"y":35,"z":3,"color":"#c79a67"},{"x":1,"y":35,"z":4,"color":"#d3ab7d"},{"x":1,"y":35,"z":5,"color":"#c79a67"},{"x":1,"y":35,"z":6,"color":"#c79a67"},{"x":1,"y":36,"z":1,"color":"#d3ab7d"},{"x":1,"y":36,"z":2,"color":"#c79a67"},{"x":1,"y":36,"z":3,"color":"#c79a67"},{"x":1,"y":36,"z":4,"color":"#d3ab7d"},{"x":1,"y":36,"z":5,"color":"#e2bf93"},{"x":1,"y":37,"z":1,"color":"#d3ab7d"},{"x":1,"y":37,"z":2,"color":"#c79a67"},{"x":1,"y":37,"z":3,"color":"#c79a67"},{"x":1,"y":37,"z":4,"color":"#e2bf93"},{"x":1,"y":37,"z":5,"color":"#c79a67"},{"x":1,"y":38,"z":1,"color":"#d3ab7d"},{"x":1,"y":38,"z":2,"color":"#b48653"},{"x":1,"y":38,"z":3,"color":"#c79a67"},{"x":1,"y":38,"z":4,"color":"#d3ab7d"},{"x":1,"y":38,"z":5,"color":"#c79a67"},{"x":1,"y":39,"z":1,"color":"#d3ab7d"},{"x":1,"y":39,"z":2,"color":"#b48653"},{"x":1,"y":39,"z":3,"color":"#c79a67"},{"x":1,"y":39,"z":4,"color":"#d3ab7d"},{"x":1,"y":39,"z":5,"color":"#c79a67"},{"x":1,"y":40,"z":1,"color":"#c79a67"},{"x":1,"y":40,"z":2,"color":"#c79a67"},{"x":1,"y":40,"z":3,"color":"#c79a67"},{"x":1,"y":40,"z":4,"color":"#c79a67"},{"x":1,"y":40,"z":5,"color":"#c79a67"},{"x":1,"y":41,"z":0,"color":"#c79a67"},{"x":1,"y":41,"z":1,"color":"#c79a67"},{"x":1,"y":41,"z":2,"color":"#c79a67"},{"x":1,"y":41,"z":3,"color":"#c79a67"},{"x":1,"y":41,"z":4,"color":"#d3ab7d"},{"x":1,"y":42,"z":0,"color":"#c79a67"},{"x":1,"y":42,"z":1,"color":"#c79a67"},{"x":1,"y":42,"z":2,"color":"#e2bf93"},{"x":1,"y":42,"z":3,"color":"#d3ab7d"},{"x":1,"y":42,"z":4,"color":"#b48653"},{"x":1,"y":43,"z":1,"color":"#d3ab7d"},{"x":1,"y":43,"z":2,"color":"#c79a67"},{"x":1,"y":43,"z":3,"color":"#e2bf93"},{"x":1,"y":43,"z":4,"color":"#b48653"},{"x":2,"y":0,"z":0,"color":"#c79a67"},{"x":2,"y":0,"z":1,"color":"#c79a67"},{"x":2,"y":0,"z":2,"color":"#c79a67"},{"x":2,"y":0,"z":23,"color":"#e2bf93"},{"x":2,"y":0,"z":24,"color":"#e2bf93"},{"x":2,"y":0,"z":25,"color":"#e2bf93"},{"x":2,"y":1,"z":0,"color":"#e2bf93"},{"x":2,"y":1,"z":1,"color":"#c79a67"},{"x":2,"y":1,"z":2,"color":"#c79a67"},{"x":2,"y":1,"z":23,"color":"#d3ab7d"},{"x":2,"y":1,"z":24,"color":"#e2bf93"},{"x":2,"y":1,"z":25,"color":"#e2bf93"},{"x":2,"y":2,"z":0,"color":"#e2bf93"},{"x":2,"y":2,"z":1,"color":"#c79a67"},{"x":2,"y":2,"z":2,"color":"#c79a67"},{"x":2,"y":2,"z":3,"color":"#e2bf93"},{"x":2,"y":2,"z":23,"color":"#d3ab7d"},{"x":2,"y":2,"z":24,"color":"#e2bf93"},{"x":2,"y":2,"z":25,"color":"#e2bf93"},{"x":2,"y":3,"z":1,"color":"#c79a67"},{"x":2,"y":3,"z":2,"color":"#d3ab7d"},{"x":2,"y":3,"z":3,"color":"#e2bf93"},{"x":2,"y":3,"z":4,"color":"#e2bf93"},{"x":2,"y":3,"z":23,"color":"#d3ab7d"},{"x":2,"y":3,"z":24,"color":"#e2bf93"},{"x":2,"y":3,"z":25,"color":"#e2bf93"},{"x":2,"y":4,"z":1,"color":"#c79a67"},{"x":2,"y":4,"z":2,"color":"#c79a67"},{"x":2,"y":4,"z":3,"color":"#b48653"},{"x":2,"y":4,"z":4,"color":"#c79a67"},{"x":2,"y":4,"z":22,"color":"#c79a67"},{"x":2,"y":4,"z":23,"color":"#d3ab7d"},{"x":2,"y":4,"z":24,"color":"#b48653"},{"x":2,"y":4,"z":25,"color":"#c79a67"},{"x":2,"y":5,"z":1,"color":"#c79a67"},{"x":2,"y":5,"z":2,"color":"#c79a67"},{"x":2,"y":5,"z":3,"color":"#b48653"},{"x":2,"y":5,"z":4,"color":"#c79a67"},{"x":2,"y":5,"z":22,"color":"#d3ab7d"},{"x":2,"y":5,"z":23,"color":"#d3ab7d"},{"x":2,"y":5,"z":24,"color":"#b48653"},{"x":2,"y":5,"z":25,"color":"#e2bf93"},{"x":2,"y":6,"z":1,"color":"#e2bf93"},{"x":2,"y":6,"z":2,"color":"#c79a67"},{"x":2,"y":6,"z":3,"color":"#c79a67"},{"x":2,"y":6,"z":4,"color":"#c79a67"},{"x":2,"y":6,"z":22,"color":"#e2bf93"},{"x":2,"y":6,"z":23,"color":"#d3ab7d"},{"x":2,"y":6,"z":24,"color":"#b48653"},{"x":2,"y":7,"z":1,"color":"#c79a67"},{"x":2,"y":7,"z":2,"color":"#c79a67"},{"x":2,"y":7,"z":3,"color":"#c79a67"},{"x":2,"y":7,"z":4,"color":"#e2bf93"},{"x":2,"y":7,"z":5,"color":"#b48653"},{"x":2,"y":7,"z":22,"color":"#d3ab7d"},{"x":2,"y":7,"z":23,"color":"#d3ab7d"},{"x":2,"y":7,"z":24,"color":"#b48653"},{"x":2,"y":8,"z":2,"color":"#c79a67"},{"x":2,"y":8,"z":3,"color":"#c79a67"},{"x":2,"y":8,"z":4,"color":"#b48653"},{"x":2,"y":8,"z":5,"color":"#b48653"},{"x":2,"y":8,"z":22,"color":"#d3ab7d"},{"x":2,"y":8,"z":23,"color":"#d3ab7d"},{"x":2,"y":8,"z":24,"color":"#b48653"},{"x":2,"y":9,"z":2,"color":"#d3ab7d"},{"x":2,"y":9,"z":3,"color":"#c79a67"},{"x":2,"y":9,"z":4,"color":"#c79a67"},{"x":2,"y":9,"z":5,"color":"#c79a67"},{"x":2,"y":9,"z":22,"color":"#d3ab7d"},{"x":2,"y":9,"z":23,"color":"#d3ab7d"},{"x":2,"y":9,"z":24,"color":"#c79a67"},{"x":2,"y":10,"z":2,"color":"#d3ab7d"},{"x":2,"y":10,"z":3,"color":"#d3ab7d"},{"x":2,"y":10,"z":4,"color":"#c79a67"},{"x":2,"y":10,"z":5,"color":"#d3ab7d"},{"x":2,"y":10,"z":22,"color":"#d3ab7d"},{"x":2,"y":10,"z":23,"color":"#d3ab7d"},{"x":2,"y":10,"z":24,"color":"#d3ab7d"},{"x":2,"y":11,"z":2,"color":"#d3ab7d"},{"x":2,"y":11,"z":3,"color":"#c79a67"},{"x":2,"y":11,"z":4,"color":"#c79a67"},{"x":2,"y":11,"z":5,"color":"#d3ab7d"},{"x":2,"y":11,"z":6,"color":"#d3ab7d"},{"x":2,"y":11,"z":21,"color":"#d3ab7d"},{"x":2,"y":11,"z":22,"color":"#d3ab7d"},{"x":2,"y":11,"z":23,"color":"#d3ab7d"},{"x":2,"y":11,"z":24,"color":"#d3ab7d"},{"x":2,"y":12,"z":2,"color":"#d3ab7d"},{"x":2,"y":12,"z":3,"color":"#d3ab7d"},{"x":2,"y":12,"z":4,"color":"#c79a67"},{"x":2,"y":12,"z":5,"color":"#c79a67"},{"x":2,"y":12,"z":6,"color":"#d3ab7d"},{"x":2,"y":12,"z":21,"color":"#d3ab7d"},{"x":2,"y":12,"z":22,"color":"#d3ab7d"},{"x":2,"y":12,"z":23,"color":"#d3ab7d"},{"x":2,"y":12,"z":24,"color":"#d3ab7d"},{"x":2,"y":13,"z":3,"color":"#d3ab7d"},{"x":2,"y":13,"z":4,"color":"#c79a67"},{"x":2,"y":13,"z":5,"color":"#b48653"},{"x":2,"y":13,"z":6,"color":"#d3ab7d"},{"x":2,"y":13,"z":21,"color":"#d3ab7d"},{"x":2,"y":13,"z":22,"color":"#d3ab7d"},{"x":2,"y":13,"z":23,"color":"#d3ab7d"},{"x":2,"y":13,"z":24,"color":"#d3ab7d"},{"x":2,"y":14,"z":3,"color":"#d3ab7d"},{"x":2,"y":14,"z":4,"color":"#c79a67"},{"x":2,"y":14,"z":5,"color":"#c79a67"},{"x":2,"y":14,"z":6,"color":"#d3ab7d"},{"x":2,"y":14,"z":21,"color":"#d3ab7d"},{"x":2,"y":14,"z":22,"color":"#d3ab7d"},{"x":2,"y":14,"z":23,"color":"#d3ab7d"},{"x":2,"y":14,"z":24,"color":"#d3ab7d"},{"x":2,"y":15,"z":3,"color":"#d3ab7d"},{"x":2,"y":15,"z":4,"color":"#c79a67"},{"x":2,"y":15,"z":5,"color":"#c79a67"},{"x":2,"y":15,"z":6,"color":"#e2bf93"},{"x":2,"y":15,"z":7,"color":"#d3ab7d"},{"x":2,"y":15,"z":21,"color":"#d3ab7d"},{"x":2,"y":15,"z":22,"color":"#d3ab7d"},{"x":2,"y":15,"z":23,"color":"#d3ab7d"},{"x":2,"y":15,"z":24,"color":"#d3ab7d"},{"x":2,"y":16,"z":3,"color":"#d3ab7d"},{"x":2,"y":16,"z":4,"color":"#d3ab7d"},{"x":2,"y":16,"z":5,"color":"#c79a67"},{"x":2,"y":16,"z":6,"color":"#b48653"},{"x":2,"y":16,"z":7,"color":"#d3ab7d"},{"x":2,"y":16,"z":21,"color":"#d3ab7d"},{"x":2,"y":16,"z":22,"color":"#d3ab7d"},{"x":2,"y":16,"z":23,"color":"#d3ab7d"},{"x":2,"y":16,"z":24,"color":"#d3ab7d"},{"x":2,"y":17,"z":3,"color":"#d3ab7d"},{"x":2,"y":17,"z":4,"color":"#d3ab7d"},{"x":2,"y":17,"z":5,"color":"#d3ab7d"},{"x":2,"y":17,"z":6,"color":"#b48653"},{"x":2,"y":17,"z":7,"color":"#d3ab7d"},{"x":2,"y":17,"z":21,"color":"#d3ab7d"},{"x":2,"y":17,"z":22,"color":"#d3ab7d"},{"x":2,"y":17,"z":23,"color":"#d3ab7d"},{"x":2,"y":18,"z":4,"color":"#d3ab7d"},{"x":2,"y":18,"z":5,"color":"#c79a67"},{"x":2,"y":18,"z":6,"color":"#c79a67"},{"x":2,"y":18,"z":7,"color":"#d3ab7d"},{"x":2,"y":18,"z":8,"color":"#d3ab7d"},{"x":2,"y":18,"z":20,"color":"#d3ab7d"},{"x":2,"y":18,"z":21,"color":"#d3ab7d"},{"x":2,"y":18,"z":22,"color":"#d3ab7d"},{"x":2,"y":18,"z":23,"color":"#d3ab7d"},{"x":2,"y":19,"z":4,"color":"#d3ab7d"},{"x":2,"y":19,"z":5,"color":"#d3ab7d"},{"x":2,"y":19,"z":6,"color":"#d3ab7d"},{"x":2,"y":19,"z":7,"color":"#d3ab7d"},{"x":2,"y":19,"z":8,"color":"#d3ab7d"},{"x":2,"y":19,"z":9,"color":"#d3ab7d"},{"x":2,"y":19,"z":10,"color":"#d3ab7d"},{"x":2,"y":19,"z":11,"color":"#d3ab7d"},{"x":2,"y":19,"z":12,"color":"#d3ab7d"},{"x":2,"y":19,"z":13,"color":"#d3ab7d"},{"x":2,"y":19,"z":20,"color":"#d3ab7d"},{"x":2,"y":19,"z":21,"color":"#d3ab7d"},{"x":2,"y":19,"z":22,"color":"#d3ab7d"},{"x":2,"y":19,"z":23,"color":"#d3ab7d"},{"x":2,"y":20,"z":4,"color":"#c79a67"},{"x":2,"y":20,"z":5,"color":"#c79a67"},{"x":2,"y":20,"z":6,"color":"#c79a67"},{"x":2,"y":20,"z":7,"color":"#c79a67"},{"x":2,"y":20,"z":8,"color":"#c79a67"},{"x":2,"y":20,"z":9,"color":"#c79a67"},{"x":2,"y":20,"z":10,"color":"#c79a67"},{"x":2,"y":20,"z":11,"color":"#c79a67"},{"x":2,"y":20,"z":12,"color":"#d3ab7d"},{"x":2,"y":20,"z":13,"color":"#d3ab7d"},{"x":2,"y":20,"z":14,"color":"#d3ab7d"},{"x":2,"y":20,"z":15,"color":"#d3ab7d"},{"x":2,"y":20,"z":16,"color":"#d3ab7d"},{"x":2,"y":20,"z":17,"color":"#d3ab7d"},{"x":2,"y":20,"z":18,"color":"#c79a67"},{"x":2,"y":20,"z":19,"color":"#c79a67"},{"x":2,"y":20,"z":20,"color":"#d3ab7d"},{"x":2,"y":20,"z":21,"color":"#d3ab7d"},{"x":2,"y":20,"z":22,"color":"#d3ab7d"},{"x":2,"y":20,"z":23,"color":"#d3ab7d"},{"x":2,"y":20,"z":24,"color":"#c79a67"},{"x":2,"y":20,"z":25,"color":"#d3ab7d"},{"x":2,"y":21,"z":4,"color":"#c79a67"},{"x":2,"y":21,"z":5,"color":"#c79a67"},{"x":2,"y":21,"z":6,"color":"#c79a67"},{"x":2,"y":21,"z":7,"color":"#966a3b"},{"x":2,"y":21,"z":8,"color":"#b48653"},{"x":2,"y":21,"z":9,"color":"#b48653"},{"x":2,"y":21,"z":10,"color":"#c79a67"},{"x":2,"y":21,"z":11,"color":"#c79a67"},{"x":2,"y":21,"z":12,"color":"#c79a67"},{"x":2,"y":21,"z":13,"color":"#c79a67"},{"x":2,"y":21,"z":14,"color":"#d3ab7d"},{"x":2,"y":21,"z":15,"color":"#b48653"},{"x":2,"y":21,"z":16,"color":"#b48653"},{"x":2,"y":21,"z":17,"color":"#b48653"},{"x":2,"y":21,"z":18,"color":"#966a3b"},{"x":2,"y":21,"z":19,"color":"#966a3b"},{"x":2,"y":21,"z":20,"color":"#966a3b"},{"x":2,"y":21,"z":21,"color":"#966a3b"},{"x":2,"y":21,"z":22,"color":"#966a3b"},{"x":2,"y":21,"z":23,"color":"#d3ab7d"},{"x":2,"y":21,"z":24,"color":"#b48653"},{"x":2,"y":21,"z":25,"color":"#d3ab7d"},{"x":2,"y":22,"z":4,"color":"#c79a67"},{"x":2,"y":22,"z":5,"color":"#c79a67"},{"x":2,"y":22,"z":6,"color":"#c79a67"},{"x":2,"y":22,"z":7,"color":"#b48653"},{"x":2,"y":22,"z":8,"color":"#b48653"},{"x":2,"y":22,"z":9,"color":"#b48653"},{"x":2,"y":22,"z":10,"color":"#c79a67"},{"x":2,"y":22,"z":11,"color":"#b48653"},{"x":2,"y":22,"z":12,"color":"#c79a67"},{"x":2,"y":22,"z":13,"color":"#c79a67"},{"x":2,"y":22,"z":14,"color":"#c79a67"},{"x":2,"y":22,"z":15,"color":"#c79a67"},{"x":2,"y":22,"z":16,"color":"#b48653"},{"x":2,"y":22,"z":17,"color":"#b48653"},{"x":2,"y":22,"z":18,"color":"#b48653"},{"x":2,"y":22,"z":19,"color":"#b48653"},{"x":2,"y":22,"z":20,"color":"#b48653"},{"x":2,"y":22,"z":21,"color":"#b48653"},{"x":2,"y":22,"z":22,"color":"#b48653"},{"x":2,"y":22,"z":23,"color":"#c79a67"},{"x":2,"y":22,"z":24,"color":"#b48653"},{"x":2,"y":22,"z":25,"color":"#e2bf93"},{"x":2,"y":23,"z":4,"color":"#c79a67"},{"x":2,"y":23,"z":5,"color":"#c79a67"},{"x":2,"y":23,"z":6,"color":"#c79a67"},{"x":2,"y":23,"z":7,"color":"#c79a67"},{"x":2,"y":23,"z":8,"color":"#d3ab7d"},{"x":2,"y":23,"z":9,"color":"#d3ab7d"},{"x":2,"y":23,"z":10,"color":"#c79a67"},{"x":2,"y":23,"z":11,"color":"#d3ab7d"},{"x":2,"y":23,"z":12,"color":"#d3ab7d"},{"x":2,"y":23,"z":13,"color":"#d3ab7d"},{"x":2,"y":23,"z":14,"color":"#d3ab7d"},{"x":2,"y":23,"z":15,"color":"#d3ab7d"},{"x":2,"y":23,"z":16,"color":"#d3ab7d"},{"x":2,"y":23,"z":17,"color":"#d3ab7d"},{"x":2,"y":23,"z":18,"color":"#d3ab7d"},{"x":2,"y":23,"z":19,"color":"#d3ab7d"},{"x":2,"y":23,"z":20,"color":"#d3ab7d"},{"x":2,"y":23,"z":21,"color":"#d3ab7d"},{"x":2,"y":23,"z":22,"color":"#d3ab7d"},{"x":2,"y":23,"z":23,"color":"#d3ab7d"},{"x":2,"y":23,"z":24,"color":"#d3ab7d"},{"x":2,"y":23,"z":25,"color":"#e2bf93"},{"x":2,"y":24,"z":4,"color":"#d3ab7d"},{"x":2,"y":24,"z":5,"color":"#d3ab7d"},{"x":2,"y":24,"z":6,"color":"#d3ab7d"},{"x":2,"y":24,"z":7,"color":"#d3ab7d"},{"x":2,"y":24,"z":8,"color":"#d3ab7d"},{"x":2,"y":24,"z":16,"color":"#d3ab7d"},{"x":2,"y":24,"z":17,"color":"#d3ab7d"},{"x":2,"y":24,"z":18,"color":"#d3ab7d"},{"x":2,"y":24,"z":19,"color":"#d3ab7d"},{"x":2,"y":24,"z":20,"color":"#d3ab7d"},{"x":2,"y":24,"z":21,"color":"#d3ab7d"},{"x":2,"y":24,"z":22,"color":"#d3ab7d"},{"x":2,"y":24,"z":23,"color":"#d3ab7d"},{"x":2,"y":24,"z":24,"color":"#d3ab7d"},{"x":2,"y":24,"z":25,"color":"#d3ab7d"},{"x":2,"y":25,"z":4,"color":"#c79a67"},{"x":2,"y":25,"z":5,"color":"#c79a67"},{"x":2,"y":25,"z":6,"color":"#c79a67"},{"x":2,"y":25,"z":7,"color":"#c79a67"},{"x":2,"y":25,"z":8,"color":"#c79a67"},{"x":2,"y":26,"z":4,"color":"#d3ab7d"},{"x":2,"y":26,"z":5,"color":"#d3ab7d"},{"x":2,"y":26,"z":6,"color":"#d3ab7d"},{"x":2,"y":26,"z":7,"color":"#d3ab7d"},{"x":2,"y":27,"z":4,"color":"#c79a67"},{"x":2,"y":27,"z":5,"color":"#c79a67"},{"x":2,"y":27,"z":6,"color":"#c79a67"},{"x":2,"y":27,"z":7,"color":"#c79a67"},{"x":2,"y":28,"z":3,"color":"#c79a67"},{"x":2,"y":28,"z":4,"color":"#c79a67"},{"x":2,"y":28,"z":5,"color":"#c79a67"},{"x":2,"y":28,"z":6,"color":"#c79a67"},{"x":2,"y":28,"z":7,"color":"#c79a67"},{"x":2,"y":29,"z":3,"color":"#c79a67"},{"x":2,"y":29,"z":4,"color":"#c79a67"},{"x":2,"y":29,"z":5,"color":"#c79a67"},{"x":2,"y":29,"z":6,"color":"#c79a67"},{"x":2,"y":29,"z":7,"color":"#c79a67"},{"x":2,"y":30,"z":3,"color":"#c79a67"},{"x":2,"y":30,"z":4,"color":"#c79a67"},{"x":2,"y":30,"z":5,"color":"#c79a67"},{"x":2,"y":30,"z":6,"color":"#c79a67"},{"x":2,"y":30,"z":7,"color":"#c79a67"},{"x":2,"y":31,"z":3,"color":"#c79a67"},{"x":2,"y":31,"z":4,"color":"#c79a67"},{"x":2,"y":31,"z":5,"color":"#c79a67"},{"x":2,"y":31,"z":6,"color":"#c79a67"},{"x":2,"y":32,"z":3,"color":"#c79a67"},{"x":2,"y":32,"z":4,"color":"#c79a67"},{"x":2,"y":32,"z":5,"color":"#d3ab7d"},{"x":2,"y":32,"z":6,"color":"#c79a67"},{"x":2,"y":33,"z":3,"color":"#d3ab7d"},{"x":2,"y":33,"z":4,"color":"#d3ab7d"},{"x":2,"y":33,"z":5,"color":"#d3ab7d"},{"x":2,"y":33,"z":6,"color":"#d3ab7d"},{"x":2,"y":34,"z":2,"color":"#d3ab7d"},{"x":2,"y":34,"z":3,"color":"#d3ab7d"},{"x":2,"y":34,"z":4,"color":"#d3ab7d"},{"x":2,"y":34,"z":5,"color":"#d3ab7d"},{"x":2,"y":34,"z":6,"color":"#d3ab7d"},{"x":2,"y":35,"z":2,"color":"#d3ab7d"},{"x":2,"y":35,"z":3,"color":"#d3ab7d"},{"x":2,"y":35,"z":4,"color":"#d3ab7d"},{"x":2,"y":35,"z":5,"color":"#d3ab7d"},{"x":2,"y":35,"z":6,"color":"#d3ab7d"},{"x":2,"y":36,"z":1,"color":"#d3ab7d"},{"x":2,"y":36,"z":2,"color":"#d3ab7d"},{"x":2,"y":36,"z":3,"color":"#d3ab7d"},{"x":2,"y":36,"z":4,"color":"#d3ab7d"},{"x":2,"y":36,"z":5,"color":"#d3ab7d"},{"x":2,"y":37,"z":1,"color":"#d3ab7d"},{"x":2,"y":37,"z":2,"color":"#c79a67"},{"x":2,"y":37,"z":3,"color":"#d3ab7d"},{"x":2,"y":37,"z":4,"color":"#d3ab7d"},{"x":2,"y":37,"z":5,"color":"#d3ab7d"},{"x":2,"y":38,"z":1,"color":"#e2bf93"},{"x":2,"y":38,"z":2,"color":"#c79a67"},{"x":2,"y":38,"z":3,"color":"#d3ab7d"},{"x":2,"y":38,"z":4,"color":"#e2bf93"},{"x":2,"y":38,"z":5,"color":"#e2bf93"},{"x":2,"y":39,"z":1,"color":"#d3ab7d"},{"x":2,"y":39,"z":2,"color":"#c79a67"},{"x":2,"y":39,"z":3,"color":"#d3ab7d"},{"x":2,"y":39,"z":4,"color":"#d3ab7d"},{"x":2,"y":39,"z":5,"color":"#d3ab7d"},{"x":2,"y":40,"z":1,"color":"#c79a67"},{"x":2,"y":40,"z":2,"color":"#d3ab7d"},{"x":2,"y":40,"z":3,"color":"#d3ab7d"},{"x":2,"y":40,"z":4,"color":"#d3ab7d"},{"x":2,"y":40,"z":5,"color":"#d3ab7d"},{"x":2,"y":41,"z":0,"color":"#d3ab7d"},{"x":2,"y":41,"z":1,"color":"#c79a67"},{"x":2,"y":41,"z":2,"color":"#d3ab7d"},{"x":2,"y":41,"z":3,"color":"#d3ab7d"},{"x":2,"y":41,"z":4,"color":"#d3ab7d"},{"x":2,"y":42,"z":0,"color":"#d3ab7d"},{"x":2,"y":42,"z":1,"color":"#c79a67"},{"x":2,"y":42,"z":2,"color":"#d3ab7d"},{"x":2,"y":42,"z":3,"color":"#d3ab7d"},{"x":2,"y":42,"z":4,"color":"#c79a67"},{"x":2,"y":43,"z":1,"color":"#e2bf93"},{"x":2,"y":43,"z":2,"color":"#e2bf93"},{"x":2,"y":43,"z":3,"color":"#e2bf93"},{"x":2,"y":43,"z":4,"color":"#e2bf93"},{"x":3,"y":3,"z":1,"color":"#c79a67"},{"x":3,"y":3,"z":2,"color":"#c79a67"},{"x":3,"y":3,"z":3,"color":"#b48653"},{"x":3,"y":3,"z":4,"color":"#b48653"},{"x":3,"y":3,"z":23,"color":"#d3ab7d"},{"x":3,"y":3,"z":24,"color":"#e2bf93"},{"x":3,"y":3,"z":25,"color":"#c79a67"},{"x":3,"y":4,"z":1,"color":"#c79a67"},{"x":3,"y":4,"z":2,"color":"#c79a67"},{"x":3,"y":4,"z":3,"color":"#b48653"},{"x":3,"y":4,"z":4,"color":"#b48653"},{"x":3,"y":4,"z":22,"color":"#d3ab7d"},{"x":3,"y":4,"z":23,"color":"#d3ab7d"},{"x":3,"y":4,"z":24,"color":"#e2bf93"},{"x":3,"y":4,"z":25,"color":"#c79a67"},{"x":3,"y":5,"z":1,"color":"#d3ab7d"},{"x":3,"y":5,"z":2,"color":"#c79a67"},{"x":3,"y":5,"z":3,"color":"#b48653"},{"x":3,"y":5,"z":4,"color":"#b48653"},{"x":3,"y":5,"z":22,"color":"#d3ab7d"},{"x":3,"y":5,"z":23,"color":"#d3ab7d"},{"x":3,"y":5,"z":24,"color":"#e2bf93"},{"x":3,"y":5,"z":25,"color":"#c79a67"},{"x":3,"y":6,"z":1,"color":"#e2bf93"},{"x":3,"y":6,"z":2,"color":"#c79a67"},{"x":3,"y":6,"z":3,"color":"#c79a67"},{"x":3,"y":6,"z":4,"color":"#e2bf93"},{"x":3,"y":6,"z":22,"color":"#e2bf93"},{"x":3,"y":6,"z":23,"color":"#d3ab7d"},{"x":3,"y":6,"z":24,"color":"#e2bf93"},{"x":3,"y":7,"z":1,"color":"#e2bf93"},{"x":3,"y":7,"z":2,"color":"#c79a67"},{"x":3,"y":7,"z":3,"color":"#c79a67"},{"x":3,"y":7,"z":4,"color":"#e2bf93"},{"x":3,"y":7,"z":5,"color":"#e2bf93"},{"x":3,"y":7,"z":22,"color":"#d3ab7d"},{"x":3,"y":7,"z":23,"color":"#d3ab7d"},{"x":3,"y":7,"z":24,"color":"#e2bf93"},{"x":3,"y":8,"z":2,"color":"#c79a67"},{"x":3,"y":8,"z":3,"color":"#c79a67"},{"x":3,"y":8,"z":4,"color":"#b48653"},{"x":3,"y":8,"z":5,"color":"#c79a67"},{"x":3,"y":8,"z":22,"color":"#d3ab7d"},{"x":3,"y":8,"z":23,"color":"#d3ab7d"},{"x":3,"y":8,"z":24,"color":"#e2bf93"},{"x":3,"y":9,"z":2,"color":"#c79a67"},{"x":3,"y":9,"z":3,"color":"#b48653"},{"x":3,"y":9,"z":4,"color":"#b48653"},{"x":3,"y":9,"z":5,"color":"#b48653"},{"x":3,"y":9,"z":22,"color":"#d3ab7d"},{"x":3,"y":9,"z":23,"color":"#d3ab7d"},{"x":3,"y":9,"z":24,"color":"#e2bf93"},{"x":3,"y":10,"z":2,"color":"#c79a67"},{"x":3,"y":10,"z":3,"color":"#c79a67"},{"x":3,"y":10,"z":4,"color":"#c79a67"},{"x":3,"y":10,"z":5,"color":"#b48653"},{"x":3,"y":10,"z":22,"color":"#d3ab7d"},{"x":3,"y":10,"z":23,"color":"#c79a67"},{"x":3,"y":10,"z":24,"color":"#e2bf93"},{"x":3,"y":11,"z":2,"color":"#b48653"},{"x":3,"y":11,"z":3,"color":"#b48653"},{"x":3,"y":11,"z":4,"color":"#b48653"},{"x":3,"y":11,"z":5,"color":"#b48653"},{"x":3,"y":11,"z":6,"color":"#b48653"},{"x":3,"y":11,"z":21,"color":"#c79a67"},{"x":3,"y":11,"z":22,"color":"#d3ab7d"},{"x":3,"y":11,"z":23,"color":"#d3ab7d"},{"x":3,"y":11,"z":24,"color":"#e2bf93"},{"x":3,"y":12,"z":2,"color":"#b48653"},{"x":3,"y":12,"z":3,"color":"#b48653"},{"x":3,"y":12,"z":4,"color":"#b48653"},{"x":3,"y":12,"z":5,"color":"#b48653"},{"x":3,"y":12,"z":6,"color":"#b48653"},{"x":3,"y":12,"z":21,"color":"#b48653"},{"x":3,"y":12,"z":22,"color":"#d3ab7d"},{"x":3,"y":12,"z":23,"color":"#c79a67"},{"x":3,"y":12,"z":24,"color":"#b48653"},{"x":3,"y":13,"z":3,"color":"#b48653"},{"x":3,"y":13,"z":4,"color":"#b48653"},{"x":3,"y":13,"z":5,"color":"#b48653"},{"x":3,"y":13,"z":6,"color":"#966a3b"},{"x":3,"y":13,"z":21,"color":"#c79a67"},{"x":3,"y":13,"z":22,"color":"#c79a67"},{"x":3,"y":13,"z":23,"color":"#966a3b"},{"x":3,"y":13,"z":24,"color":"#966a3b"},{"x":3,"y":14,"z":3,"color":"#b48653"},{"x":3,"y":14,"z":4,"color":"#b48653"},{"x":3,"y":14,"z":5,"color":"#b48653"},{"x":3,"y":14,"z":6,"color":"#966a3b"},{"x":3,"y":14,"z":21,"color":"#c79a67"},{"x":3,"y":14,"z":22,"color":"#c79a67"},{"x":3,"y":14,"z":23,"color":"#966a3b"},{"x":3,"y":14,"z":24,"color":"#966a3b"},{"x":3,"y":15,"z":3,"color":"#966a3b"},{"x":3,"y":15,"z":4,"color":"#b48653"},{"x":3,"y":15,"z":5,"color":"#b48653"},{"x":3,"y":15,"z":6,"color":"#b48653"},{"x":3,"y":15,"z":7,"color":"#966a3b"},{"x":3,"y":15,"z":21,"color":"#c79a67"},{"x":3,"y":15,"z":22,"color":"#c79a67"},{"x":3,"y":15,"z":23,"color":"#966a3b"},{"x":3,"y":15,"z":24,"color":"#966a3b"},{"x":3,"y":16,"z":3,"color":"#b48653"},{"x":3,"y":16,"z":4,"color":"#b48653"},{"x":3,"y":16,"z":5,"color":"#b48653"},{"x":3,"y":16,"z":6,"color":"#b48653"},{"x":3,"y":16,"z":7,"color":"#b48653"},{"x":3,"y":16,"z":21,"color":"#d3ab7d"},{"x":3,"y":16,"z":22,"color":"#d3ab7d"},{"x":3,"y":16,"z":23,"color":"#b48653"},{"x":3,"y":16,"z":24,"color":"#b48653"},{"x":3,"y":17,"z":3,"color":"#b48653"},{"x":3,"y":17,"z":4,"color":"#c79a67"},{"x":3,"y":17,"z":5,"color":"#c79a67"},{"x":3,"y":17,"z":6,"color":"#b48653"},{"x":3,"y":17,"z":7,"color":"#b48653"},{"x":3,"y":17,"z":21,"color":"#d3ab7d"},{"x":3,"y":17,"z":22,"color":"#d3ab7d"},{"x":3,"y":17,"z":23,"color":"#c79a67"},{"x":3,"y":18,"z":4,"color":"#c79a67"},{"x":3,"y":18,"z":5,"color":"#c79a67"},{"x":3,"y":18,"z":6,"color":"#c79a67"},{"x":3,"y":18,"z":7,"color":"#b48653"},{"x":3,"y":18,"z":8,"color":"#c79a67"},{"x":3,"y":18,"z":20,"color":"#c79a67"},{"x":3,"y":18,"z":21,"color":"#d3ab7d"},{"x":3,"y":18,"z":22,"color":"#d3ab7d"},{"x":3,"y":18,"z":23,"color":"#c79a67"},{"x":3,"y":19,"z":4,"color":"#c79a67"},{"x":3,"y":19,"z":5,"color":"#b48653"},{"x":3,"y":19,"z":6,"color":"#c79a67"},{"x":3,"y":19,"z":7,"color":"#d3ab7d"},{"x":3,"y":19,"z":8,"color":"#c79a67"},{"x":3,"y":19,"z":9,"color":"#d3ab7d"},{"x":3,"y":19,"z":10,"color":"#c79a67"},{"x":3,"y":19,"z":11,"color":"#d3ab7d"},{"x":3,"y":19,"z":12,"color":"#d3ab7d"},{"x":3,"y":19,"z":13,"color":"#d3ab7d"},{"x":3,"y":19,"z":20,"color":"#c79a67"},{"x":3,"y":19,"z":21,"color":"#d3ab7d"},{"x":3,"y":19,"z":22,"color":"#d3ab7d"},{"x":3,"y":19,"z":23,"color":"#d3ab7d"},{"x":3,"y":20,"z":4,"color":"#c79a67"},{"x":3,"y":20,"z":5,"color":"#c79a67"},{"x":3,"y":20,"z":6,"color":"#c79a67"},{"x":3,"y":20,"z":7,"color":"#c79a67"},{"x":3,"y":20,"z":8,"color":"#c79a67"},{"x":3,"y":20,"z":9,"color":"#c79a67"},{"x":3,"y":20,"z":10,"color":"#c79a67"},{"x":3,"y":20,"z":11,"color":"#b48653"},{"x":3,"y":20,"z":12,"color":"#e2bf93"},{"x":3,"y":20,"z":13,"color":"#c79a67"},{"x":3,"y":20,"z":14,"color":"#c79a67"},{"x":3,"y":20,"z":15,"color":"#c79a67"},{"x":3,"y":20,"z":16,"color":"#c79a67"},{"x":3,"y":20,"z":17,"color":"#c79a67"},{"x":3,"y":20,"z":18,"color":"#c79a67"},{"x":3,"y":20,"z":19,"color":"#c79a67"},{"x":3,"y":20,"z":20,"color":"#c79a67"},{"x":3,"y":20,"z":21,"color":"#c79a67"},{"x":3,"y":20,"z":22,"color":"#c79a67"},{"x":3,"y":20,"z":23,"color":"#c79a67"},{"x":3,"y":20,"z":24,"color":"#c79a67"},{"x":3,"y":20,"z":25,"color":"#966a3b"},{"x":3,"y":21,"z":4,"color":"#966a3b"},{"x":3,"y":21,"z":5,"color":"#b48653"},{"x":3,"y":21,"z":6,"color":"#c79a67"},{"x":3,"y":21,"z":7,"color":"#966a3b"},{"x":3,"y":21,"z":8,"color":"#b48653"},{"x":3,"y":21,"z":9,"color":"#b48653"},{"x":3,"y":21,"z":10,"color":"#b48653"},{"x":3,"y":21,"z":11,"color":"#b48653"},{"x":3,"y":21,"z":12,"color":"#b48653"},{"x":3,"y":21,"z":13,"color":"#c79a67"},{"x":3,"y":21,"z":14,"color":"#c79a67"},{"x":3,"y":21,"z":15,"color":"#b48653"},{"x":3,"y":21,"z":16,"color":"#966a3b"},{"x":3,"y":21,"z":17,"color":"#966a3b"},{"x":3,"y":21,"z":18,"color":"#966a3b"},{"x":3,"y":21,"z":19,"color":"#966a3b"},{"x":3,"y":21,"z":20,"color":"#966a3b"},{"x":3,"y":21,"z":21,"color":"#966a3b"},{"x":3,"y":21,"z":22,"color":"#966a3b"},{"x":3,"y":21,"z":23,"color":"#c79a67"},{"x":3,"y":21,"z":24,"color":"#966a3b"},{"x":3,"y":21,"z":25,"color":"#966a3b"},{"x":3,"y":22,"z":4,"color":"#b48653"},{"x":3,"y":22,"z":5,"color":"#b48653"},{"x":3,"y":22,"z":6,"color":"#c79a67"},{"x":3,"y":22,"z":7,"color":"#b48653"},{"x":3,"y":22,"z":8,"color":"#b48653"},{"x":3,"y":22,"z":9,"color":"#b48653"},{"x":3,"y":22,"z":10,"color":"#b48653"},{"x":3,"y":22,"z":11,"color":"#b48653"},{"x":3,"y":22,"z":12,"color":"#c79a67"},{"x":3,"y":22,"z":13,"color":"#c79a67"},{"x":3,"y":22,"z":14,"color":"#c79a67"},{"x":3,"y":22,"z":15,"color":"#c79a67"},{"x":3,"y":22,"z":16,"color":"#b48653"},{"x":3,"y":22,"z":17,"color":"#b48653"},{"x":3,"y":22,"z":18,"color":"#b48653"},{"x":3,"y":22,"z":19,"color":"#b48653"},{"x":3,"y":22,"z":20,"color":"#b48653"},{"x":3,"y":22,"z":21,"color":"#b48653"},{"x":3,"y":22,"z":22,"color":"#b48653"},{"x":3,"y":22,"z":23,"color":"#b48653"},{"x":3,"y":22,"z":24,"color":"#b48653"},{"x":3,"y":22,"z":25,"color":"#b48653"},{"x":3,"y":23,"z":4,"color":"#b48653"},{"x":3,"y":23,"z":5,"color":"#c79a67"},{"x":3,"y":23,"z":6,"color":"#c79a67"},{"x":3,"y":23,"z":7,"color":"#b48653"},{"x":3,"y":23,"z":8,"color":"#c79a67"},{"x":3,"y":23,"z":9,"color":"#c79a67"},{"x":3,"y":23,"z":10,"color":"#c79a67"},{"x":3,"y":23,"z":11,"color":"#d3ab7d"},{"x":3,"y":23,"z":12,"color":"#d3ab7d"},{"x":3,"y":23,"z":13,"color":"#d3ab7d"},{"x":3,"y":23,"z":14,"color":"#d3ab7d"},{"x":3,"y":23,"z":15,"color":"#d3ab7d"},{"x":3,"y":23,"z":16,"color":"#d3ab7d"},{"x":3,"y":23,"z":17,"color":"#d3ab7d"},{"x":3,"y":23,"z":18,"color":"#d3ab7d"},{"x":3,"y":23,"z":19,"color":"#d3ab7d"},{"x":3,"y":23,"z":20,"color":"#d3ab7d"},{"x":3,"y":23,"z":21,"color":"#d3ab7d"},{"x":3,"y":23,"z":22,"color":"#d3ab7d"},{"x":3,"y":23,"z":23,"color":"#d3ab7d"},{"x":3,"y":23,"z":24,"color":"#e2bf93"},{"x":3,"y":23,"z":25,"color":"#d3ab7d"},{"x":3,"y":24,"z":4,"color":"#b48653"},{"x":3,"y":24,"z":5,"color":"#c79a67"},{"x":3,"y":24,"z":6,"color":"#c79a67"},{"x":3,"y":24,"z":7,"color":"#b48653"},{"x":3,"y":24,"z":8,"color":"#c79a67"},{"x":3,"y":24,"z":16,"color":"#d3ab7d"},{"x":3,"y":24,"z":17,"color":"#e2bf93"},{"x":3,"y":24,"z":18,"color":"#d3ab7d"},{"x":3,"y":24,"z":19,"color":"#e2bf93"},{"x":3,"y":24,"z":20,"color":"#e2bf93"},{"x":3,"y":24,"z":21,"color":"#d3ab7d"},{"x":3,"y":24,"z":22,"color":"#d3ab7d"},{"x":3,"y":24,"z":23,"color":"#e2bf93"},{"x":3,"y":24,"z":24,"color":"#e2bf93"},{"x":3,"y":24,"z":25,"color":"#c79a67"},{"x":3,"y":25,"z":4,"color":"#b48653"},{"x":3,"y":25,"z":5,"color":"#c79a67"},{"x":3,"y":25,"z":6,"color":"#c79a67"},{"x":3,"y":25,"z":7,"color":"#b48653"},{"x":3,"y":25,"z":8,"color":"#c79a67"},{"x":3,"y":26,"z":4,"color":"#d3ab7d"},{"x":3,"y":26,"z":5,"color":"#d3ab7d"},{"x":3,"y":26,"z":6,"color":"#d3ab7d"},{"x":3,"y":26,"z":7,"color":"#d3ab7d"},{"x":3,"y":27,"z":4,"color":"#c79a67"},{"x":3,"y":27,"z":5,"color":"#c79a67"},{"x":3,"y":27,"z":6,"color":"#c79a67"},{"x":3,"y":27,"z":7,"color":"#b48653"},{"x":3,"y":28,"z":3,"color":"#b48653"},{"x":3,"y":28,"z":4,"color":"#c79a67"},{"x":3,"y":28,"z":5,"color":"#c79a67"},{"x":3,"y":28,"z":6,"color":"#c79a67"},{"x":3,"y":28,"z":7,"color":"#b48653"},{"x":3,"y":29,"z":3,"color":"#c79a67"},{"x":3,"y":29,"z":4,"color":"#c79a67"},{"x":3,"y":29,"z":5,"color":"#c79a67"},{"x":3,"y":29,"z":6,"color":"#c79a67"},{"x":3,"y":29,"z":7,"color":"#c79a67"},{"x":3,"y":30,"z":3,"color":"#d3ab7d"},{"x":3,"y":30,"z":4,"color":"#d3ab7d"},{"x":3,"y":30,"z":5,"color":"#d3ab7d"},{"x":3,"y":30,"z":6,"color":"#d3ab7d"},{"x":3,"y":30,"z":7,"color":"#d3ab7d"},{"x":3,"y":31,"z":3,"color":"#e2bf93"},{"x":3,"y":31,"z":4,"color":"#c79a67"},{"x":3,"y":31,"z":5,"color":"#d3ab7d"},{"x":3,"y":31,"z":6,"color":"#e2bf93"},{"x":3,"y":32,"z":3,"color":"#c79a67"},{"x":3,"y":32,"z":4,"color":"#c79a67"},{"x":3,"y":32,"z":5,"color":"#e2bf93"},{"x":3,"y":32,"z":6,"color":"#d3ab7d"},{"x":3,"y":33,"z":3,"color":"#d3ab7d"},{"x":3,"y":33,"z":4,"color":"#d3ab7d"},{"x":3,"y":33,"z":5,"color":"#d3ab7d"},{"x":3,"y":33,"z":6,"color":"#d3ab7d"},{"x":3,"y":34,"z":2,"color":"#e2bf93"},{"x":3,"y":34,"z":3,"color":"#d3ab7d"},{"x":3,"y":34,"z":4,"color":"#d3ab7d"},{"x":3,"y":34,"z":5,"color":"#d3ab7d"},{"x":3,"y":34,"z":6,"color":"#e2bf93"},{"x":3,"y":35,"z":2,"color":"#c79a67"},{"x":3,"y":35,"z":3,"color":"#c79a67"},{"x":3,"y":35,"z":4,"color":"#d3ab7d"},{"x":3,"y":35,"z":5,"color":"#b48653"},{"x":3,"y":35,"z":6,"color":"#c79a67"},{"x":3,"y":36,"z":1,"color":"#d3ab7d"},{"x":3,"y":36,"z":2,"color":"#c79a67"},{"x":3,"y":36,"z":3,"color":"#c79a67"},{"x":3,"y":36,"z":4,"color":"#d3ab7d"},{"x":3,"y":36,"z":5,"color":"#c79a67"},{"x":3,"y":37,"z":1,"color":"#d3ab7d"},{"x":3,"y":37,"z":2,"color":"#c79a67"},{"x":3,"y":37,"z":3,"color":"#c79a67"},{"x":3,"y":37,"z":4,"color":"#e2bf93"},{"x":3,"y":37,"z":5,"color":"#b48653"},{"x":3,"y":38,"z":1,"color":"#d3ab7d"},{"x":3,"y":38,"z":2,"color":"#b48653"},{"x":3,"y":38,"z":3,"color":"#c79a67"},{"x":3,"y":38,"z":4,"color":"#d3ab7d"},{"x":3,"y":38,"z":5,"color":"#b48653"},{"x":3,"y":39,"z":1,"color":"#d3ab7d"},{"x":3,"y":39,"z":2,"color":"#b48653"},{"x":3,"y":39,"z":3,"color":"#c79a67"},{"x":3,"y":39,"z":4,"color":"#d3ab7d"},{"x":3,"y":39,"z":5,"color":"#b48653"},{"x":3,"y":40,"z":1,"color":"#c79a67"},{"x":3,"y":40,"z":2,"color":"#c79a67"},{"x":3,"y":40,"z":3,"color":"#c79a67"},{"x":3,"y":40,"z":4,"color":"#b48653"},{"x":3,"y":40,"z":5,"color":"#b48653"},{"x":3,"y":41,"z":1,"color":"#c79a67"},{"x":3,"y":41,"z":2,"color":"#c79a67"},{"x":3,"y":41,"z":3,"color":"#b48653"},{"x":3,"y":41,"z":4,"color":"#d3ab7d"},{"x":3,"y":42,"z":1,"color":"#c79a67"},{"x":3,"y":42,"z":2,"color":"#e2bf93"},{"x":3,"y":42,"z":3,"color":"#d3ab7d"},{"x":3,"y":42,"z":4,"color":"#b48653"},{"x":3,"y":43,"z":1,"color":"#e2bf93"},{"x":3,"y":43,"z":2,"color":"#e2bf93"},{"x":3,"y":43,"z":3,"color":"#e2bf93"},{"x":3,"y":43,"z":4,"color":"#e2bf93"},{"x":4,"y":10,"z":2,"color":"#c79a67"},{"x":4,"y":10,"z":3,"color":"#c79a67"},{"x":4,"y":10,"z":4,"color":"#c79a67"},{"x":4,"y":10,"z":5,"color":"#c79a67"},{"x":4,"y":10,"z":22,"color":"#d3ab7d"},{"x":4,"y":10,"z":23,"color":"#c79a67"},{"x":4,"y":10,"z":24,"color":"#c79a67"},{"x":4,"y":11,"z":2,"color":"#c79a67"},{"x":4,"y":11,"z":3,"color":"#c79a67"},{"x":4,"y":11,"z":4,"color":"#c79a67"},{"x":4,"y":11,"z":5,"color":"#e2bf93"},{"x":4,"y":11,"z":6,"color":"#c79a67"},{"x":4,"y":11,"z":21,"color":"#c79a67"},{"x":4,"y":11,"z":22,"color":"#d3ab7d"},{"x":4,"y":11,"z":23,"color":"#e2bf93"},{"x":4,"y":11,"z":24,"color":"#c79a67"},{"x":4,"y":12,"z":2,"color":"#c79a67"},{"x":4,"y":12,"z":3,"color":"#c79a67"},{"x":4,"y":12,"z":4,"color":"#c79a67"},{"x":4,"y":12,"z":5,"color":"#b48653"},{"x":4,"y":12,"z":6,"color":"#c79a67"},{"x":4,"y":12,"z":21,"color":"#c79a67"},{"x":4,"y":12,"z":22,"color":"#d3ab7d"},{"x":4,"y":12,"z":23,"color":"#e2bf93"},{"x":4,"y":12,"z":24,"color":"#c79a67"},{"x":4,"y":13,"z":3,"color":"#c79a67"},{"x":4,"y":13,"z":4,"color":"#c79a67"},{"x":4,"y":13,"z":5,"color":"#b48653"},{"x":4,"y":13,"z":6,"color":"#c79a67"},{"x":4,"y":13,"z":21,"color":"#c79a67"},{"x":4,"y":13,"z":22,"color":"#d3ab7d"},{"x":4,"y":13,"z":23,"color":"#c79a67"},{"x":4,"y":13,"z":24,"color":"#c79a67"},{"x":4,"y":14,"z":3,"color":"#d3ab7d"},{"x":4,"y":14,"z":4,"color":"#c79a67"},{"x":4,"y":14,"z":5,"color":"#c79a67"},{"x":4,"y":14,"z":6,"color":"#c79a67"},{"x":4,"y":14,"z":21,"color":"#c79a67"},{"x":4,"y":14,"z":22,"color":"#d3ab7d"},{"x":4,"y":14,"z":23,"color":"#c79a67"},{"x":4,"y":14,"z":24,"color":"#c79a67"},{"x":4,"y":15,"z":3,"color":"#b48653"},{"x":4,"y":15,"z":4,"color":"#c79a67"},{"x":4,"y":15,"z":5,"color":"#c79a67"},{"x":4,"y":15,"z":6,"color":"#e2bf93"},{"x":4,"y":15,"z":7,"color":"#d3ab7d"},{"x":4,"y":15,"z":21,"color":"#c79a67"},{"x":4,"y":15,"z":22,"color":"#d3ab7d"},{"x":4,"y":15,"z":23,"color":"#c79a67"},{"x":4,"y":15,"z":24,"color":"#c79a67"},{"x":4,"y":16,"z":3,"color":"#e2bf93"},{"x":4,"y":16,"z":4,"color":"#d3ab7d"},{"x":4,"y":16,"z":5,"color":"#c79a67"},{"x":4,"y":16,"z":6,"color":"#b48653"},{"x":4,"y":16,"z":7,"color":"#d3ab7d"},{"x":4,"y":16,"z":21,"color":"#d3ab7d"},{"x":4,"y":16,"z":22,"color":"#d3ab7d"},{"x":4,"y":16,"z":23,"color":"#c79a67"},{"x":4,"y":16,"z":24,"color":"#c79a67"},{"x":4,"y":17,"z":3,"color":"#b48653"},{"x":4,"y":17,"z":4,"color":"#e2bf93"},{"x":4,"y":17,"z":5,"color":"#c79a67"},{"x":4,"y":17,"z":6,"color":"#b48653"},{"x":4,"y":17,"z":7,"color":"#d3ab7d"},{"x":4,"y":17,"z":21,"color":"#d3ab7d"},{"x":4,"y":17,"z":22,"color":"#d3ab7d"},{"x":4,"y":17,"z":23,"color":"#c79a67"},{"x":4,"y":18,"z":4,"color":"#e2bf93"},{"x":4,"y":18,"z":5,"color":"#c79a67"},{"x":4,"y":18,"z":6,"color":"#c79a67"},{"x":4,"y":18,"z":7,"color":"#d3ab7d"},{"x":4,"y":18,"z":8,"color":"#d3ab7d"},{"x":4,"y":18,"z":20,"color":"#d3ab7d"},{"x":4,"y":18,"z":21,"color":"#d3ab7d"},{"x":4,"y":18,"z":22,"color":"#e2bf93"},{"x":4,"y":18,"z":23,"color":"#c79a67"},{"x":4,"y":19,"z":4,"color":"#e2bf93"},{"x":4,"y":19,"z":5,"color":"#c79a67"},{"x":4,"y":19,"z":6,"color":"#c79a67"},{"x":4,"y":19,"z":7,"color":"#e2bf93"},{"x":4,"y":19,"z":8,"color":"#d3ab7d"},{"x":4,"y":19,"z":9,"color":"#c79a67"},{"x":4,"y":19,"z":10,"color":"#d3ab7d"},{"x":4,"y":19,"z":11,"color":"#c79a67"},{"x":4,"y":19,"z":12,"color":"#d3ab7d"},{"x":4,"y":19,"z":13,"color":"#d3ab7d"},{"x":4,"y":19,"z":20,"color":"#c79a67"},{"x":4,"y":19,"z":21,"color":"#c79a67"},{"x":4,"y":19,"z":22,"color":"#e2bf93"},{"x":4,"y":19,"z":23,"color":"#c79a67"},{"x":4,"y":20,"z":4,"color":"#d3ab7d"},{"x":4,"y":20,"z":5,"color":"#c79a67"},{"x":4,"y":20,"z":6,"color":"#c79a67"},{"x":4,"y":20,"z":7,"color":"#c79a67"},{"x":4,"y":20,"z":8,"color":"#d3ab7d"},{"x":4,"y":20,"z":9,"color":"#c79a67"},{"x":4,"y":20,"z":10,"color":"#d3ab7d"},{"x":4,"y":20,"z":11,"color":"#b48653"},{"x":4,"y":20,"z":12,"color":"#e2bf93"},{"x":4,"y":20,"z":13,"color":"#c79a67"},{"x":4,"y":20,"z":14,"color":"#c79a67"},{"x":4,"y":20,"z":15,"color":"#c79a67"},{"x":4,"y":20,"z":16,"color":"#c79a67"},{"x":4,"y":20,"z":17,"color":"#c79a67"},{"x":4,"y":20,"z":18,"color":"#c79a67"},{"x":4,"y":20,"z":19,"color":"#c79a67"},{"x":4,"y":20,"z":20,"color":"#c79a67"},{"x":4,"y":20,"z":21,"color":"#c79a67"},{"x":4,"y":20,"z":22,"color":"#d3ab7d"},{"x":4,"y":20,"z":23,"color":"#c79a67"},{"x":4,"y":20,"z":24,"color":"#b48653"},{"x":4,"y":20,"z":25,"color":"#b48653"},{"x":4,"y":21,"z":4,"color":"#b48653"},{"x":4,"y":21,"z":5,"color":"#c79a67"},{"x":4,"y":21,"z":6,"color":"#c79a67"},{"x":4,"y":21,"z":7,"color":"#966a3b"},{"x":4,"y":21,"z":8,"color":"#b48653"},{"x":4,"y":21,"z":9,"color":"#b48653"},{"x":4,"y":21,"z":10,"color":"#b48653"},{"x":4,"y":21,"z":11,"color":"#b48653"},{"x":4,"y":21,"z":12,"color":"#c79a67"},{"x":4,"y":21,"z":13,"color":"#c79a67"},{"x":4,"y":21,"z":14,"color":"#c79a67"},{"x":4,"y":21,"z":15,"color":"#b48653"},{"x":4,"y":21,"z":16,"color":"#b48653"},{"x":4,"y":21,"z":17,"color":"#b48653"},{"x":4,"y":21,"z":18,"color":"#966a3b"},{"x":4,"y":21,"z":19,"color":"#966a3b"},{"x":4,"y":21,"z":20,"color":"#966a3b"},{"x":4,"y":21,"z":21,"color":"#966a3b"},{"x":4,"y":21,"z":22,"color":"#966a3b"},{"x":4,"y":21,"z":23,"color":"#c79a67"},{"x":4,"y":21,"z":24,"color":"#966a3b"},{"x":4,"y":21,"z":25,"color":"#966a3b"},{"x":4,"y":22,"z":4,"color":"#c79a67"},{"x":4,"y":22,"z":5,"color":"#c79a67"},{"x":4,"y":22,"z":6,"color":"#c79a67"},{"x":4,"y":22,"z":7,"color":"#b48653"},{"x":4,"y":22,"z":8,"color":"#b48653"},{"x":4,"y":22,"z":9,"color":"#b48653"},{"x":4,"y":22,"z":10,"color":"#c79a67"},{"x":4,"y":22,"z":11,"color":"#b48653"},{"x":4,"y":22,"z":12,"color":"#c79a67"},{"x":4,"y":22,"z":13,"color":"#c79a67"},{"x":4,"y":22,"z":14,"color":"#c79a67"},{"x":4,"y":22,"z":15,"color":"#c79a67"},{"x":4,"y":22,"z":16,"color":"#b48653"},{"x":4,"y":22,"z":17,"color":"#b48653"},{"x":4,"y":22,"z":18,"color":"#b48653"},{"x":4,"y":22,"z":19,"color":"#b48653"},{"x":4,"y":22,"z":20,"color":"#b48653"},{"x":4,"y":22,"z":21,"color":"#b48653"},{"x":4,"y":22,"z":22,"color":"#b48653"},{"x":4,"y":22,"z":23,"color":"#c79a67"},{"x":4,"y":22,"z":24,"color":"#b48653"},{"x":4,"y":22,"z":25,"color":"#c79a67"},{"x":4,"y":23,"z":4,"color":"#d3ab7d"},{"x":4,"y":23,"z":5,"color":"#d3ab7d"},{"x":4,"y":23,"z":6,"color":"#d3ab7d"},{"x":4,"y":23,"z":7,"color":"#d3ab7d"},{"x":4,"y":23,"z":8,"color":"#d3ab7d"},{"x":4,"y":23,"z":9,"color":"#d3ab7d"},{"x":4,"y":23,"z":10,"color":"#d3ab7d"},{"x":4,"y":23,"z":11,"color":"#d3ab7d"},{"x":4,"y":23,"z":12,"color":"#d3ab7d"},{"x":4,"y":23,"z":13,"color":"#d3ab7d"},{"x":4,"y":23,"z":14,"color":"#d3ab7d"},{"x":4,"y":23,"z":15,"color":"#d3ab7d"},{"x":4,"y":23,"z":16,"color":"#d3ab7d"},{"x":4,"y":23,"z":17,"color":"#d3ab7d"},{"x":4,"y":23,"z":18,"color":"#d3ab7d"},{"x":4,"y":23,"z":19,"color":"#d3ab7d"},{"x":4,"y":23,"z":20,"color":"#d3ab7d"},{"x":4,"y":23,"z":21,"color":"#d3ab7d"},{"x":4,"y":23,"z":22,"color":"#d3ab7d"},{"x":4,"y":23,"z":23,"color":"#d3ab7d"},{"x":4,"y":23,"z":24,"color":"#d3ab7d"},{"x":4,"y":23,"z":25,"color":"#d3ab7d"},{"x":4,"y":24,"z":4,"color":"#d3ab7d"},{"x":4,"y":24,"z":5,"color":"#d3ab7d"},{"x":4,"y":24,"z":6,"color":"#c79a67"},{"x":4,"y":24,"z":7,"color":"#d3ab7d"},{"x":4,"y":24,"z":8,"color":"#d3ab7d"},{"x":4,"y":24,"z":16,"color":"#d3ab7d"},{"x":4,"y":24,"z":17,"color":"#e2bf93"},{"x":4,"y":24,"z":18,"color":"#e2bf93"},{"x":4,"y":24,"z":19,"color":"#e2bf93"},{"x":4,"y":24,"z":20,"color":"#e2bf93"},{"x":4,"y":24,"z":21,"color":"#d3ab7d"},{"x":4,"y":24,"z":22,"color":"#e2bf93"},{"x":4,"y":24,"z":23,"color":"#e2bf93"},{"x":4,"y":24,"z":24,"color":"#e2bf93"},{"x":4,"y":24,"z":25,"color":"#d3ab7d"},{"x":4,"y":25,"z":4,"color":"#d3ab7d"},{"x":4,"y":25,"z":5,"color":"#c79a67"},{"x":4,"y":25,"z":6,"color":"#c79a67"},{"x":4,"y":25,"z":7,"color":"#c79a67"},{"x":4,"y":25,"z":8,"color":"#d3ab7d"},{"x":4,"y":26,"z":4,"color":"#e2bf93"},{"x":4,"y":26,"z":5,"color":"#d3ab7d"},{"x":4,"y":26,"z":6,"color":"#d3ab7d"},{"x":4,"y":26,"z":7,"color":"#e2bf93"},{"x":4,"y":27,"z":4,"color":"#d3ab7d"},{"x":4,"y":27,"z":5,"color":"#c79a67"},{"x":4,"y":27,"z":6,"color":"#c79a67"},{"x":4,"y":27,"z":7,"color":"#d3ab7d"},{"x":4,"y":28,"z":3,"color":"#b48653"},{"x":4,"y":28,"z":4,"color":"#d3ab7d"},{"x":4,"y":28,"z":5,"color":"#c79a67"},{"x":4,"y":28,"z":6,"color":"#c79a67"},{"x":4,"y":28,"z":7,"color":"#d3ab7d"},{"x":4,"y":29,"z":3,"color":"#b48653"},{"x":4,"y":29,"z":4,"color":"#d3ab7d"},{"x":4,"y":29,"z":5,"color":"#c79a67"},{"x":4,"y":29,"z":6,"color":"#c79a67"},{"x":4,"y":29,"z":7,"color":"#d3ab7d"},{"x":4,"y":30,"z":3,"color":"#b48653"},{"x":4,"y":30,"z":4,"color":"#e2bf93"},{"x":4,"y":30,"z":5,"color":"#d3ab7d"},{"x":4,"y":30,"z":6,"color":"#c79a67"},{"x":4,"y":30,"z":7,"color":"#d3ab7d"},{"x":4,"y":31,"z":3,"color":"#e2bf93"},{"x":4,"y":31,"z":4,"color":"#d3ab7d"},{"x":4,"y":31,"z":5,"color":"#c79a67"},{"x":4,"y":31,"z":6,"color":"#d3ab7d"},{"x":4,"y":32,"z":3,"color":"#b48653"},{"x":4,"y":32,"z":4,"color":"#d3ab7d"},{"x":4,"y":32,"z":5,"color":"#e2bf93"},{"x":4,"y":32,"z":6,"color":"#c79a67"},{"x":4,"y":34,"z":2,"color":"#c79a67"},{"x":4,"y":34,"z":3,"color":"#d3ab7d"},{"x":4,"y":34,"z":4,"color":"#d3ab7d"},{"x":4,"y":34,"z":5,"color":"#d3ab7d"},{"x":4,"y":34,"z":6,"color":"#c79a67"},{"x":4,"y":35,"z":2,"color":"#d3ab7d"},{"x":4,"y":35,"z":3,"color":"#d3ab7d"},{"x":4,"y":35,"z":4,"color":"#e2bf93"},{"x":4,"y":35,"z":5,"color":"#d3ab7d"},{"x":4,"y":35,"z":6,"color":"#d3ab7d"},{"x":4,"y":36,"z":1,"color":"#d3ab7d"},{"x":4,"y":36,"z":2,"color":"#c79a67"},{"x":4,"y":36,"z":3,"color":"#d3ab7d"},{"x":4,"y":36,"z":4,"color":"#e2bf93"},{"x":4,"y":36,"z":5,"color":"#d3ab7d"},{"x":4,"y":37,"z":1,"color":"#d3ab7d"},{"x":4,"y":37,"z":2,"color":"#c79a67"},{"x":4,"y":37,"z":3,"color":"#d3ab7d"},{"x":4,"y":37,"z":4,"color":"#e2bf93"},{"x":4,"y":37,"z":5,"color":"#d3ab7d"},{"x":4,"y":38,"z":1,"color":"#d3ab7d"},{"x":4,"y":38,"z":2,"color":"#c79a67"},{"x":4,"y":38,"z":3,"color":"#d3ab7d"},{"x":4,"y":38,"z":4,"color":"#e2bf93"},{"x":4,"y":38,"z":5,"color":"#d3ab7d"},{"x":4,"y":39,"z":1,"color":"#d3ab7d"},{"x":4,"y":39,"z":2,"color":"#c79a67"},{"x":4,"y":39,"z":3,"color":"#d3ab7d"},{"x":4,"y":39,"z":4,"color":"#e2bf93"},{"x":4,"y":39,"z":5,"color":"#d3ab7d"},{"x":4,"y":40,"z":1,"color":"#d3ab7d"},{"x":4,"y":40,"z":2,"color":"#c79a67"},{"x":4,"y":40,"z":3,"color":"#d3ab7d"},{"x":4,"y":40,"z":4,"color":"#e2bf93"},{"x":4,"y":40,"z":5,"color":"#e2bf93"},{"x":4,"y":41,"z":1,"color":"#d3ab7d"},{"x":4,"y":41,"z":2,"color":"#e2bf93"},{"x":4,"y":41,"z":3,"color":"#d3ab7d"},{"x":4,"y":41,"z":4,"color":"#e2bf93"},{"x":4,"y":42,"z":1,"color":"#d3ab7d"},{"x":4,"y":42,"z":2,"color":"#e2bf93"},{"x":4,"y":42,"z":3,"color":"#d3ab7d"},{"x":4,"y":42,"z":4,"color":"#e2bf93"},{"x":4,"y":43,"z":1,"color":"#d3ab7d"},{"x":4,"y":43,"z":2,"color":"#c79a67"},{"x":4,"y":43,"z":3,"color":"#e2bf93"},{"x":4,"y":43,"z":4,"color":"#e2bf93"},{"x":5,"y":19,"z":4,"color":"#d3ab7d"},{"x":5,"y":19,"z":5,"color":"#c79a67"},{"x":5,"y":19,"z":6,"color":"#c79a67"},{"x":5,"y":19,"z":7,"color":"#e2bf93"},{"x":5,"y":19,"z":8,"color":"#d3ab7d"},{"x":5,"y":19,"z":9,"color":"#b48653"},{"x":5,"y":19,"z":10,"color":"#d3ab7d"},{"x":5,"y":19,"z":11,"color":"#d3ab7d"},{"x":5,"y":19,"z":12,"color":"#d3ab7d"},{"x":5,"y":19,"z":13,"color":"#c79a67"},{"x":5,"y":19,"z":20,"color":"#c79a67"},{"x":5,"y":19,"z":21,"color":"#d3ab7d"},{"x":5,"y":19,"z":22,"color":"#d3ab7d"},{"x":5,"y":19,"z":23,"color":"#d3ab7d"},{"x":5,"y":20,"z":4,"color":"#c79a67"},{"x":5,"y":20,"z":5,"color":"#c79a67"},{"x":5,"y":20,"z":6,"color":"#c79a67"},{"x":5,"y":20,"z":7,"color":"#c79a67"},{"x":5,"y":20,"z":8,"color":"#d3ab7d"},{"x":5,"y":20,"z":9,"color":"#c79a67"},{"x":5,"y":20,"z":10,"color":"#d3ab7d"},{"x":5,"y":20,"z":11,"color":"#b48653"},{"x":5,"y":20,"z":12,"color":"#e2bf93"},{"x":5,"y":20,"z":13,"color":"#c79a67"},{"x":5,"y":20,"z":14,"color":"#c79a67"},{"x":5,"y":20,"z":15,"color":"#c79a67"},{"x":5,"y":20,"z":16,"color":"#c79a67"},{"x":5,"y":20,"z":17,"color":"#c79a67"},{"x":5,"y":20,"z":18,"color":"#c79a67"},{"x":5,"y":20,"z":19,"color":"#c79a67"},{"x":5,"y":20,"z":20,"color":"#c79a67"},{"x":5,"y":20,"z":21,"color":"#c79a67"},{"x":5,"y":20,"z":22,"color":"#c79a67"},{"x":5,"y":20,"z":23,"color":"#c79a67"},{"x":5,"y":20,"z":24,"color":"#e2bf93"},{"x":5,"y":20,"z":25,"color":"#b48653"},{"x":5,"y":21,"z":4,"color":"#b48653"},{"x":5,"y":21,"z":5,"color":"#c79a67"},{"x":5,"y":21,"z":6,"color":"#c79a67"},{"x":5,"y":21,"z":7,"color":"#966a3b"},{"x":5,"y":21,"z":8,"color":"#b48653"},{"x":5,"y":21,"z":9,"color":"#b48653"},{"x":5,"y":21,"z":10,"color":"#c79a67"},{"x":5,"y":21,"z":11,"color":"#c79a67"},{"x":5,"y":21,"z":12,"color":"#c79a67"},{"x":5,"y":21,"z":13,"color":"#c79a67"},{"x":5,"y":21,"z":14,"color":"#c79a67"},{"x":5,"y":21,"z":15,"color":"#b48653"},{"x":5,"y":21,"z":16,"color":"#b48653"},{"x":5,"y":21,"z":17,"color":"#b48653"},{"x":5,"y":21,"z":18,"color":"#966a3b"},{"x":5,"y":21,"z":19,"color":"#966a3b"},{"x":5,"y":21,"z":20,"color":"#966a3b"},{"x":5,"y":21,"z":21,"color":"#966a3b"},{"x":5,"y":21,"z":22,"color":"#966a3b"},{"x":5,"y":21,"z":23,"color":"#d3ab7d"},{"x":5,"y":21,"z":24,"color":"#c79a67"},{"x":5,"y":21,"z":25,"color":"#966a3b"},{"x":5,"y":22,"z":4,"color":"#c79a67"},{"x":5,"y":22,"z":5,"color":"#c79a67"},{"x":5,"y":22,"z":6,"color":"#c79a67"},{"x":5,"y":22,"z":7,"color":"#c79a67"},{"x":5,"y":22,"z":8,"color":"#c79a67"},{"x":5,"y":22,"z":9,"color":"#c79a67"},{"x":5,"y":22,"z":10,"color":"#c79a67"},{"x":5,"y":22,"z":11,"color":"#c79a67"},{"x":5,"y":22,"z":12,"color":"#c79a67"},{"x":5,"y":22,"z":13,"color":"#c79a67"},{"x":5,"y":22,"z":14,"color":"#c79a67"},{"x":5,"y":22,"z":15,"color":"#c79a67"},{"x":5,"y":22,"z":16,"color":"#c79a67"},{"x":5,"y":22,"z":17,"color":"#c79a67"},{"x":5,"y":22,"z":18,"color":"#c79a67"},{"x":5,"y":22,"z":19,"color":"#c79a67"},{"x":5,"y":22,"z":20,"color":"#c79a67"},{"x":5,"y":22,"z":21,"color":"#c79a67"},{"x":5,"y":22,"z":22,"color":"#c79a67"},{"x":5,"y":22,"z":23,"color":"#c79a67"},{"x":5,"y":22,"z":24,"color":"#c79a67"},{"x":5,"y":22,"z":25,"color":"#c79a67"},{"x":5,"y":23,"z":4,"color":"#d3ab7d"},{"x":5,"y":23,"z":5,"color":"#d3ab7d"},{"x":5,"y":23,"z":6,"color":"#d3ab7d"},{"x":5,"y":23,"z":7,"color":"#c79a67"},{"x":5,"y":23,"z":8,"color":"#d3ab7d"},{"x":5,"y":23,"z":9,"color":"#d3ab7d"},{"x":5,"y":23,"z":10,"color":"#d3ab7d"},{"x":5,"y":23,"z":11,"color":"#d3ab7d"},{"x":5,"y":23,"z":12,"color":"#d3ab7d"},{"x":5,"y":23,"z":13,"color":"#d3ab7d"},{"x":5,"y":23,"z":14,"color":"#d3ab7d"},{"x":5,"y":23,"z":15,"color":"#d3ab7d"},{"x":5,"y":23,"z":16,"color":"#d3ab7d"},{"x":5,"y":23,"z":17,"color":"#d3ab7d"},{"x":5,"y":23,"z":18,"color":"#d3ab7d"},{"x":5,"y":23,"z":19,"color":"#d3ab7d"},{"x":5,"y":23,"z":20,"color":"#d3ab7d"},{"x":5,"y":23,"z":21,"color":"#d3ab7d"},{"x":5,"y":23,"z":22,"color":"#d3ab7d"},{"x":5,"y":23,"z":23,"color":"#d3ab7d"},{"x":5,"y":23,"z":24,"color":"#d3ab7d"},{"x":5,"y":23,"z":25,"color":"#d3ab7d"},{"x":5,"y":24,"z":4,"color":"#b48653"},{"x":5,"y":24,"z":5,"color":"#c79a67"},{"x":5,"y":24,"z":6,"color":"#c79a67"},{"x":5,"y":24,"z":7,"color":"#c79a67"},{"x":5,"y":24,"z":8,"color":"#d3ab7d"},{"x":5,"y":24,"z":16,"color":"#d3ab7d"},{"x":5,"y":24,"z":17,"color":"#e2bf93"},{"x":5,"y":24,"z":18,"color":"#e2bf93"},{"x":5,"y":24,"z":19,"color":"#e2bf93"},{"x":5,"y":24,"z":20,"color":"#e2bf93"},{"x":5,"y":24,"z":21,"color":"#e2bf93"},{"x":5,"y":24,"z":22,"color":"#e2bf93"},{"x":5,"y":24,"z":23,"color":"#e2bf93"},{"x":5,"y":24,"z":24,"color":"#e2bf93"},{"x":5,"y":24,"z":25,"color":"#c79a67"},{"x":5,"y":34,"z":2,"color":"#e2bf93"},{"x":5,"y":34,"z":3,"color":"#d3ab7d"},{"x":5,"y":34,"z":4,"color":"#d3ab7d"},{"x":5,"y":34,"z":5,"color":"#d3ab7d"},{"x":5,"y":34,"z":6,"color":"#e2bf93"},{"x":5,"y":35,"z":2,"color":"#d3ab7d"},{"x":5,"y":35,"z":3,"color":"#d3ab7d"},{"x":5,"y":35,"z":4,"color":"#d3ab7d"},{"x":5,"y":35,"z":5,"color":"#d3ab7d"},{"x":5,"y":35,"z":6,"color":"#d3ab7d"},{"x":5,"y":36,"z":1,"color":"#d3ab7d"},{"x":5,"y":36,"z":2,"color":"#c79a67"},{"x":5,"y":36,"z":3,"color":"#d3ab7d"},{"x":5,"y":36,"z":4,"color":"#d3ab7d"},{"x":5,"y":36,"z":5,"color":"#d3ab7d"},{"x":5,"y":37,"z":1,"color":"#e2bf93"},{"x":5,"y":37,"z":2,"color":"#c79a67"},{"x":5,"y":37,"z":3,"color":"#d3ab7d"},{"x":5,"y":37,"z":4,"color":"#e2bf93"},{"x":5,"y":37,"z":5,"color":"#e2bf93"},{"x":5,"y":38,"z":1,"color":"#d3ab7d"},{"x":5,"y":38,"z":2,"color":"#c79a67"},{"x":5,"y":38,"z":3,"color":"#d3ab7d"},{"x":5,"y":38,"z":4,"color":"#d3ab7d"},{"x":5,"y":38,"z":5,"color":"#d3ab7d"},{"x":5,"y":39,"z":1,"color":"#d3ab7d"},{"x":5,"y":39,"z":2,"color":"#c79a67"},{"x":5,"y":39,"z":3,"color":"#d3ab7d"},{"x":5,"y":39,"z":4,"color":"#e2bf93"},{"x":5,"y":39,"z":5,"color":"#d3ab7d"},{"x":5,"y":40,"z":1,"color":"#d3ab7d"},{"x":5,"y":40,"z":2,"color":"#c79a67"},{"x":5,"y":40,"z":3,"color":"#d3ab7d"},{"x":5,"y":40,"z":4,"color":"#e2bf93"},{"x":5,"y":40,"z":5,"color":"#e2bf93"},{"x":5,"y":41,"z":1,"color":"#d3ab7d"},{"x":5,"y":41,"z":2,"color":"#d3ab7d"},{"x":5,"y":41,"z":3,"color":"#d3ab7d"},{"x":5,"y":41,"z":4,"color":"#d3ab7d"},{"x":5,"y":42,"z":1,"color":"#d3ab7d"},{"x":5,"y":42,"z":2,"color":"#d3ab7d"},{"x":5,"y":42,"z":3,"color":"#d3ab7d"},{"x":5,"y":42,"z":4,"color":"#d3ab7d"},{"x":6,"y":19,"z":4,"color":"#d3ab7d"},{"x":6,"y":19,"z":5,"color":"#c79a67"},{"x":6,"y":19,"z":6,"color":"#b48653"},{"x":6,"y":19,"z":7,"color":"#e2bf93"},{"x":6,"y":19,"z":8,"color":"#b48653"},{"x":6,"y":19,"z":9,"color":"#c79a67"},{"x":6,"y":19,"z":10,"color":"#c79a67"},{"x":6,"y":19,"z":11,"color":"#c79a67"},{"x":6,"y":19,"z":12,"color":"#c79a67"},{"x":6,"y":19,"z":13,"color":"#d3ab7d"},{"x":6,"y":19,"z":20,"color":"#c79a67"},{"x":6,"y":19,"z":21,"color":"#c79a67"},{"x":6,"y":19,"z":22,"color":"#d3ab7d"},{"x":6,"y":19,"z":23,"color":"#d3ab7d"},{"x":6,"y":20,"z":4,"color":"#c79a67"},{"x":6,"y":20,"z":5,"color":"#c79a67"},{"x":6,"y":20,"z":6,"color":"#c79a67"},{"x":6,"y":20,"z":7,"color":"#c79a67"},{"x":6,"y":20,"z":8,"color":"#c79a67"},{"x":6,"y":20,"z":9,"color":"#c79a67"},{"x":6,"y":20,"z":10,"color":"#c79a67"},{"x":6,"y":20,"z":11,"color":"#b48653"},{"x":6,"y":20,"z":12,"color":"#e2bf93"},{"x":6,"y":20,"z":13,"color":"#c79a67"},{"x":6,"y":20,"z":14,"color":"#c79a67"},{"x":6,"y":20,"z":15,"color":"#c79a67"},{"x":6,"y":20,"z":16,"color":"#c79a67"},{"x":6,"y":20,"z":17,"color":"#c79a67"},{"x":6,"y":20,"z":18,"color":"#c79a67"},{"x":6,"y":20,"z":19,"color":"#d3ab7d"},{"x":6,"y":20,"z":20,"color":"#c79a67"},{"x":6,"y":20,"z":21,"color":"#c79a67"},{"x":6,"y":20,"z":22,"color":"#c79a67"},{"x":6,"y":20,"z":23,"color":"#c79a67"},{"x":6,"y":20,"z":24,"color":"#b48653"},{"x":6,"y":20,"z":25,"color":"#c79a67"},{"x":6,"y":21,"z":4,"color":"#b48653"},{"x":6,"y":21,"z":5,"color":"#c79a67"},{"x":6,"y":21,"z":6,"color":"#c79a67"},{"x":6,"y":21,"z":7,"color":"#966a3b"},{"x":6,"y":21,"z":8,"color":"#b48653"},{"x":6,"y":21,"z":9,"color":"#b48653"},{"x":6,"y":21,"z":10,"color":"#c79a67"},{"x":6,"y":21,"z":11,"color":"#c79a67"},{"x":6,"y":21,"z":12,"color":"#c79a67"},{"x":6,"y":21,"z":13,"color":"#c79a67"},{"x":6,"y":21,"z":14,"color":"#c79a67"},{"x":6,"y":21,"z":15,"color":"#b48653"},{"x":6,"y":21,"z":16,"color":"#b48653"},{"x":6,"y":21,"z":17,"color":"#b48653"},{"x":6,"y":21,"z":18,"color":"#966a3b"},{"x":6,"y":21,"z":19,"color":"#966a3b"},{"x":6,"y":21,"z":20,"color":"#966a3b"},{"x":6,"y":21,"z":21,"color":"#966a3b"},{"x":6,"y":21,"z":22,"color":"#966a3b"},{"x":6,"y":21,"z":23,"color":"#c79a67"},{"x":6,"y":21,"z":24,"color":"#966a3b"},{"x":6,"y":21,"z":25,"color":"#b48653"},{"x":6,"y":22,"z":4,"color":"#d3ab7d"},{"x":6,"y":22,"z":5,"color":"#d3ab7d"},{"x":6,"y":22,"z":6,"color":"#d3ab7d"},{"x":6,"y":22,"z":7,"color":"#c79a67"},{"x":6,"y":22,"z":8,"color":"#b48653"},{"x":6,"y":22,"z":9,"color":"#c79a67"},{"x":6,"y":22,"z":10,"color":"#c79a67"},{"x":6,"y":22,"z":11,"color":"#c79a67"},{"x":6,"y":22,"z":12,"color":"#c79a67"},{"x":6,"y":22,"z":13,"color":"#d3ab7d"},{"x":6,"y":22,"z":14,"color":"#c79a67"},{"x":6,"y":22,"z":15,"color":"#c79a67"},{"x":6,"y":22,"z":16,"color":"#d3ab7d"},{"x":6,"y":22,"z":17,"color":"#d3ab7d"},{"x":6,"y":22,"z":18,"color":"#d3ab7d"},{"x":6,"y":22,"z":19,"color":"#d3ab7d"},{"x":6,"y":22,"z":20,"color":"#d3ab7d"},{"x":6,"y":22,"z":21,"color":"#c79a67"},{"x":6,"y":22,"z":22,"color":"#d3ab7d"},{"x":6,"y":22,"z":23,"color":"#c79a67"},{"x":6,"y":22,"z":24,"color":"#b48653"},{"x":6,"y":22,"z":25,"color":"#d3ab7d"},{"x":6,"y":23,"z":4,"color":"#d3ab7d"},{"x":6,"y":23,"z":5,"color":"#d3ab7d"},{"x":6,"y":23,"z":6,"color":"#d3ab7d"},{"x":6,"y":23,"z":7,"color":"#c79a67"},{"x":6,"y":23,"z":8,"color":"#d3ab7d"},{"x":6,"y":23,"z":9,"color":"#d3ab7d"},{"x":6,"y":23,"z":10,"color":"#d3ab7d"},{"x":6,"y":23,"z":11,"color":"#d3ab7d"},{"x":6,"y":23,"z":12,"color":"#d3ab7d"},{"x":6,"y":23,"z":13,"color":"#d3ab7d"},{"x":6,"y":23,"z":14,"color":"#d3ab7d"},{"x":6,"y":23,"z":15,"color":"#d3ab7d"},{"x":6,"y":23,"z":16,"color":"#d3ab7d"},{"x":6,"y":23,"z":17,"color":"#d3ab7d"},{"x":6,"y":23,"z":18,"color":"#d3ab7d"},{"x":6,"y":23,"z":19,"color":"#d3ab7d"},{"x":6,"y":23,"z":20,"color":"#d3ab7d"},{"x":6,"y":23,"z":21,"color":"#d3ab7d"},{"x":6,"y":23,"z":22,"color":"#d3ab7d"},{"x":6,"y":23,"z":23,"color":"#d3ab7d"},{"x":6,"y":23,"z":24,"color":"#d3ab7d"},{"x":6,"y":23,"z":25,"color":"#d3ab7d"},{"x":6,"y":34,"z":2,"color":"#e2bf93"},{"x":6,"y":34,"z":3,"color":"#d3ab7d"},{"x":6,"y":34,"z":4,"color":"#d3ab7d"},{"x":6,"y":34,"z":5,"color":"#d3ab7d"},{"x":6,"y":34,"z":6,"color":"#e2bf93"},{"x":6,"y":35,"z":2,"color":"#d3ab7d"},{"x":6,"y":35,"z":3,"color":"#d3ab7d"},{"x":6,"y":35,"z":4,"color":"#d3ab7d"},{"x":6,"y":35,"z":5,"color":"#d3ab7d"},{"x":6,"y":35,"z":6,"color":"#d3ab7d"},{"x":6,"y":36,"z":1,"color":"#d3ab7d"},{"x":6,"y":36,"z":2,"color":"#c79a67"},{"x":6,"y":36,"z":3,"color":"#c79a67"},{"x":6,"y":36,"z":4,"color":"#d3ab7d"},{"x":6,"y":36,"z":5,"color":"#d3ab7d"},{"x":6,"y":37,"z":1,"color":"#e2bf93"},{"x":6,"y":37,"z":2,"color":"#c79a67"},{"x":6,"y":37,"z":3,"color":"#d3ab7d"},{"x":6,"y":37,"z":4,"color":"#e2bf93"},{"x":6,"y":37,"z":5,"color":"#e2bf93"},{"x":6,"y":38,"z":1,"color":"#d3ab7d"},{"x":6,"y":38,"z":2,"color":"#b48653"},{"x":6,"y":38,"z":3,"color":"#d3ab7d"},{"x":6,"y":38,"z":4,"color":"#d3ab7d"},{"x":6,"y":38,"z":5,"color":"#d3ab7d"},{"x":6,"y":39,"z":1,"color":"#d3ab7d"},{"x":6,"y":39,"z":2,"color":"#b48653"},{"x":6,"y":39,"z":3,"color":"#d3ab7d"},{"x":6,"y":39,"z":4,"color":"#e2bf93"},{"x":6,"y":39,"z":5,"color":"#d3ab7d"},{"x":6,"y":40,"z":1,"color":"#c79a67"},{"x":6,"y":40,"z":2,"color":"#c79a67"},{"x":6,"y":40,"z":3,"color":"#c79a67"},{"x":6,"y":40,"z":4,"color":"#d3ab7d"},{"x":6,"y":40,"z":5,"color":"#c79a67"},{"x":6,"y":41,"z":0,"color":"#d3ab7d"},{"x":6,"y":41,"z":1,"color":"#d3ab7d"},{"x":6,"y":41,"z":2,"color":"#d3ab7d"},{"x":6,"y":41,"z":3,"color":"#d3ab7d"},{"x":6,"y":41,"z":4,"color":"#d3ab7d"},{"x":6,"y":42,"z":0,"color":"#d3ab7d"},{"x":6,"y":42,"z":1,"color":"#d3ab7d"},{"x":6,"y":42,"z":2,"color":"#d3ab7d"},{"x":6,"y":42,"z":3,"color":"#d3ab7d"},{"x":6,"y":42,"z":4,"color":"#d3ab7d"},{"x":7,"y":19,"z":4,"color":"#d3ab7d"},{"x":7,"y":19,"z":5,"color":"#c79a67"},{"x":7,"y":19,"z":6,"color":"#c79a67"},{"x":7,"y":19,"z":7,"color":"#e2bf93"},{"x":7,"y":19,"z":8,"color":"#d3ab7d"},{"x":7,"y":19,"z":9,"color":"#d3ab7d"},{"x":7,"y":19,"z":10,"color":"#c79a67"},{"x":7,"y":19,"z":11,"color":"#c79a67"},{"x":7,"y":19,"z":12,"color":"#c79a67"},{"x":7,"y":19,"z":13,"color":"#c79a67"},{"x":7,"y":19,"z":20,"color":"#c79a67"},{"x":7,"y":19,"z":21,"color":"#c79a67"},{"x":7,"y":19,"z":22,"color":"#d3ab7d"},{"x":7,"y":19,"z":23,"color":"#d3ab7d"},{"x":7,"y":20,"z":4,"color":"#c79a67"},{"x":7,"y":20,"z":5,"color":"#c79a67"},{"x":7,"y":20,"z":6,"color":"#c79a67"},{"x":7,"y":20,"z":7,"color":"#c79a67"},{"x":7,"y":20,"z":8,"color":"#d3ab7d"},{"x":7,"y":20,"z":9,"color":"#c79a67"},{"x":7,"y":20,"z":10,"color":"#c79a67"},{"x":7,"y":20,"z":11,"color":"#b48653"},{"x":7,"y":20,"z":12,"color":"#e2bf93"},{"x":7,"y":20,"z":13,"color":"#c79a67"},{"x":7,"y":20,"z":14,"color":"#c79a67"},{"x":7,"y":20,"z":15,"color":"#c79a67"},{"x":7,"y":20,"z":16,"color":"#c79a67"},{"x":7,"y":20,"z":17,"color":"#c79a67"},{"x":7,"y":20,"z":18,"color":"#c79a67"},{"x":7,"y":20,"z":19,"color":"#c79a67"},{"x":7,"y":20,"z":20,"color":"#c79a67"},{"x":7,"y":20,"z":21,"color":"#c79a67"},{"x":7,"y":20,"z":22,"color":"#c79a67"},{"x":7,"y":20,"z":23,"color":"#c79a67"},{"x":7,"y":20,"z":24,"color":"#b48653"},{"x":7,"y":20,"z":25,"color":"#c79a67"},{"x":7,"y":21,"z":4,"color":"#b48653"},{"x":7,"y":21,"z":5,"color":"#c79a67"},{"x":7,"y":21,"z":6,"color":"#c79a67"},{"x":7,"y":21,"z":7,"color":"#966a3b"},{"x":7,"y":21,"z":8,"color":"#b48653"},{"x":7,"y":21,"z":9,"color":"#b48653"},{"x":7,"y":21,"z":10,"color":"#c79a67"},{"x":7,"y":21,"z":11,"color":"#c79a67"},{"x":7,"y":21,"z":12,"color":"#c79a67"},{"x":7,"y":21,"z":13,"color":"#c79a67"},{"x":7,"y":21,"z":14,"color":"#c79a67"},{"x":7,"y":21,"z":15,"color":"#b48653"},{"x":7,"y":21,"z":16,"color":"#b48653"},{"x":7,"y":21,"z":17,"color":"#b48653"},{"x":7,"y":21,"z":18,"color":"#966a3b"},{"x":7,"y":21,"z":19,"color":"#966a3b"},{"x":7,"y":21,"z":20,"color":"#966a3b"},{"x":7,"y":21,"z":21,"color":"#966a3b"},{"x":7,"y":21,"z":22,"color":"#966a3b"},{"x":7,"y":21,"z":23,"color":"#c79a67"},{"x":7,"y":21,"z":24,"color":"#b48653"},{"x":7,"y":21,"z":25,"color":"#b48653"},{"x":7,"y":22,"z":4,"color":"#d3ab7d"},{"x":7,"y":22,"z":5,"color":"#d3ab7d"},{"x":7,"y":22,"z":6,"color":"#c79a67"},{"x":7,"y":22,"z":7,"color":"#c79a67"},{"x":7,"y":22,"z":8,"color":"#c79a67"},{"x":7,"y":22,"z":9,"color":"#d3ab7d"},{"x":7,"y":22,"z":10,"color":"#c79a67"},{"x":7,"y":22,"z":11,"color":"#c79a67"},{"x":7,"y":22,"z":12,"color":"#c79a67"},{"x":7,"y":22,"z":13,"color":"#c79a67"},{"x":7,"y":22,"z":14,"color":"#c79a67"},{"x":7,"y":22,"z":15,"color":"#c79a67"},{"x":7,"y":22,"z":16,"color":"#d3ab7d"},{"x":7,"y":22,"z":17,"color":"#d3ab7d"},{"x":7,"y":22,"z":18,"color":"#c79a67"},{"x":7,"y":22,"z":19,"color":"#c79a67"},{"x":7,"y":22,"z":20,"color":"#c79a67"},{"x":7,"y":22,"z":21,"color":"#c79a67"},{"x":7,"y":22,"z":22,"color":"#d3ab7d"},{"x":7,"y":22,"z":23,"color":"#c79a67"},{"x":7,"y":22,"z":24,"color":"#b48653"},{"x":7,"y":22,"z":25,"color":"#d3ab7d"},{"x":7,"y":23,"z":4,"color":"#d3ab7d"},{"x":7,"y":23,"z":5,"color":"#d3ab7d"},{"x":7,"y":23,"z":6,"color":"#d3ab7d"},{"x":7,"y":23,"z":7,"color":"#c79a67"},{"x":7,"y":23,"z":8,"color":"#d3ab7d"},{"x":7,"y":23,"z":9,"color":"#d3ab7d"},{"x":7,"y":23,"z":10,"color":"#d3ab7d"},{"x":7,"y":23,"z":11,"color":"#d3ab7d"},{"x":7,"y":23,"z":12,"color":"#d3ab7d"},{"x":7,"y":23,"z":13,"color":"#d3ab7d"},{"x":7,"y":23,"z":14,"color":"#d3ab7d"},{"x":7,"y":23,"z":15,"color":"#d3ab7d"},{"x":7,"y":23,"z":16,"color":"#d3ab7d"},{"x":7,"y":23,"z":17,"color":"#d3ab7d"},{"x":7,"y":23,"z":18,"color":"#d3ab7d"},{"x":7,"y":23,"z":19,"color":"#d3ab7d"},{"x":7,"y":23,"z":20,"color":"#d3ab7d"},{"x":7,"y":23,"z":21,"color":"#d3ab7d"},{"x":7,"y":23,"z":22,"color":"#d3ab7d"},{"x":7,"y":23,"z":23,"color":"#d3ab7d"},{"x":7,"y":23,"z":24,"color":"#d3ab7d"},{"x":7,"y":23,"z":25,"color":"#d3ab7d"},{"x":7,"y":34,"z":2,"color":"#d3ab7d"},{"x":7,"y":34,"z":3,"color":"#d3ab7d"},{"x":7,"y":34,"z":4,"color":"#d3ab7d"},{"x":7,"y":34,"z":5,"color":"#d3ab7d"},{"x":7,"y":34,"z":6,"color":"#d3ab7d"},{"x":7,"y":35,"z":2,"color":"#c79a67"},{"x":7,"y":35,"z":3,"color":"#c79a67"},{"x":7,"y":35,"z":4,"color":"#d3ab7d"},{"x":7,"y":35,"z":5,"color":"#c79a67"},{"x":7,"y":35,"z":6,"color":"#c79a67"},{"x":7,"y":36,"z":1,"color":"#d3ab7d"},{"x":7,"y":36,"z":2,"color":"#c79a67"},{"x":7,"y":36,"z":3,"color":"#d3ab7d"},{"x":7,"y":36,"z":4,"color":"#d3ab7d"},{"x":7,"y":36,"z":5,"color":"#d3ab7d"},{"x":7,"y":37,"z":1,"color":"#c79a67"},{"x":7,"y":37,"z":2,"color":"#c79a67"},{"x":7,"y":37,"z":3,"color":"#c79a67"},{"x":7,"y":37,"z":4,"color":"#e2bf93"},{"x":7,"y":37,"z":5,"color":"#c79a67"},{"x":7,"y":38,"z":1,"color":"#d3ab7d"},{"x":7,"y":38,"z":2,"color":"#b48653"},{"x":7,"y":38,"z":3,"color":"#d3ab7d"},{"x":7,"y":38,"z":4,"color":"#d3ab7d"},{"x":7,"y":38,"z":5,"color":"#d3ab7d"},{"x":7,"y":39,"z":1,"color":"#d3ab7d"},{"x":7,"y":39,"z":2,"color":"#b48653"},{"x":7,"y":39,"z":3,"color":"#d3ab7d"},{"x":7,"y":39,"z":4,"color":"#d3ab7d"},{"x":7,"y":39,"z":5,"color":"#d3ab7d"},{"x":7,"y":40,"z":1,"color":"#c79a67"},{"x":7,"y":40,"z":2,"color":"#c79a67"},{"x":7,"y":40,"z":3,"color":"#c79a67"},{"x":7,"y":40,"z":4,"color":"#c79a67"},{"x":7,"y":40,"z":5,"color":"#c79a67"},{"x":7,"y":41,"z":0,"color":"#d3ab7d"},{"x":7,"y":41,"z":1,"color":"#c79a67"},{"x":7,"y":41,"z":2,"color":"#c79a67"},{"x":7,"y":41,"z":3,"color":"#c79a67"},{"x":7,"y":41,"z":4,"color":"#e2bf93"},{"x":7,"y":42,"z":0,"color":"#d3ab7d"},{"x":7,"y":42,"z":1,"color":"#c79a67"},{"x":7,"y":42,"z":2,"color":"#e2bf93"},{"x":7,"y":42,"z":3,"color":"#d3ab7d"},{"x":7,"y":42,"z":4,"color":"#d3ab7d"},{"x":8,"y":19,"z":4,"color":"#d3ab7d"},{"x":8,"y":19,"z":5,"color":"#c79a67"},{"x":8,"y":19,"z":6,"color":"#b48653"},{"x":8,"y":19,"z":7,"color":"#e2bf93"},{"x":8,"y":19,"z":8,"color":"#b48653"},{"x":8,"y":19,"z":9,"color":"#c79a67"},{"x":8,"y":19,"z":10,"color":"#c79a67"},{"x":8,"y":19,"z":11,"color":"#c79a67"},{"x":8,"y":19,"z":12,"color":"#d3ab7d"},{"x":8,"y":19,"z":13,"color":"#d3ab7d"},{"x":8,"y":19,"z":20,"color":"#c79a67"},{"x":8,"y":19,"z":21,"color":"#d3ab7d"},{"x":8,"y":19,"z":22,"color":"#d3ab7d"},{"x":8,"y":19,"z":23,"color":"#d3ab7d"},{"x":8,"y":20,"z":4,"color":"#c79a67"},{"x":8,"y":20,"z":5,"color":"#c79a67"},{"x":8,"y":20,"z":6,"color":"#c79a67"},{"x":8,"y":20,"z":7,"color":"#c79a67"},{"x":8,"y":20,"z":8,"color":"#c79a67"},{"x":8,"y":20,"z":9,"color":"#c79a67"},{"x":8,"y":20,"z":10,"color":"#c79a67"},{"x":8,"y":20,"z":11,"color":"#b48653"},{"x":8,"y":20,"z":12,"color":"#e2bf93"},{"x":8,"y":20,"z":13,"color":"#c79a67"},{"x":8,"y":20,"z":14,"color":"#c79a67"},{"x":8,"y":20,"z":15,"color":"#c79a67"},{"x":8,"y":20,"z":16,"color":"#c79a67"},{"x":8,"y":20,"z":17,"color":"#c79a67"},{"x":8,"y":20,"z":18,"color":"#c79a67"},{"x":8,"y":20,"z":19,"color":"#c79a67"},{"x":8,"y":20,"z":20,"color":"#d3ab7d"},{"x":8,"y":20,"z":21,"color":"#c79a67"},{"x":8,"y":20,"z":22,"color":"#c79a67"},{"x":8,"y":20,"z":23,"color":"#c79a67"},{"x":8,"y":20,"z":24,"color":"#b48653"},{"x":8,"y":20,"z":25,"color":"#c79a67"},{"x":8,"y":21,"z":4,"color":"#966a3b"},{"x":8,"y":21,"z":5,"color":"#c79a67"},{"x":8,"y":21,"z":6,"color":"#b48653"},{"x":8,"y":21,"z":7,"color":"#966a3b"},{"x":8,"y":21,"z":8,"color":"#b48653"},{"x":8,"y":21,"z":9,"color":"#b48653"},{"x":8,"y":21,"z":10,"color":"#b48653"},{"x":8,"y":21,"z":11,"color":"#b48653"},{"x":8,"y":21,"z":12,"color":"#b48653"},{"x":8,"y":21,"z":13,"color":"#c79a67"},{"x":8,"y":21,"z":14,"color":"#c79a67"},{"x":8,"y":21,"z":15,"color":"#b48653"},{"x":8,"y":21,"z":16,"color":"#b48653"},{"x":8,"y":21,"z":17,"color":"#b48653"},{"x":8,"y":21,"z":18,"color":"#966a3b"},{"x":8,"y":21,"z":19,"color":"#966a3b"},{"x":8,"y":21,"z":20,"color":"#966a3b"},{"x":8,"y":21,"z":21,"color":"#966a3b"},{"x":8,"y":21,"z":22,"color":"#966a3b"},{"x":8,"y":21,"z":23,"color":"#c79a67"},{"x":8,"y":21,"z":24,"color":"#b48653"},{"x":8,"y":21,"z":25,"color":"#966a3b"},{"x":8,"y":22,"z":4,"color":"#d3ab7d"},{"x":8,"y":22,"z":5,"color":"#d3ab7d"},{"x":8,"y":22,"z":6,"color":"#d3ab7d"},{"x":8,"y":22,"z":7,"color":"#c79a67"},{"x":8,"y":22,"z":8,"color":"#b48653"},{"x":8,"y":22,"z":9,"color":"#c79a67"},{"x":8,"y":22,"z":10,"color":"#c79a67"},{"x":8,"y":22,"z":11,"color":"#c79a67"},{"x":8,"y":22,"z":12,"color":"#d3ab7d"},{"x":8,"y":22,"z":13,"color":"#d3ab7d"},{"x":8,"y":22,"z":14,"color":"#c79a67"},{"x":8,"y":22,"z":15,"color":"#c79a67"},{"x":8,"y":22,"z":16,"color":"#c79a67"},{"x":8,"y":22,"z":17,"color":"#d3ab7d"},{"x":8,"y":22,"z":18,"color":"#c79a67"},{"x":8,"y":22,"z":19,"color":"#d3ab7d"},{"x":8,"y":22,"z":20,"color":"#d3ab7d"},{"x":8,"y":22,"z":21,"color":"#d3ab7d"},{"x":8,"y":22,"z":22,"color":"#d3ab7d"},{"x":8,"y":22,"z":23,"color":"#d3ab7d"},{"x":8,"y":22,"z":24,"color":"#b48653"},{"x":8,"y":22,"z":25,"color":"#d3ab7d"},{"x":8,"y":23,"z":4,"color":"#d3ab7d"},{"x":8,"y":23,"z":5,"color":"#d3ab7d"},{"x":8,"y":23,"z":6,"color":"#d3ab7d"},{"x":8,"y":23,"z":7,"color":"#c79a67"},{"x":8,"y":23,"z":8,"color":"#d3ab7d"},{"x":8,"y":23,"z":9,"color":"#d3ab7d"},{"x":8,"y":23,"z":10,"color":"#d3ab7d"},{"x":8,"y":23,"z":11,"color":"#d3ab7d"},{"x":8,"y":23,"z":12,"color":"#d3ab7d"},{"x":8,"y":23,"z":13,"color":"#d3ab7d"},{"x":8,"y":23,"z":14,"color":"#d3ab7d"},{"x":8,"y":23,"z":15,"color":"#d3ab7d"},{"x":8,"y":23,"z":16,"color":"#d3ab7d"},{"x":8,"y":23,"z":17,"color":"#d3ab7d"},{"x":8,"y":23,"z":18,"color":"#d3ab7d"},{"x":8,"y":23,"z":19,"color":"#d3ab7d"},{"x":8,"y":23,"z":20,"color":"#d3ab7d"},{"x":8,"y":23,"z":21,"color":"#d3ab7d"},{"x":8,"y":23,"z":22,"color":"#d3ab7d"},{"x":8,"y":23,"z":23,"color":"#d3ab7d"},{"x":8,"y":23,"z":24,"color":"#d3ab7d"},{"x":8,"y":23,"z":25,"color":"#d3ab7d"},{"x":8,"y":34,"z":2,"color":"#c79a67"},{"x":8,"y":34,"z":3,"color":"#d3ab7d"},{"x":8,"y":34,"z":4,"color":"#d3ab7d"},{"x":8,"y":34,"z":5,"color":"#d3ab7d"},{"x":8,"y":34,"z":6,"color":"#c79a67"},{"x":8,"y":35,"z":2,"color":"#c79a67"},{"x":8,"y":35,"z":3,"color":"#c79a67"},{"x":8,"y":35,"z":4,"color":"#d3ab7d"},{"x":8,"y":35,"z":5,"color":"#c79a67"},{"x":8,"y":35,"z":6,"color":"#c79a67"},{"x":8,"y":36,"z":1,"color":"#d3ab7d"},{"x":8,"y":36,"z":2,"color":"#c79a67"},{"x":8,"y":36,"z":3,"color":"#d3ab7d"},{"x":8,"y":36,"z":4,"color":"#d3ab7d"},{"x":8,"y":36,"z":5,"color":"#d3ab7d"},{"x":8,"y":37,"z":1,"color":"#c79a67"},{"x":8,"y":37,"z":2,"color":"#c79a67"},{"x":8,"y":37,"z":3,"color":"#c79a67"},{"x":8,"y":37,"z":4,"color":"#e2bf93"},{"x":8,"y":37,"z":5,"color":"#c79a67"},{"x":8,"y":38,"z":1,"color":"#c79a67"},{"x":8,"y":38,"z":2,"color":"#b48653"},{"x":8,"y":38,"z":3,"color":"#c79a67"},{"x":8,"y":38,"z":4,"color":"#d3ab7d"},{"x":8,"y":38,"z":5,"color":"#c79a67"},{"x":8,"y":39,"z":1,"color":"#c79a67"},{"x":8,"y":39,"z":2,"color":"#b48653"},{"x":8,"y":39,"z":3,"color":"#c79a67"},{"x":8,"y":39,"z":4,"color":"#d3ab7d"},{"x":8,"y":39,"z":5,"color":"#c79a67"},{"x":8,"y":40,"z":1,"color":"#c79a67"},{"x":8,"y":40,"z":2,"color":"#c79a67"},{"x":8,"y":40,"z":3,"color":"#d3ab7d"},{"x":8,"y":40,"z":4,"color":"#d3ab7d"},{"x":8,"y":40,"z":5,"color":"#d3ab7d"},{"x":8,"y":41,"z":0,"color":"#d3ab7d"},{"x":8,"y":41,"z":1,"color":"#c79a67"},{"x":8,"y":41,"z":2,"color":"#d3ab7d"},{"x":8,"y":41,"z":3,"color":"#d3ab7d"},{"x":8,"y":41,"z":4,"color":"#d3ab7d"},{"x":8,"y":42,"z":0,"color":"#d3ab7d"},{"x":8,"y":42,"z":1,"color":"#c79a67"},{"x":8,"y":42,"z":2,"color":"#d3ab7d"},{"x":8,"y":42,"z":3,"color":"#d3ab7d"},{"x":8,"y":42,"z":4,"color":"#d3ab7d"},{"x":9,"y":19,"z":4,"color":"#d3ab7d"},{"x":9,"y":19,"z":5,"color":"#c79a67"},{"x":9,"y":19,"z":6,"color":"#b48653"},{"x":9,"y":19,"z":7,"color":"#e2bf93"},{"x":9,"y":19,"z":8,"color":"#c79a67"},{"x":9,"y":19,"z":9,"color":"#c79a67"},{"x":9,"y":19,"z":10,"color":"#c79a67"},{"x":9,"y":19,"z":11,"color":"#c79a67"},{"x":9,"y":19,"z":12,"color":"#c79a67"},{"x":9,"y":19,"z":13,"color":"#c79a67"},{"x":9,"y":19,"z":20,"color":"#c79a67"},{"x":9,"y":19,"z":21,"color":"#d3ab7d"},{"x":9,"y":19,"z":22,"color":"#d3ab7d"},{"x":9,"y":19,"z":23,"color":"#d3ab7d"},{"x":9,"y":20,"z":4,"color":"#c79a67"},{"x":9,"y":20,"z":5,"color":"#c79a67"},{"x":9,"y":20,"z":6,"color":"#c79a67"},{"x":9,"y":20,"z":7,"color":"#c79a67"},{"x":9,"y":20,"z":8,"color":"#c79a67"},{"x":9,"y":20,"z":9,"color":"#c79a67"},{"x":9,"y":20,"z":10,"color":"#c79a67"},{"x":9,"y":20,"z":11,"color":"#b48653"},{"x":9,"y":20,"z":12,"color":"#e2bf93"},{"x":9,"y":20,"z":13,"color":"#c79a67"},{"x":9,"y":20,"z":14,"color":"#c79a67"},{"x":9,"y":20,"z":15,"color":"#c79a67"},{"x":9,"y":20,"z":16,"color":"#c79a67"},{"x":9,"y":20,"z":17,"color":"#c79a67"},{"x":9,"y":20,"z":18,"color":"#c79a67"},{"x":9,"y":20,"z":19,"color":"#c79a67"},{"x":9,"y":20,"z":20,"color":"#c79a67"},{"x":9,"y":20,"z":21,"color":"#c79a67"},{"x":9,"y":20,"z":22,"color":"#c79a67"},{"x":9,"y":20,"z":23,"color":"#c79a67"},{"x":9,"y":20,"z":24,"color":"#c79a67"},{"x":9,"y":20,"z":25,"color":"#c79a67"},{"x":9,"y":21,"z":4,"color":"#966a3b"},{"x":9,"y":21,"z":5,"color":"#c79a67"},{"x":9,"y":21,"z":6,"color":"#b48653"},{"x":9,"y":21,"z":7,"color":"#966a3b"},{"x":9,"y":21,"z":8,"color":"#b48653"},{"x":9,"y":21,"z":9,"color":"#b48653"},{"x":9,"y":21,"z":10,"color":"#b48653"},{"x":9,"y":21,"z":11,"color":"#b48653"},{"x":9,"y":21,"z":12,"color":"#b48653"},{"x":9,"y":21,"z":13,"color":"#c79a67"},{"x":9,"y":21,"z":14,"color":"#c79a67"},{"x":9,"y":21,"z":15,"color":"#b48653"},{"x":9,"y":21,"z":16,"color":"#b48653"},{"x":9,"y":21,"z":17,"color":"#b48653"},{"x":9,"y":21,"z":18,"color":"#966a3b"},{"x":9,"y":21,"z":19,"color":"#966a3b"},{"x":9,"y":21,"z":20,"color":"#966a3b"},{"x":9,"y":21,"z":21,"color":"#966a3b"},{"x":9,"y":21,"z":22,"color":"#966a3b"},{"x":9,"y":21,"z":23,"color":"#d3ab7d"},{"x":9,"y":21,"z":24,"color":"#b48653"},{"x":9,"y":21,"z":25,"color":"#966a3b"},{"x":9,"y":22,"z":4,"color":"#d3ab7d"},{"x":9,"y":22,"z":5,"color":"#d3ab7d"},{"x":9,"y":22,"z":6,"color":"#d3ab7d"},{"x":9,"y":22,"z":7,"color":"#c79a67"},{"x":9,"y":22,"z":8,"color":"#c79a67"},{"x":9,"y":22,"z":9,"color":"#c79a67"},{"x":9,"y":22,"z":10,"color":"#c79a67"},{"x":9,"y":22,"z":11,"color":"#c79a67"},{"x":9,"y":22,"z":12,"color":"#c79a67"},{"x":9,"y":22,"z":13,"color":"#c79a67"},{"x":9,"y":22,"z":14,"color":"#c79a67"},{"x":9,"y":22,"z":15,"color":"#c79a67"},{"x":9,"y":22,"z":16,"color":"#c79a67"},{"x":9,"y":22,"z":17,"color":"#c79a67"},{"x":9,"y":22,"z":18,"color":"#c79a67"},{"x":9,"y":22,"z":19,"color":"#c79a67"},{"x":9,"y":22,"z":20,"color":"#d3ab7d"},{"x":9,"y":22,"z":21,"color":"#d3ab7d"},{"x":9,"y":22,"z":22,"color":"#d3ab7d"},{"x":9,"y":22,"z":23,"color":"#d3ab7d"},{"x":9,"y":22,"z":24,"color":"#c79a67"},{"x":9,"y":22,"z":25,"color":"#d3ab7d"},{"x":9,"y":23,"z":4,"color":"#d3ab7d"},{"x":9,"y":23,"z":5,"color":"#d3ab7d"},{"x":9,"y":23,"z":6,"color":"#d3ab7d"},{"x":9,"y":23,"z":7,"color":"#c79a67"},{"x":9,"y":23,"z":8,"color":"#d3ab7d"},{"x":9,"y":23,"z":9,"color":"#d3ab7d"},{"x":9,"y":23,"z":10,"color":"#d3ab7d"},{"x":9,"y":23,"z":11,"color":"#d3ab7d"},{"x":9,"y":23,"z":12,"color":"#d3ab7d"},{"x":9,"y":23,"z":13,"color":"#d3ab7d"},{"x":9,"y":23,"z":14,"color":"#d3ab7d"},{"x":9,"y":23,"z":15,"color":"#d3ab7d"},{"x":9,"y":23,"z":16,"color":"#d3ab7d"},{"x":9,"y":23,"z":17,"color":"#d3ab7d"},{"x":9,"y":23,"z":18,"color":"#d3ab7d"},{"x":9,"y":23,"z":19,"color":"#d3ab7d"},{"x":9,"y":23,"z":20,"color":"#d3ab7d"},{"x":9,"y":23,"z":21,"color":"#d3ab7d"},{"x":9,"y":23,"z":22,"color":"#d3ab7d"},{"x":9,"y":23,"z":23,"color":"#d3ab7d"},{"x":9,"y":23,"z":24,"color":"#d3ab7d"},{"x":9,"y":23,"z":25,"color":"#d3ab7d"},{"x":9,"y":34,"z":2,"color":"#b48653"},{"x":9,"y":34,"z":3,"color":"#d3ab7d"},{"x":9,"y":34,"z":4,"color":"#d3ab7d"},{"x":9,"y":34,"z":5,"color":"#d3ab7d"},{"x":9,"y":34,"z":6,"color":"#b48653"},{"x":9,"y":35,"z":2,"color":"#c79a67"},{"x":9,"y":35,"z":3,"color":"#c79a67"},{"x":9,"y":35,"z":4,"color":"#d3ab7d"},{"x":9,"y":35,"z":5,"color":"#c79a67"},{"x":9,"y":35,"z":6,"color":"#c79a67"},{"x":9,"y":36,"z":1,"color":"#c79a67"},{"x":9,"y":36,"z":2,"color":"#c79a67"},{"x":9,"y":36,"z":3,"color":"#c79a67"},{"x":9,"y":36,"z":4,"color":"#d3ab7d"},{"x":9,"y":36,"z":5,"color":"#c79a67"},{"x":9,"y":37,"z":1,"color":"#c79a67"},{"x":9,"y":37,"z":2,"color":"#c79a67"},{"x":9,"y":37,"z":3,"color":"#c79a67"},{"x":9,"y":37,"z":4,"color":"#d3ab7d"},{"x":9,"y":37,"z":5,"color":"#c79a67"},{"x":9,"y":38,"z":1,"color":"#c79a67"},{"x":9,"y":38,"z":2,"color":"#b48653"},{"x":9,"y":38,"z":3,"color":"#c79a67"},{"x":9,"y":38,"z":4,"color":"#d3ab7d"},{"x":9,"y":38,"z":5,"color":"#c79a67"},{"x":9,"y":39,"z":1,"color":"#c79a67"},{"x":9,"y":39,"z":2,"color":"#b48653"},{"x":9,"y":39,"z":3,"color":"#c79a67"},{"x":9,"y":39,"z":4,"color":"#d3ab7d"},{"x":9,"y":39,"z":5,"color":"#c79a67"},{"x":9,"y":40,"z":1,"color":"#c79a67"},{"x":9,"y":40,"z":2,"color":"#c79a67"},{"x":9,"y":40,"z":3,"color":"#c79a67"},{"x":9,"y":40,"z":4,"color":"#c79a67"},{"x":9,"y":40,"z":5,"color":"#c79a67"},{"x":9,"y":41,"z":0,"color":"#d3ab7d"},{"x":9,"y":41,"z":1,"color":"#c79a67"},{"x":9,"y":41,"z":2,"color":"#c79a67"},{"x":9,"y":41,"z":3,"color":"#c79a67"},{"x":9,"y":41,"z":4,"color":"#e2bf93"},{"x":9,"y":42,"z":0,"color":"#d3ab7d"},{"x":9,"y":42,"z":1,"color":"#c79a67"},{"x":9,"y":42,"z":2,"color":"#d3ab7d"},{"x":9,"y":42,"z":3,"color":"#d3ab7d"},{"x":9,"y":42,"z":4,"color":"#d3ab7d"},{"x":10,"y":19,"z":4,"color":"#d3ab7d"},{"x":10,"y":19,"z":5,"color":"#c79a67"},{"x":10,"y":19,"z":6,"color":"#c79a67"},{"x":10,"y":19,"z":7,"color":"#e2bf93"},{"x":10,"y":19,"z":8,"color":"#b48653"},{"x":10,"y":19,"z":9,"color":"#b48653"},{"x":10,"y":19,"z":10,"color":"#c79a67"},{"x":10,"y":19,"z":11,"color":"#c79a67"},{"x":10,"y":19,"z":12,"color":"#c79a67"},{"x":10,"y":19,"z":13,"color":"#c79a67"},{"x":10,"y":19,"z":20,"color":"#c79a67"},{"x":10,"y":19,"z":21,"color":"#d3ab7d"},{"x":10,"y":19,"z":22,"color":"#d3ab7d"},{"x":10,"y":19,"z":23,"color":"#c79a67"},{"x":10,"y":20,"z":4,"color":"#c79a67"},{"x":10,"y":20,"z":5,"color":"#c79a67"},{"x":10,"y":20,"z":6,"color":"#c79a67"},{"x":10,"y":20,"z":7,"color":"#c79a67"},{"x":10,"y":20,"z":8,"color":"#c79a67"},{"x":10,"y":20,"z":9,"color":"#c79a67"},{"x":10,"y":20,"z":10,"color":"#c79a67"},{"x":10,"y":20,"z":11,"color":"#b48653"},{"x":10,"y":20,"z":12,"color":"#e2bf93"},{"x":10,"y":20,"z":13,"color":"#c79a67"},{"x":10,"y":20,"z":14,"color":"#c79a67"},{"x":10,"y":20,"z":15,"color":"#c79a67"},{"x":10,"y":20,"z":16,"color":"#c79a67"},{"x":10,"y":20,"z":17,"color":"#c79a67"},{"x":10,"y":20,"z":18,"color":"#c79a67"},{"x":10,"y":20,"z":19,"color":"#c79a67"},{"x":10,"y":20,"z":20,"color":"#c79a67"},{"x":10,"y":20,"z":21,"color":"#c79a67"},{"x":10,"y":20,"z":22,"color":"#c79a67"},{"x":10,"y":20,"z":23,"color":"#c79a67"},{"x":10,"y":20,"z":24,"color":"#b48653"},{"x":10,"y":20,"z":25,"color":"#b48653"},{"x":10,"y":21,"z":4,"color":"#b48653"},{"x":10,"y":21,"z":5,"color":"#c79a67"},{"x":10,"y":21,"z":6,"color":"#c79a67"},{"x":10,"y":21,"z":7,"color":"#966a3b"},{"x":10,"y":21,"z":8,"color":"#b48653"},{"x":10,"y":21,"z":9,"color":"#b48653"},{"x":10,"y":21,"z":10,"color":"#c79a67"},{"x":10,"y":21,"z":11,"color":"#c79a67"},{"x":10,"y":21,"z":12,"color":"#c79a67"},{"x":10,"y":21,"z":13,"color":"#c79a67"},{"x":10,"y":21,"z":14,"color":"#c79a67"},{"x":10,"y":21,"z":15,"color":"#b48653"},{"x":10,"y":21,"z":16,"color":"#b48653"},{"x":10,"y":21,"z":17,"color":"#b48653"},{"x":10,"y":21,"z":18,"color":"#966a3b"},{"x":10,"y":21,"z":19,"color":"#966a3b"},{"x":10,"y":21,"z":20,"color":"#966a3b"},{"x":10,"y":21,"z":21,"color":"#966a3b"},{"x":10,"y":21,"z":22,"color":"#966a3b"},{"x":10,"y":21,"z":23,"color":"#c79a67"},{"x":10,"y":21,"z":24,"color":"#c79a67"},{"x":10,"y":21,"z":25,"color":"#b48653"},{"x":10,"y":22,"z":4,"color":"#d3ab7d"},{"x":10,"y":22,"z":5,"color":"#d3ab7d"},{"x":10,"y":22,"z":6,"color":"#d3ab7d"},{"x":10,"y":22,"z":7,"color":"#c79a67"},{"x":10,"y":22,"z":8,"color":"#b48653"},{"x":10,"y":22,"z":9,"color":"#c79a67"},{"x":10,"y":22,"z":10,"color":"#c79a67"},{"x":10,"y":22,"z":11,"color":"#c79a67"},{"x":10,"y":22,"z":12,"color":"#c79a67"},{"x":10,"y":22,"z":13,"color":"#c79a67"},{"x":10,"y":22,"z":14,"color":"#c79a67"},{"x":10,"y":22,"z":15,"color":"#c79a67"},{"x":10,"y":22,"z":16,"color":"#d3ab7d"},{"x":10,"y":22,"z":17,"color":"#d3ab7d"},{"x":10,"y":22,"z":18,"color":"#d3ab7d"},{"x":10,"y":22,"z":19,"color":"#d3ab7d"},{"x":10,"y":22,"z":20,"color":"#c79a67"},{"x":10,"y":22,"z":21,"color":"#d3ab7d"},{"x":10,"y":22,"z":22,"color":"#c79a67"},{"x":10,"y":22,"z":23,"color":"#c79a67"},{"x":10,"y":22,"z":24,"color":"#c79a67"},{"x":10,"y":22,"z":25,"color":"#d3ab7d"},{"x":10,"y":23,"z":4,"color":"#d3ab7d"},{"x":10,"y":23,"z":5,"color":"#d3ab7d"},{"x":10,"y":23,"z":6,"color":"#d3ab7d"},{"x":10,"y":23,"z":7,"color":"#c79a67"},{"x":10,"y":23,"z":8,"color":"#d3ab7d"},{"x":10,"y":23,"z":9,"color":"#d3ab7d"},{"x":10,"y":23,"z":10,"color":"#d3ab7d"},{"x":10,"y":23,"z":11,"color":"#d3ab7d"},{"x":10,"y":23,"z":12,"color":"#d3ab7d"},{"x":10,"y":23,"z":13,"color":"#d3ab7d"},{"x":10,"y":23,"z":14,"color":"#d3ab7d"},{"x":10,"y":23,"z":15,"color":"#d3ab7d"},{"x":10,"y":23,"z":16,"color":"#d3ab7d"},{"x":10,"y":23,"z":17,"color":"#d3ab7d"},{"x":10,"y":23,"z":18,"color":"#d3ab7d"},{"x":10,"y":23,"z":19,"color":"#d3ab7d"},{"x":10,"y":23,"z":20,"color":"#d3ab7d"},{"x":10,"y":23,"z":21,"color":"#d3ab7d"},{"x":10,"y":23,"z":22,"color":"#d3ab7d"},{"x":10,"y":23,"z":23,"color":"#d3ab7d"},{"x":10,"y":23,"z":24,"color":"#d3ab7d"},{"x":10,"y":23,"z":25,"color":"#d3ab7d"},{"x":10,"y":34,"z":2,"color":"#b48653"},{"x":10,"y":34,"z":3,"color":"#d3ab7d"},{"x":10,"y":34,"z":4,"color":"#d3ab7d"},{"x":10,"y":34,"z":5,"color":"#d3ab7d"},{"x":10,"y":34,"z":6,"color":"#c79a67"},{"x":10,"y":35,"z":2,"color":"#c79a67"},{"x":10,"y":35,"z":3,"color":"#c79a67"},{"x":10,"y":35,"z":4,"color":"#d3ab7d"},{"x":10,"y":35,"z":5,"color":"#c79a67"},{"x":10,"y":35,"z":6,"color":"#c79a67"},{"x":10,"y":36,"z":1,"color":"#c79a67"},{"x":10,"y":36,"z":2,"color":"#c79a67"},{"x":10,"y":36,"z":3,"color":"#c79a67"},{"x":10,"y":36,"z":4,"color":"#d3ab7d"},{"x":10,"y":36,"z":5,"color":"#c79a67"},{"x":10,"y":37,"z":1,"color":"#c79a67"},{"x":10,"y":37,"z":2,"color":"#c79a67"},{"x":10,"y":37,"z":3,"color":"#c79a67"},{"x":10,"y":37,"z":4,"color":"#d3ab7d"},{"x":10,"y":37,"z":5,"color":"#c79a67"},{"x":10,"y":38,"z":1,"color":"#c79a67"},{"x":10,"y":38,"z":2,"color":"#b48653"},{"x":10,"y":38,"z":3,"color":"#c79a67"},{"x":10,"y":38,"z":4,"color":"#d3ab7d"},{"x":10,"y":38,"z":5,"color":"#c79a67"},{"x":10,"y":39,"z":1,"color":"#b48653"},{"x":10,"y":39,"z":2,"color":"#b48653"},{"x":10,"y":39,"z":3,"color":"#c79a67"},{"x":10,"y":39,"z":4,"color":"#c79a67"},{"x":10,"y":39,"z":5,"color":"#b48653"},{"x":10,"y":40,"z":1,"color":"#c79a67"},{"x":10,"y":40,"z":2,"color":"#c79a67"},{"x":10,"y":40,"z":3,"color":"#c79a67"},{"x":10,"y":40,"z":4,"color":"#c79a67"},{"x":10,"y":40,"z":5,"color":"#c79a67"},{"x":10,"y":41,"z":0,"color":"#c79a67"},{"x":10,"y":41,"z":1,"color":"#c79a67"},{"x":10,"y":41,"z":2,"color":"#c79a67"},{"x":10,"y":41,"z":3,"color":"#c79a67"},{"x":10,"y":41,"z":4,"color":"#d3ab7d"},{"x":10,"y":42,"z":0,"color":"#d3ab7d"},{"x":10,"y":42,"z":1,"color":"#c79a67"},{"x":10,"y":42,"z":2,"color":"#e2bf93"},{"x":10,"y":42,"z":3,"color":"#d3ab7d"},{"x":10,"y":42,"z":4,"color":"#d3ab7d"},{"x":11,"y":19,"z":4,"color":"#d3ab7d"},{"x":11,"y":19,"z":5,"color":"#b48653"},{"x":11,"y":19,"z":6,"color":"#b48653"},{"x":11,"y":19,"z":7,"color":"#e2bf93"},{"x":11,"y":19,"z":8,"color":"#c79a67"},{"x":11,"y":19,"z":9,"color":"#c79a67"},{"x":11,"y":19,"z":10,"color":"#c79a67"},{"x":11,"y":19,"z":11,"color":"#c79a67"},{"x":11,"y":19,"z":12,"color":"#b48653"},{"x":11,"y":19,"z":13,"color":"#c79a67"},{"x":11,"y":19,"z":20,"color":"#c79a67"},{"x":11,"y":19,"z":21,"color":"#d3ab7d"},{"x":11,"y":19,"z":22,"color":"#d3ab7d"},{"x":11,"y":19,"z":23,"color":"#c79a67"},{"x":11,"y":20,"z":4,"color":"#c79a67"},{"x":11,"y":20,"z":5,"color":"#c79a67"},{"x":11,"y":20,"z":6,"color":"#c79a67"},{"x":11,"y":20,"z":7,"color":"#c79a67"},{"x":11,"y":20,"z":8,"color":"#c79a67"},{"x":11,"y":20,"z":9,"color":"#c79a67"},{"x":11,"y":20,"z":10,"color":"#c79a67"},{"x":11,"y":20,"z":11,"color":"#b48653"},{"x":11,"y":20,"z":12,"color":"#e2bf93"},{"x":11,"y":20,"z":13,"color":"#c79a67"},{"x":11,"y":20,"z":14,"color":"#b48653"},{"x":11,"y":20,"z":15,"color":"#c79a67"},{"x":11,"y":20,"z":16,"color":"#c79a67"},{"x":11,"y":20,"z":17,"color":"#c79a67"},{"x":11,"y":20,"z":18,"color":"#c79a67"},{"x":11,"y":20,"z":19,"color":"#c79a67"},{"x":11,"y":20,"z":20,"color":"#c79a67"},{"x":11,"y":20,"z":21,"color":"#c79a67"},{"x":11,"y":20,"z":22,"color":"#c79a67"},{"x":11,"y":20,"z":23,"color":"#c79a67"},{"x":11,"y":20,"z":24,"color":"#c79a67"},{"x":11,"y":20,"z":25,"color":"#b48653"},{"x":11,"y":21,"z":4,"color":"#b48653"},{"x":11,"y":21,"z":5,"color":"#c79a67"},{"x":11,"y":21,"z":6,"color":"#c79a67"},{"x":11,"y":21,"z":7,"color":"#966a3b"},{"x":11,"y":21,"z":8,"color":"#b48653"},{"x":11,"y":21,"z":9,"color":"#b48653"},{"x":11,"y":21,"z":10,"color":"#c79a67"},{"x":11,"y":21,"z":11,"color":"#c79a67"},{"x":11,"y":21,"z":12,"color":"#b48653"},{"x":11,"y":21,"z":13,"color":"#c79a67"},{"x":11,"y":21,"z":14,"color":"#c79a67"},{"x":11,"y":21,"z":15,"color":"#b48653"},{"x":11,"y":21,"z":16,"color":"#b48653"},{"x":11,"y":21,"z":17,"color":"#b48653"},{"x":11,"y":21,"z":18,"color":"#966a3b"},{"x":11,"y":21,"z":19,"color":"#966a3b"},{"x":11,"y":21,"z":20,"color":"#966a3b"},{"x":11,"y":21,"z":21,"color":"#966a3b"},{"x":11,"y":21,"z":22,"color":"#966a3b"},{"x":11,"y":21,"z":23,"color":"#c79a67"},{"x":11,"y":21,"z":24,"color":"#c79a67"},{"x":11,"y":21,"z":25,"color":"#b48653"},{"x":11,"y":22,"z":4,"color":"#d3ab7d"},{"x":11,"y":22,"z":5,"color":"#d3ab7d"},{"x":11,"y":22,"z":6,"color":"#c79a67"},{"x":11,"y":22,"z":7,"color":"#b48653"},{"x":11,"y":22,"z":8,"color":"#c79a67"},{"x":11,"y":22,"z":9,"color":"#c79a67"},{"x":11,"y":22,"z":10,"color":"#c79a67"},{"x":11,"y":22,"z":11,"color":"#c79a67"},{"x":11,"y":22,"z":12,"color":"#c79a67"},{"x":11,"y":22,"z":13,"color":"#c79a67"},{"x":11,"y":22,"z":14,"color":"#c79a67"},{"x":11,"y":22,"z":15,"color":"#c79a67"},{"x":11,"y":22,"z":16,"color":"#c79a67"},{"x":11,"y":22,"z":17,"color":"#d3ab7d"},{"x":11,"y":22,"z":18,"color":"#d3ab7d"},{"x":11,"y":22,"z":19,"color":"#d3ab7d"},{"x":11,"y":22,"z":20,"color":"#c79a67"},{"x":11,"y":22,"z":21,"color":"#d3ab7d"},{"x":11,"y":22,"z":22,"color":"#d3ab7d"},{"x":11,"y":22,"z":23,"color":"#c79a67"},{"x":11,"y":22,"z":24,"color":"#c79a67"},{"x":11,"y":22,"z":25,"color":"#d3ab7d"},{"x":11,"y":23,"z":4,"color":"#d3ab7d"},{"x":11,"y":23,"z":5,"color":"#c79a67"},{"x":11,"y":23,"z":6,"color":"#c79a67"},{"x":11,"y":23,"z":7,"color":"#c79a67"},{"x":11,"y":23,"z":8,"color":"#d3ab7d"},{"x":11,"y":23,"z":9,"color":"#d3ab7d"},{"x":11,"y":23,"z":10,"color":"#d3ab7d"},{"x":11,"y":23,"z":11,"color":"#d3ab7d"},{"x":11,"y":23,"z":12,"color":"#d3ab7d"},{"x":11,"y":23,"z":13,"color":"#d3ab7d"},{"x":11,"y":23,"z":14,"color":"#d3ab7d"},{"x":11,"y":23,"z":15,"color":"#d3ab7d"},{"x":11,"y":23,"z":16,"color":"#d3ab7d"},{"x":11,"y":23,"z":17,"color":"#d3ab7d"},{"x":11,"y":23,"z":18,"color":"#d3ab7d"},{"x":11,"y":23,"z":19,"color":"#d3ab7d"},{"x":11,"y":23,"z":20,"color":"#d3ab7d"},{"x":11,"y":23,"z":21,"color":"#d3ab7d"},{"x":11,"y":23,"z":22,"color":"#d3ab7d"},{"x":11,"y":23,"z":23,"color":"#d3ab7d"},{"x":11,"y":23,"z":24,"color":"#d3ab7d"},{"x":11,"y":23,"z":25,"color":"#d3ab7d"},{"x":11,"y":34,"z":2,"color":"#b48653"},{"x":11,"y":34,"z":3,"color":"#d3ab7d"},{"x":11,"y":34,"z":4,"color":"#d3ab7d"},{"x":11,"y":34,"z":5,"color":"#d3ab7d"},{"x":11,"y":34,"z":6,"color":"#b48653"},{"x":11,"y":35,"z":2,"color":"#b48653"},{"x":11,"y":35,"z":3,"color":"#c79a67"},{"x":11,"y":35,"z":4,"color":"#c79a67"},{"x":11,"y":35,"z":5,"color":"#b48653"},{"x":11,"y":35,"z":6,"color":"#b48653"},{"x":11,"y":36,"z":1,"color":"#b48653"},{"x":11,"y":36,"z":2,"color":"#b48653"},{"x":11,"y":36,"z":3,"color":"#c79a67"},{"x":11,"y":36,"z":4,"color":"#d3ab7d"},{"x":11,"y":36,"z":5,"color":"#c79a67"},{"x":11,"y":37,"z":1,"color":"#b48653"},{"x":11,"y":37,"z":2,"color":"#b48653"},{"x":11,"y":37,"z":3,"color":"#c79a67"},{"x":11,"y":37,"z":4,"color":"#d3ab7d"},{"x":11,"y":37,"z":5,"color":"#b48653"},{"x":11,"y":38,"z":1,"color":"#c79a67"},{"x":11,"y":38,"z":2,"color":"#b48653"},{"x":11,"y":38,"z":3,"color":"#c79a67"},{"x":11,"y":38,"z":4,"color":"#d3ab7d"},{"x":11,"y":38,"z":5,"color":"#c79a67"},{"x":11,"y":39,"z":1,"color":"#b48653"},{"x":11,"y":39,"z":2,"color":"#b48653"},{"x":11,"y":39,"z":3,"color":"#c79a67"},{"x":11,"y":39,"z":4,"color":"#c79a67"},{"x":11,"y":39,"z":5,"color":"#b48653"},{"x":11,"y":40,"z":1,"color":"#c79a67"},{"x":11,"y":40,"z":2,"color":"#b48653"},{"x":11,"y":40,"z":3,"color":"#c79a67"},{"x":11,"y":40,"z":4,"color":"#c79a67"},{"x":11,"y":40,"z":5,"color":"#b48653"},{"x":11,"y":41,"z":0,"color":"#c79a67"},{"x":11,"y":41,"z":1,"color":"#c79a67"},{"x":11,"y":41,"z":2,"color":"#c79a67"},{"x":11,"y":41,"z":3,"color":"#c79a67"},{"x":11,"y":41,"z":4,"color":"#c79a67"},{"x":11,"y":42,"z":0,"color":"#d3ab7d"},{"x":11,"y":42,"z":1,"color":"#c79a67"},{"x":11,"y":42,"z":2,"color":"#d3ab7d"},{"x":11,"y":42,"z":3,"color":"#d3ab7d"},{"x":11,"y":42,"z":4,"color":"#d3ab7d"},{"x":12,"y":19,"z":5,"color":"#b48653"},{"x":12,"y":19,"z":6,"color":"#b48653"},{"x":12,"y":19,"z":7,"color":"#e2bf93"},{"x":12,"y":19,"z":8,"color":"#c79a67"},{"x":12,"y":19,"z":9,"color":"#c79a67"},{"x":12,"y":19,"z":10,"color":"#c79a67"},{"x":12,"y":19,"z":11,"color":"#c79a67"},{"x":12,"y":19,"z":12,"color":"#c79a67"},{"x":12,"y":19,"z":13,"color":"#c79a67"},{"x":12,"y":19,"z":20,"color":"#c79a67"},{"x":12,"y":19,"z":21,"color":"#c79a67"},{"x":12,"y":19,"z":22,"color":"#d3ab7d"},{"x":12,"y":19,"z":23,"color":"#c79a67"},{"x":12,"y":20,"z":5,"color":"#b48653"},{"x":12,"y":20,"z":6,"color":"#b48653"},{"x":12,"y":20,"z":7,"color":"#b48653"},{"x":12,"y":20,"z":8,"color":"#c79a67"},{"x":12,"y":20,"z":9,"color":"#c79a67"},{"x":12,"y":20,"z":10,"color":"#c79a67"},{"x":12,"y":20,"z":11,"color":"#b48653"},{"x":12,"y":20,"z":12,"color":"#e2bf93"},{"x":12,"y":20,"z":13,"color":"#b48653"},{"x":12,"y":20,"z":14,"color":"#b48653"},{"x":12,"y":20,"z":15,"color":"#c79a67"},{"x":12,"y":20,"z":16,"color":"#b48653"},{"x":12,"y":20,"z":17,"color":"#c79a67"},{"x":12,"y":20,"z":18,"color":"#b48653"},{"x":12,"y":20,"z":19,"color":"#b48653"},{"x":12,"y":20,"z":20,"color":"#c79a67"},{"x":12,"y":20,"z":21,"color":"#c79a67"},{"x":12,"y":20,"z":22,"color":"#c79a67"},{"x":12,"y":20,"z":23,"color":"#c79a67"},{"x":12,"y":20,"z":24,"color":"#b48653"},{"x":12,"y":20,"z":25,"color":"#b48653"},{"x":12,"y":21,"z":5,"color":"#c79a67"},{"x":12,"y":21,"z":6,"color":"#c79a67"},{"x":12,"y":21,"z":7,"color":"#966a3b"},{"x":12,"y":21,"z":8,"color":"#b48653"},{"x":12,"y":21,"z":9,"color":"#b48653"},{"x":12,"y":21,"z":10,"color":"#c79a67"},{"x":12,"y":21,"z":11,"color":"#b48653"},{"x":12,"y":21,"z":12,"color":"#c79a67"},{"x":12,"y":21,"z":13,"color":"#c79a67"},{"x":12,"y":21,"z":14,"color":"#c79a67"},{"x":12,"y":21,"z":15,"color":"#b48653"},{"x":12,"y":21,"z":16,"color":"#b48653"},{"x":12,"y":21,"z":17,"color":"#b48653"},{"x":12,"y":21,"z":18,"color":"#966a3b"},{"x":12,"y":21,"z":19,"color":"#966a3b"},{"x":12,"y":21,"z":20,"color":"#966a3b"},{"x":12,"y":21,"z":21,"color":"#966a3b"},{"x":12,"y":21,"z":22,"color":"#966a3b"},{"x":12,"y":21,"z":23,"color":"#c79a67"},{"x":12,"y":21,"z":24,"color":"#c79a67"},{"x":12,"y":21,"z":25,"color":"#b48653"},{"x":12,"y":22,"z":5,"color":"#d3ab7d"},{"x":12,"y":22,"z":6,"color":"#d3ab7d"},{"x":12,"y":22,"z":7,"color":"#b48653"},{"x":12,"y":22,"z":8,"color":"#c79a67"},{"x":12,"y":22,"z":9,"color":"#c79a67"},{"x":12,"y":22,"z":10,"color":"#c79a67"},{"x":12,"y":22,"z":11,"color":"#c79a67"},{"x":12,"y":22,"z":12,"color":"#c79a67"},{"x":12,"y":22,"z":13,"color":"#c79a67"},{"x":12,"y":22,"z":14,"color":"#c79a67"},{"x":12,"y":22,"z":15,"color":"#c79a67"},{"x":12,"y":22,"z":16,"color":"#c79a67"},{"x":12,"y":22,"z":17,"color":"#c79a67"},{"x":12,"y":22,"z":18,"color":"#c79a67"},{"x":12,"y":22,"z":19,"color":"#c79a67"},{"x":12,"y":22,"z":20,"color":"#c79a67"},{"x":12,"y":22,"z":21,"color":"#c79a67"},{"x":12,"y":22,"z":22,"color":"#c79a67"},{"x":12,"y":22,"z":23,"color":"#c79a67"},{"x":12,"y":22,"z":24,"color":"#c79a67"},{"x":12,"y":22,"z":25,"color":"#d3ab7d"},{"x":12,"y":23,"z":5,"color":"#d3ab7d"},{"x":12,"y":23,"z":6,"color":"#d3ab7d"},{"x":12,"y":23,"z":7,"color":"#c79a67"},{"x":12,"y":23,"z":8,"color":"#d3ab7d"},{"x":12,"y":23,"z":9,"color":"#d3ab7d"},{"x":12,"y":23,"z":10,"color":"#d3ab7d"},{"x":12,"y":23,"z":11,"color":"#d3ab7d"},{"x":12,"y":23,"z":12,"color":"#d3ab7d"},{"x":12,"y":23,"z":13,"color":"#d3ab7d"},{"x":12,"y":23,"z":14,"color":"#d3ab7d"},{"x":12,"y":23,"z":15,"color":"#d3ab7d"},{"x":12,"y":23,"z":16,"color":"#d3ab7d"},{"x":12,"y":23,"z":17,"color":"#d3ab7d"},{"x":12,"y":23,"z":18,"color":"#d3ab7d"},{"x":12,"y":23,"z":19,"color":"#d3ab7d"},{"x":12,"y":23,"z":20,"color":"#d3ab7d"},{"x":12,"y":23,"z":21,"color":"#d3ab7d"},{"x":12,"y":23,"z":22,"color":"#d3ab7d"},{"x":12,"y":23,"z":23,"color":"#d3ab7d"},{"x":12,"y":23,"z":24,"color":"#d3ab7d"},{"x":12,"y":23,"z":25,"color":"#d3ab7d"},{"x":12,"y":34,"z":2,"color":"#b48653"},{"x":12,"y":34,"z":3,"color":"#d3ab7d"},{"x":12,"y":34,"z":5,"color":"#d3ab7d"},{"x":12,"y":34,"z":6,"color":"#b48653"},{"x":12,"y":35,"z":2,"color":"#b48653"},{"x":12,"y":35,"z":3,"color":"#c79a67"},{"x":12,"y":35,"z":5,"color":"#b48653"},{"x":12,"y":35,"z":6,"color":"#b48653"},{"x":12,"y":36,"z":1,"color":"#b48653"},{"x":12,"y":36,"z":2,"color":"#b48653"},{"x":12,"y":36,"z":3,"color":"#c79a67"},{"x":12,"y":36,"z":5,"color":"#c79a67"},{"x":12,"y":37,"z":1,"color":"#b48653"},{"x":12,"y":37,"z":2,"color":"#c79a67"},{"x":12,"y":37,"z":3,"color":"#c79a67"},{"x":12,"y":37,"z":5,"color":"#b48653"},{"x":12,"y":38,"z":1,"color":"#c79a67"},{"x":12,"y":38,"z":2,"color":"#b48653"},{"x":12,"y":38,"z":3,"color":"#c79a67"},{"x":12,"y":38,"z":5,"color":"#c79a67"},{"x":12,"y":39,"z":1,"color":"#b48653"},{"x":12,"y":39,"z":2,"color":"#b48653"},{"x":12,"y":39,"z":3,"color":"#b48653"},{"x":12,"y":39,"z":5,"color":"#b48653"},{"x":12,"y":40,"z":1,"color":"#c79a67"},{"x":12,"y":40,"z":2,"color":"#b48653"},{"x":12,"y":40,"z":3,"color":"#c79a67"},{"x":12,"y":40,"z":5,"color":"#b48653"},{"x":12,"y":41,"z":0,"color":"#d3ab7d"},{"x":12,"y":41,"z":1,"color":"#c79a67"},{"x":12,"y":41,"z":2,"color":"#c79a67"},{"x":12,"y":41,"z":3,"color":"#c79a67"},{"x":12,"y":42,"z":0,"color":"#d3ab7d"},{"x":12,"y":42,"z":1,"color":"#c79a67"},{"x":12,"y":42,"z":2,"color":"#d3ab7d"},{"x":12,"y":42,"z":3,"color":"#d3ab7d"},{"x":13,"y":19,"z":4,"color":"#d3ab7d"},{"x":13,"y":19,"z":5,"color":"#b48653"},